Workbook

Sheet Dashboard
B1: DASHBOARD — APROVEITAMENTO DA FROTA · AGOSTO / 2026
B2: Painel gerencial consolidado. Atualiza automaticamente conforme os lançamentos diários são preenchidos.
B3: ="Período: 01/08/2026 a 31/08/2026 | Dados lançados até o dia "&TEXT(Consolidado!C35,"0")&"/08/2026 | "&TEXT(Consolidado!C36,"0")&" dias com operação" -> Período: 01/08/2026 a 31/08/2026 | Dados lançados até o dia 31/08/2026 | 27 dias com operação
B5: TOTAL DE CARREGAMENTOS | E5: MÉDIA DIÁRIA | H5: MAIOR VOLUME EM UM DIA | K5: % FROTA PRÓPRIA (s/ FOB)
B6: =Consolidado!C37 -> 2360 | E6: =Consolidado!C38 -> 87.407407 | H6: =Consolidado!C39 -> 117 | K6: =Consolidado!C40 -> 0.60832587
B8: % TERCEIROS (s/ FOB) | E8: FOB (FORA DO COMPARATIVO) | H8: VEÍCULOS DE DISTRIBUIÇÃO | K8: VIAGENS POR VEÍCULO (MÊS)
B9: =Consolidado!C41 -> 0.39167413 | E9: =Consolidado!C44 -> 126 | H9: =Consolidado!C46 -> 128 | K9: =Consolidado!C45 -> 10.617188
B69: Fonte: aba Lançamento Diário · Consolidação automática · Predilecta e empresas do grupo.

Sheet Divulgação Diária
D1: CARREGAMENTOS DIÁRIOS — RESULTADO ACUMULADO
D2: ="Posição de "&TEXT(DATE(2026,8,Consolidado!$C$35),"DD/MM/YYYY")&" · acumulado de 01/08 a "&TEXT(DATE(2026,8,Consolidado!$C$35),"DD/MM")&" · "&TEXT(Consolidado!C36,"0")&" dias com operação" -> Posição de 31/08/YYYY · acumulado de 01/08 a 31/08 · 27 dias com operação
B4: GRUPO PREDILECTA · CONTROLE DE APROVEITAMENTO DA FROTA
B6: CARREGAMENTOS NO DIA | D6: FROTA PRÓPRIA — ACUMULADO | G6: % FROTA PRÓPRIA | I6: TERCEIROS — ACUMULADO | K6: FOB — FORA DO COMPARATIVO
B7: =INDEX('Totais Diários'!$C$11:$AG$11,1,Consolidado!$C$35) -> 83 | D7: =Consolidado!C42 -> 1359 | G7: =Consolidado!C40 -> 0.60832587 | I7: =Consolidado!C43 -> 875 | K7: =Consolidado!C44 -> 126
B8: total do último dia lançado | D8: frota + transpredi | G8: sobre próprio + terceiro | I8: terceiros + transpredi contratado | K8: carga retirada pelo cliente
B23: RESULTADO POR EMPRESA — DESTAQUE PARA A FROTA PRÓPRIA
C24: EMPRESA | D24: NO DIA | E24: PRÓPRIA NO DIA | F24: PRÓPRIA ACUMULADO | G24: TERCEIRO ACUMULADO | H24: % FROTA PRÓPRIA | I24: % TERCEIRO | J24: FOB (fora) | K24: TOTAL GERAL | L24: VIAGENS/ VEÍC. | M24: DIA x MÉDIA
C25: Predilecta | D25: =INDEX('Totais Diários'!$C$18:$AG$18,1,Consolidado!$C$35) -> 16 | E25: =INDEX('Totais Diários'!$C$28:$AG$28,1,Consolidado!$C$35) -> 3 | F25: =Consolidado!C16 -> 460 | G25: =Consolidado!D16 -> 201 | H25: =Consolidado!F16 -> 0.69591528 | I25: =Consolidado!G16 -> 0.30408472 | J25: =Consolidado!H16 -> 45 | K25: =Consolidado!I16 -> 706 | L25: =Consolidado!E26 -> 9.787234 | M25: =IFERROR(D25/Consolidado!I26-1,0) -> -0.41076487
C26: Salsaretti | D26: =INDEX('Totais Diários'!$C$19:$AG$19,1,Consolidado!$C$35) -> 14 | E26: =INDEX('Totais Diários'!$C$29:$AG$29,1,Consolidado!$C$35) -> 4 | F26: =Consolidado!C17 -> 148 | G26: =Consolidado!D17 -> 164 | H26: =Consolidado!F17 -> 0.47435897 | I26: =Consolidado!G17 -> 0.52564103 | J26: =Consolidado!H17 -> 9 | K26: =Consolidado!I17 -> 321 | L26: =Consolidado!E27 -> 12.333333 | M26: =IFERROR(D26/Consolidado!I27-1,0) -> 0.13395639
C27: Stella d'Oro | D27: =INDEX('Totais Diários'!$C$20:$AG$20,1,Consolidado!$C$35) -> 15 | E27: =INDEX('Totais Diários'!$C$30:$AG$30,1,Consolidado!$C$35) -> 11 | F27: =Consolidado!C18 -> 250 | G27: =Consolidado!D18 -> 106 | H27: =Consolidado!F18 -> 0.70224719 | I27: =Consolidado!G18 -> 0.29775281 | J27: =Consolidado!H18 -> 23 | K27: =Consolidado!I18 -> 379 | L27: =Consolidado!E28 -> 12.5 | M27: =IFERROR(D27/Consolidado!I28-1,0) -> 0.068601583
C28: Sofruta | D28: =INDEX('Totais Diários'!$C$21:$AG$21,1,Consolidado!$C$35) -> 18 | E28: =INDEX('Totais Diários'!$C$31:$AG$31,1,Consolidado!$C$35) -> 8 | F28: =Consolidado!C19 -> 278 | G28: =Consolidado!D19 -> 174 | H28: =Consolidado!F19 -> 0.61504425 | I28: =Consolidado!G19 -> 0.38495575 | J28: =Consolidado!H19 -> 22 | K28: =Consolidado!I19 -> 474 | L28: =Consolidado!E29 -> 10.692308 | M28: =IFERROR(D28/Consolidado!I29-1,0) -> 0.025316456
C29: Minas Mais | D29: =INDEX('Totais Diários'!$C$22:$AG$22,1,Consolidado!$C$35) -> 20 | E29: =INDEX('Totais Diários'!$C$32:$AG$32,1,Consolidado!$C$35) -> 4 | F29: =Consolidado!C20 -> 184 | G29: =Consolidado!D20 -> 171 | H29: =Consolidado!F20 -> 0.51830986 | I29: =Consolidado!G20 -> 0.48169014 | J29: =Consolidado!H20 -> 27 | K29: =Consolidado!I20 -> 382 | L29: =Consolidado!E30 -> 9.2 | M29: =IFERROR(D29/Consolidado!I30-1,0) -> 0.30890052
C30: Nordeste Mais | D30: =INDEX('Totais Diários'!$C$23:$AG$23,1,Consolidado!$C$35) -> 0 | E30: =INDEX('Totais Diários'!$C$33:$AG$33,1,Consolidado!$C$35) -> 0 | F30: =Consolidado!C21 -> 39 | G30: =Consolidado!D21 -> 59 | H30: =Consolidado!F21 -> 0.39795918 | I30: =Consolidado!G21 -> 0.60204082 | J30: =Consolidado!H21 -> 0 | K30: =Consolidado!I21 -> 98 | L30: =Consolidado!E31 -> 13 | M30: =IFERROR(D30/Consolidado!I31-1,0) -> -1
B31: TOTAL DO GRUPO PREDILECTA | D31: =INDEX('Totais Diários'!$C$11:$AG$11,1,Consolidado!$C$35) -> 83 | E31: =INDEX('Totais Diários'!$C$34:$AG$34,1,Consolidado!$C$35) -> 30 | F31: =Consolidado!C22 -> 1359 | G31: =Consolidado!D22 -> 875 | H31: =Consolidado!F22 -> 0.60832587 | I31: =Consolidado!G22 -> 0.39167413 | J31: =Consolidado!H22 -> 126 | K31: =Consolidado!I22 -> 2360 | L31: =Consolidado!E32 -> 10.617188 | M31: =IFERROR(D31/Consolidado!I32-1,0) -> -0.050423729
B33: ="Destaque do dia: "&INDEX($C$25:$C$30,MATCH(MAX($E$25:$E$30),$E$25:$E$30,0))&" ("&TEXT(MAX($E$25:$E$30),"#,##0")&" próprios)"&" | Melhor % próprio: "&INDEX($C$25:$C$30,MATCH(MAX($H$25:$H$30),$H$25:$H$30,0))&" ("&TEXT(MAX($H$25:$H$30),"0.0%")&")"&" | Frota: "&TEXT(Consolidado!C46,"0")&" veículos" -> Destaque do dia: Stella d'Oro (11,0 próprios) | Melhor % próprio: Stella d'Oro (70%) | Frota: 128 veículos
B34: Critério: FROTA PRÓPRIA = frota + transpredi · TERCEIRO = terceiros + transpredi contratado · FOB fora do comparativo.

Sheet Consolidado
B1: CONSOLIDAÇÃO DE DADOS — AGOSTO / 2026
B2: Todas as células desta aba são calculadas a partir da aba Lançamento Diário. Não digitar valores aqui.
B4: 1. CARREGAMENTOS POR EMPRESA E MODALIDADE
B5: EMPRESA | C5: FROTA | D5: TRANSPREDI | E5: TRANSPREDI CONTRATADO | F5: TERCEIROS | G5: FOB | H5: TOTAL | I5: % DO TOTAL
B6: Predilecta | C6: ='Lançamento Diário'!AH7 -> 389 | D6: ='Lançamento Diário'!AH8 -> 71 | E6: ='Lançamento Diário'!AH9 -> 14 | F6: ='Lançamento Diário'!AH10 -> 187 | G6: ='Lançamento Diário'!AH11 -> 45 | H6: =SUM(C6:G6) -> 706 | I6: =IFERROR(H6/$H$12,0) -> 0.29915254
B7: Salsaretti | C7: ='Lançamento Diário'!AH15 -> 119 | D7: ='Lançamento Diário'!AH16 -> 29 | E7: ='Lançamento Diário'!AH17 -> 68 | F7: ='Lançamento Diário'!AH18 -> 96 | G7: ='Lançamento Diário'!AH19 -> 9 | H7: =SUM(C7:G7) -> 321 | I7: =IFERROR(H7/$H$12,0) -> 0.13601695
B8: Stella d'Oro | C8: ='Lançamento Diário'!AH23 -> 213 | D8: ='Lançamento Diário'!AH24 -> 37 | E8: ='Lançamento Diário'!AH25 -> 7 | F8: ='Lançamento Diário'!AH26 -> 99 | G8: ='Lançamento Diário'!AH27 -> 23 | H8: =SUM(C8:G8) -> 379 | I8: =IFERROR(H8/$H$12,0) -> 0.16059322
B9: Sofruta | C9: ='Lançamento Diário'!AH31 -> 220 | D9: ='Lançamento Diário'!AH32 -> 58 | E9: ='Lançamento Diário'!AH33 -> 8 | F9: ='Lançamento Diário'!AH34 -> 166 | G9: ='Lançamento Diário'!AH35 -> 22 | H9: =SUM(C9:G9) -> 474 | I9: =IFERROR(H9/$H$12,0) -> 0.20084746
B10: Minas Mais | C10: ='Lançamento Diário'!AH39 -> 158 | D10: ='Lançamento Diário'!AH40 -> 26 | E10: ='Lançamento Diário'!AH41 -> 41 | F10: ='Lançamento Diário'!AH42 -> 130 | G10: ='Lançamento Diário'!AH43 -> 27 | H10: =SUM(C10:G10) -> 382 | I10: =IFERROR(H10/$H$12,0) -> 0.16186441
B11: Nordeste Mais | C11: ='Lançamento Diário'!AH47 -> 39 | D11: ='Lançamento Diário'!AH48 -> 0 | E11: ='Lançamento Diário'!AH49 -> 17 | F11: ='Lançamento Diário'!AH50 -> 42 | G11: ='Lançamento Diário'!AH51 -> 0 | H11: =SUM(C11:G11) -> 98 | I11: =IFERROR(H11/$H$12,0) -> 0.041525424
B12: TOTAL GERAL | C12: =SUM(C6:C11) -> 1138 | D12: =SUM(D6:D11) -> 221 | E12: =SUM(E6:E11) -> 155 | F12: =SUM(F6:F11) -> 720 | G12: =SUM(G6:G11) -> 126 | H12: =SUM(H6:H11) -> 2360 | I12: =IFERROR(H12/H12,0) -> 1
B14: 2. FROTA PRÓPRIA x TERCEIROS (FOB fora do comparativo)
B15: EMPRESA | C15: FROTA PRÓPRIA (Frota + Transpredi) | D15: TERCEIRO (Contratado + Terceiros) | E15: BASE DO COMPARATIVO | F15: % FROTA PRÓPRIA | G15: % TERCEIRO | H15: FOB (fora) | I15: TOTAL GERAL
B16: Predilecta | C16: =C6+D6 -> 460 | D16: =E6+F6 -> 201 | E16: =C16+D16 -> 661 | F16: =IFERROR(C16/$E16,0) -> 0.69591528 | G16: =IFERROR(D16/$E16,0) -> 0.30408472 | H16: =G6 -> 45 | I16: =E16+H16 -> 706
B17: Salsaretti | C17: =C7+D7 -> 148 | D17: =E7+F7 -> 164 | E17: =C17+D17 -> 312 | F17: =IFERROR(C17/$E17,0) -> 0.47435897 | G17: =IFERROR(D17/$E17,0) -> 0.52564103 | H17: =G7 -> 9 | I17: =E17+H17 -> 321
B18: Stella d'Oro | C18: =C8+D8 -> 250 | D18: =E8+F8 -> 106 | E18: =C18+D18 -> 356 | F18: =IFERROR(C18/$E18,0) -> 0.70224719 | G18: =IFERROR(D18/$E18,0) -> 0.29775281 | H18: =G8 -> 23 | I18: =E18+H18 -> 379
B19: Sofruta | C19: =C9+D9 -> 278 | D19: =E9+F9 -> 174 | E19: =C19+D19 -> 452 | F19: =IFERROR(C19/$E19,0) -> 0.61504425 | G19: =IFERROR(D19/$E19,0) -> 0.38495575 | H19: =G9 -> 22 | I19: =E19+H19 -> 474
B20: Minas Mais | C20: =C10+D10 -> 184 | D20: =E10+F10 -> 171 | E20: =C20+D20 -> 355 | F20: =IFERROR(C20/$E20,0) -> 0.51830986 | G20: =IFERROR(D20/$E20,0) -> 0.48169014 | H20: =G10 -> 27 | I20: =E20+H20 -> 382
B21: Nordeste Mais | C21: =C11+D11 -> 39 | D21: =E11+F11 -> 59 | E21: =C21+D21 -> 98 | F21: =IFERROR(C21/$E21,0) -> 0.39795918 | G21: =IFERROR(D21/$E21,0) -> 0.60204082 | H21: =G11 -> 0 | I21: =E21+H21 -> 98
B22: TOTAL GERAL | C22: =SUM(C16:C21) -> 1359 | D22: =SUM(D16:D21) -> 875 | E22: =SUM(E16:E21) -> 2234 | F22: =IFERROR(C22/$E22,0) -> 0.60832587 | G22: =IFERROR(D22/$E22,0) -> 0.39167413 | H22: =SUM(H16:H21) -> 126 | I22: =SUM(I16:I21) -> 2360
B24: 3. APROVEITAMENTO DA FROTA (VIAGENS POR VEÍCULO)
B25: EMPRESA | C25: VEÍCULOS (Distribuição) | D25: CARREG. PRÓPRIOS | E25: VIAGENS POR VEÍCULO (MÊS) | F25: DIAS COM OPERAÇÃO | G25: VIAGENS/VEÍC. POR DIA | H25: TOTAL CARREG. | I25: MÉDIA DIÁRIA
B26: Predilecta | C26: =Frota!C6 -> 47 | D26: =C16 -> 460 | E26: =IFERROR(D26/C26,0) -> 9.787234 | F26: =COUNTIF('Lançamento Diário'!C12:AG12,">0") -> 26 | G26: =IFERROR(E26/F26,0) -> 0.37643208 | H26: =H6 -> 706 | I26: =IFERROR(H26/F26,0) -> 27.153846
B27: Salsaretti | C27: =Frota!C7 -> 12 | D27: =C17 -> 148 | E27: =IFERROR(D27/C27,0) -> 12.333333 | F27: =COUNTIF('Lançamento Diário'!C20:AG20,">0") -> 26 | G27: =IFERROR(E27/F27,0) -> 0.47435897 | H27: =H7 -> 321 | I27: =IFERROR(H27/F27,0) -> 12.346154
B28: Stella d'Oro | C28: =Frota!C8 -> 20 | D28: =C18 -> 250 | E28: =IFERROR(D28/C28,0) -> 12.5 | F28: =COUNTIF('Lançamento Diário'!C28:AG28,">0") -> 27 | G28: =IFERROR(E28/F28,0) -> 0.46296296 | H28: =H8 -> 379 | I28: =IFERROR(H28/F28,0) -> 14.037037
B29: Sofruta | C29: =Frota!C9 -> 26 | D29: =C19 -> 278 | E29: =IFERROR(D29/C29,0) -> 10.692308 | F29: =COUNTIF('Lançamento Diário'!C36:AG36,">0") -> 27 | G29: =IFERROR(E29/F29,0) -> 0.3960114 | H29: =H9 -> 474 | I29: =IFERROR(H29/F29,0) -> 17.555556
B30: Minas Mais | C30: =Frota!C10 -> 20 | D30: =C20 -> 184 | E30: =IFERROR(D30/C30,0) -> 9.2 | F30: =COUNTIF('Lançamento Diário'!C44:AG44,">0") -> 25 | G30: =IFERROR(E30/F30,0) -> 0.368 | H30: =H10 -> 382 | I30: =IFERROR(H30/F30,0) -> 15.28
B31: Nordeste Mais | C31: =Frota!C11 -> 3 | D31: =C21 -> 39 | E31: =IFERROR(D31/C31,0) -> 13 | F31: =COUNTIF('Lançamento Diário'!C52:AG52,">0") -> 24 | G31: =IFERROR(E31/F31,0) -> 0.54166667 | H31: =H11 -> 98 | I31: =IFERROR(H31/F31,0) -> 4.0833333
B32: TOTAL GERAL | C32: =SUM(C26:C31) -> 128 | D32: =SUM(D26:D31) -> 1359 | E32: =IFERROR(D32/C32,0) -> 10.617188 | F32: =COUNTIF('Lançamento Diário'!C60:AG60,">0") -> 27 | G32: =IFERROR(E32/F32,0) -> 0.39322917 | H32: =SUM(H26:H31) -> 2360 | I32: =IFERROR(H32/F32,0) -> 87.407407
B34: 4. INDICADORES AUXILIARES (usados no Dashboard)
B35: Último dia lançado | C35: =SUMPRODUCT(MAX(('Totais Diários'!C11:AG11>0)*'Totais Diários'!C5:AG5)) -> 31
B36: Dias com operação | C36: =COUNTIF('Totais Diários'!C11:AG11,">0") -> 27
B37: Total de carregamentos | C37: =H12 -> 2360
B38: Média diária de carregamentos | C38: =IFERROR(C37/C36,0) -> 87.407407
B39: Maior volume em um dia | C39: =MAX('Totais Diários'!C11:AG11) -> 117
B40: % Frota própria (s/ FOB) | C40: =F22 -> 0.60832587
B41: % Terceiros (s/ FOB) | C41: =G22 -> 0.39167413
B42: Carregamentos frota própria | C42: =C22 -> 1359
B43: Carregamentos terceiros | C43: =D22 -> 875
B44: Carregamentos FOB | C44: =H22 -> 126
...

Sheet Totais Diários
B1: TOTAIS DIÁRIOS — AGOSTO / 2026
B2: Visão dia a dia por modalidade e por empresa. Calculado a partir da aba Lançamento Diário.
B4: 1. TOTAIS DIÁRIOS POR MODALIDADE
B5: MODALIDADE | C5: 1 | D5: 2 | E5: 3 | F5: 4 | G5: 5 | H5: 6 | I5: 7 | J5: 8 | K5: 9 | L5: 10 | M5: 11 | N5: 12 | O5: 13 | P5: 14 | Q5: 15 | R5: 16 | S5: 17 | T5: 18 | U5: 19 | V5: 20 | W5: 21 | X5: 22 | Y5: 23 | Z5: 24 | AA5: 25 | AB5: 26 | AC5: 27 | AD5: 28 | AE5: 29 | AF5: 30 | AG5: 31
B6: FROTA | C6: ='Lançamento Diário'!C55 -> 40 | D6: ='Lançamento Diário'!D55 -> 17 | E6: ='Lançamento Diário'!E55 -> 25 | F6: ='Lançamento Diário'!F55 -> 46 | G6: ='Lançamento Diário'!G55 -> 50 | H6: ='Lançamento Diário'!H55 -> 44 | I6: ='Lançamento Diário'!I55 -> 46 | J6: ='Lançamento Diário'!J55 -> 46 | ... AG6: ='Lançamento Diário'!AG55 -> 25
B7: TRANSPREDI | C7: ='Lançamento Diário'!C56 -> 8 | D7: ='Lançamento Diário'!D56 -> 7 | E7: ='Lançamento Diário'!E56 -> 4 | F7: ='Lançamento Diário'!F56 -> 13 | G7: ='Lançamento Diário'!G56 -> 12 | H7: ='Lançamento Diário'!H56 -> 13 | I7: ='Lançamento Diário'!I56 -> 12 | J7: ='Lançamento Diário'!J56 -> 5 | ... AG7: ='Lançamento Diário'!AG56 -> 5
B8: TRANSPREDI CONTRATADO | C8: ='Lançamento Diário'!C57 -> 4 | D8: ='Lançamento Diário'!D57 -> 1 | E8: ='Lançamento Diário'!E57 -> 11 | F8: ='Lançamento Diário'!F57 -> 10 | G8: ='Lançamento Diário'!G57 -> 7 | H8: ='Lançamento Diário'!H57 -> 6 | I8: ='Lançamento Diário'!I57 -> 8 | J8: ='Lançamento Diário'!J57 -> 4 | ... AG8: ='Lançamento Diário'!AG57 -> 8
B9: TERCEIROS | C9: ='Lançamento Diário'!C58 -> 11 | D9: ='Lançamento Diário'!D58 -> 2 | E9: ='Lançamento Diário'!E58 -> 40 | F9: ='Lançamento Diário'!F58 -> 41 | G9: ='Lançamento Diário'!G58 -> 45 | H9: ='Lançamento Diário'!H58 -> 42 | I9: ='Lançamento Diário'!I58 -> 48 | J9: ='Lançamento Diário'!J58 -> 26 | ... AG9: ='Lançamento Diário'!AG58 -> 35
B10: FOB | C10: ='Lançamento Diário'!C59 -> 12 | D10: ='Lançamento Diário'!D59 -> 1 | E10: ='Lançamento Diário'!E59 -> 7 | F10: ='Lançamento Diário'!F59 -> 2 | G10: ='Lançamento Diário'!G59 -> 2 | H10: ='Lançamento Diário'!H59 -> 7 | I10: ='Lançamento Diário'!I59 -> 3 | J10: ='Lançamento Diário'!J59 -> 1 | ... AG10: ='Lançamento Diário'!AG59 -> 10
B11: TOTAL DIA | C11: =SUM(C6:C10) -> 75 | D11: =SUM(D6:D10) -> 28 | E11: =SUM(E6:E10) -> 87 | F11: =SUM(F6:F10) -> 112 | G11: =SUM(G6:G10) -> 116 | H11: =SUM(H6:H10) -> 112 | I11: =SUM(I6:I10) -> 117 | J11: =SUM(J6:J10) -> 82 | ... AG11: =SUM(AG6:AG10) -> 83
B12: PRÓPRIO | C12: =C6+C7 -> 48 | D12: =D6+D7 -> 24 | E12: =E6+E7 -> 29 | F12: =F6+F7 -> 59 | G12: =G6+G7 -> 62 | H12: =H6+H7 -> 57 | I12: =I6+I7 -> 58 | J12: =J6+J7 -> 51 | ... AG12: =AG6+AG7 -> 30
B13: TERCEIRO | C13: =C8+C9 -> 15 | D13: =D8+D9 -> 3 | E13: =E8+E9 -> 51 | F13: =F8+F9 -> 51 | G13: =G8+G9 -> 52 | H13: =H8+H9 -> 48 | I13: =I8+I9 -> 56 | J13: =J8+J9 -> 30 | ... AG13: =AG8+AG9 -> 43
B16: 2. TOTAIS DIÁRIOS POR EMPRESA
B17: EMPRESA | C17: 1 | D17: 2 | E17: 3 | F17: 4 | G17: 5 | H17: 6 | I17: 7 | J17: 8 | K17: 9 | L17: 10 | M17: 11 | N17: 12 | O17: 13 | P17: 14 | Q17: 15 | R17: 16 | S17: 17 | T17: 18 | U17: 19 | V17: 20 | W17: 21 | X17: 22 | Y17: 23 | Z17: 24 | AA17: 25 | AB17: 26 | AC17: 27 | AD17: 28 | AE17: 29 | AF17: 30 | AG17: 31
B18: Predilecta | C18: ='Lançamento Diário'!C12 -> 24 | D18: ='Lançamento Diário'!D12 -> 13 | E18: ='Lançamento Diário'!E12 -> 24 | F18: ='Lançamento Diário'!F12 -> 38 | G18: ='Lançamento Diário'!G12 -> 38 | H18: ='Lançamento Diário'!H12 -> 36 | I18: ='Lançamento Diário'!I12 -> 32 | J18: ='Lançamento Diário'!J12 -> 34 | ... AG18: ='Lançamento Diário'!AG12 -> 16
B19: Salsaretti | C19: ='Lançamento Diário'!C20 -> 7 | D19: ='Lançamento Diário'!D20 -> 0 | E19: ='Lançamento Diário'!E20 -> 16 | F19: ='Lançamento Diário'!F20 -> 18 | G19: ='Lançamento Diário'!G20 -> 17 | H19: ='Lançamento Diário'!H20 -> 12 | I19: ='Lançamento Diário'!I20 -> 20 | J19: ='Lançamento Diário'!J20 -> 9 | ... AG19: ='Lançamento Diário'!AG20 -> 14
B20: Stella d'Oro | C20: ='Lançamento Diário'!C28 -> 10 | D20: ='Lançamento Diário'!D28 -> 6 | E20: ='Lançamento Diário'!E28 -> 9 | F20: ='Lançamento Diário'!F28 -> 13 | G20: ='Lançamento Diário'!G28 -> 17 | H20: ='Lançamento Diário'!H28 -> 17 | I20: ='Lançamento Diário'!I28 -> 12 | J20: ='Lançamento Diário'!J28 -> 10 | ... AG20: ='Lançamento Diário'!AG28 -> 15
B21: Sofruta | C21: ='Lançamento Diário'!C36 -> 16 | D21: ='Lançamento Diário'!D36 -> 9 | E21: ='Lançamento Diário'!E36 -> 16 | F21: ='Lançamento Diário'!F36 -> 21 | G21: ='Lançamento Diário'!G36 -> 23 | H21: ='Lançamento Diário'!H36 -> 25 | I21: ='Lançamento Diário'!I36 -> 25 | J21: ='Lançamento Diário'!J36 -> 16 | ... AG21: ='Lançamento Diário'!AG36 -> 18
B22: Minas Mais | C22: ='Lançamento Diário'!C44 -> 12 | D22: ='Lançamento Diário'!D44 -> 0 | E22: ='Lançamento Diário'!E44 -> 17 | F22: ='Lançamento Diário'!F44 -> 17 | G22: ='Lançamento Diário'!G44 -> 19 | H22: ='Lançamento Diário'!H44 -> 17 | I22: ='Lançamento Diário'!I44 -> 23 | J22: ='Lançamento Diário'!J44 -> 13 | ... AG22: ='Lançamento Diário'!AG44 -> 20
B23: Nordeste Mais | C23: ='Lançamento Diário'!C52 -> 6 | D23: ='Lançamento Diário'!D52 -> 0 | E23: ='Lançamento Diário'!E52 -> 5 | F23: ='Lançamento Diário'!F52 -> 5 | G23: ='Lançamento Diário'!G52 -> 2 | H23: ='Lançamento Diário'!H52 -> 5 | I23: ='Lançamento Diário'!I52 -> 5 | J23: ='Lançamento Diário'!J52 -> 0 | ... AG23: ='Lançamento Diário'!AG52 -> 0
B24: TOTAL | C24: =SUM(C18:C23) -> 75 | D24: =SUM(D18:D23) -> 28 | E24: =SUM(E18:E23) -> 87 | F24: =SUM(F18:F23) -> 112 | G24: =SUM(G18:G23) -> 116 | H24: =SUM(H18:H23) -> 112 | I24: =SUM(I18:I23) -> 117 | J24: =SUM(J18:J23) -> 82 | ... AG24: =SUM(AG18:AG23) -> 83
B26: 3. FROTA PRÓPRIA POR EMPRESA (frota + transpredi)
B27: EMPRESA | C27: 1 | D27: 2 | E27: 3 | F27: 4 | G27: 5 | H27: 6 | I27: 7 | J27: 8 | K27: 9 | L27: 10 | M27: 11 | N27: 12 | O27: 13 | P27: 14 | Q27: 15 | R27: 16 | S27: 17 | T27: 18 | U27: 19 | V27: 20 | W27: 21 | X27: 22 | Y27: 23 | Z27: 24 | AA27: 25 | AB27: 26 | AC27: 27 | AD27: 28 | AE27: 29 | AF27: 30 | AG27: 31
B28: Predilecta | C28: ='Lançamento Diário'!C7+'Lançamento Diário'!C8 -> 17 | D28: ='Lançamento Diário'!D7+'Lançamento Diário'!D8 -> 12 | E28: ='Lançamento Diário'!E7+'Lançamento Diário'!E8 -> 13 | F28: ='Lançamento Diário'!F7+'Lançamento Diário'!F8 -> 21 | G28: ='Lançamento Diário'!G7+'Lançamento Diário'!G8 -> 24 | H28: ='Lançamento Diário'!H7+'Lançamento Diário'!H8 -> 19 | I28: ='Lançamento Diário'!I7+'Lançamento Diário'!I8 -> 20 | J28: ='Lançamento Diário'!J7+'Lançamento Diário'!J8 -> 21 | ... AG28: ='Lançamento Diário'!AG7+'Lançamento Diário'!AG8 -> 3
B29: Salsaretti | C29: ='Lançamento Diário'!C15+'Lançamento Diário'!C16 -> 6 | D29: ='Lançamento Diário'!D15+'Lançamento Diário'!D16 -> 0 | E29: ='Lançamento Diário'!E15+'Lançamento Diário'!E16 -> 5 | F29: ='Lançamento Diário'!F15+'Lançamento Diário'!F16 -> 8 | G29: ='Lançamento Diário'!G15+'Lançamento Diário'!G16 -> 8 | H29: ='Lançamento Diário'!H15+'Lançamento Diário'!H16 -> 6 | I29: ='Lançamento Diário'!I15+'Lançamento Diário'!I16 -> 7 | J29: ='Lançamento Diário'!J15+'Lançamento Diário'!J16 -> 5 | ... AG29: ='Lançamento Diário'!AG15+'Lançamento Diário'!AG16 -> 4
B30: Stella d'Oro | C30: ='Lançamento Diário'!C23+'Lançamento Diário'!C24 -> 7 | D30: ='Lançamento Diário'!D23+'Lançamento Diário'!D24 -> 5 | E30: ='Lançamento Diário'!E23+'Lançamento Diário'!E24 -> 4 | F30: ='Lançamento Diário'!F23+'Lançamento Diário'!F24 -> 8 | G30: ='Lançamento Diário'!G23+'Lançamento Diário'!G24 -> 10 | H30: ='Lançamento Diário'!H23+'Lançamento Diário'!H24 -> 10 | I30: ='Lançamento Diário'!I23+'Lançamento Diário'!I24 -> 8 | J30: ='Lançamento Diário'!J23+'Lançamento Diário'!J24 -> 8 | ... AG30: ='Lançamento Diário'!AG23+'Lançamento Diário'!AG24 -> 11
B31: Sofruta | C31: ='Lançamento Diário'!C31+'Lançamento Diário'!C32 -> 8 | D31: ='Lançamento Diário'!D31+'Lançamento Diário'!D32 -> 7 | E31: ='Lançamento Diário'!E31+'Lançamento Diário'!E32 -> 4 | F31: ='Lançamento Diário'!F31+'Lançamento Diário'!F32 -> 11 | G31: ='Lançamento Diário'!G31+'Lançamento Diário'!G32 -> 13 | H31: ='Lançamento Diário'!H31+'Lançamento Diário'!H32 -> 11 | I31: ='Lançamento Diário'!I31+'Lançamento Diário'!I32 -> 13 | J31: ='Lançamento Diário'!J31+'Lançamento Diário'!J32 -> 11 | ... AG31: ='Lançamento Diário'!AG31+'Lançamento Diário'!AG32 -> 8
B32: Minas Mais | C32: ='Lançamento Diário'!C39+'Lançamento Diário'!C40 -> 7 | D32: ='Lançamento Diário'!D39+'Lançamento Diário'!D40 -> 0 | E32: ='Lançamento Diário'!E39+'Lançamento Diário'!E40 -> 3 | F32: ='Lançamento Diário'!F39+'Lançamento Diário'!F40 -> 9 | G32: ='Lançamento Diário'!G39+'Lançamento Diário'!G40 -> 7 | H32: ='Lançamento Diário'!H39+'Lançamento Diário'!H40 -> 8 | I32: ='Lançamento Diário'!I39+'Lançamento Diário'!I40 -> 10 | J32: ='Lançamento Diário'!J39+'Lançamento Diário'!J40 -> 6 | ... AG32: ='Lançamento Diário'!AG39+'Lançamento Diário'!AG40 -> 4
B33: Nordeste Mais | C33: ='Lançamento Diário'!C47+'Lançamento Diário'!C48 -> 3 | D33: ='Lançamento Diário'!D47+'Lançamento Diário'!D48 -> 0 | E33: ='Lançamento Diário'!E47+'Lançamento Diário'!E48 -> 0 | F33: ='Lançamento Diário'!F47+'Lançamento Diário'!F48 -> 2 | G33: ='Lançamento Diário'!G47+'Lançamento Diário'!G48 -> 0 | H33: ='Lançamento Diário'!H47+'Lançamento Diário'!H48 -> 3 | I33: ='Lançamento Diário'!I47+'Lançamento Diário'!I48 -> 0 | J33: ='Lançamento Diário'!J47+'Lançamento Diário'!J48 -> 0 | ... AG33: ='Lançamento Diário'!AG47+'Lançamento Diário'!AG48 -> 0
B34: TOTAL | C34: =SUM(C28:C33) -> 48 | D34: =SUM(D28:D33) -> 24 | E34: =SUM(E28:E33) -> 29 | F34: =SUM(F28:F33) -> 59 | G34: =SUM(G28:G33) -> 62 | H34: =SUM(H28:H33) -> 57 | I34: =SUM(I28:I33) -> 58 | J34: =SUM(J28:J33) -> 51 | ... AG34: =SUM(AG28:AG33) -> 30
B36: 4. TERCEIROS POR EMPRESA (transpredi contratado + terceiros)
B37: EMPRESA | C37: 1 | D37: 2 | E37: 3 | F37: 4 | G37: 5 | H37: 6 | I37: 7 | J37: 8 | K37: 9 | L37: 10 | M37: 11 | N37: 12 | O37: 13 | P37: 14 | Q37: 15 | R37: 16 | S37: 17 | T37: 18 | U37: 19 | V37: 20 | W37: 21 | X37: 22 | Y37: 23 | Z37: 24 | AA37: 25 | AB37: 26 | AC37: 27 | AD37: 28 | AE37: 29 | AF37: 30 | AG37: 31
B38: Predilecta | C38: ='Lançamento Diário'!C9+'Lançamento Diário'!C10 -> 6 | D38: ='Lançamento Diário'!D9+'Lançamento Diário'!D10 -> 1 | E38: ='Lançamento Diário'!E9+'Lançamento Diário'!E10 -> 10 | F38: ='Lançamento Diário'!F9+'Lançamento Diário'!F10 -> 16 | G38: ='Lançamento Diário'!G9+'Lançamento Diário'!G10 -> 13 | H38: ='Lançamento Diário'!H9+'Lançamento Diário'!H10 -> 12 | I38: ='Lançamento Diário'!I9+'Lançamento Diário'!I10 -> 10 | J38: ='Lançamento Diário'!J9+'Lançamento Diário'!J10 -> 12 | ... AG38: ='Lançamento Diário'!AG9+'Lançamento Diário'!AG10 -> 10
B39: Salsaretti | C39: ='Lançamento Diário'!C17+'Lançamento Diário'!C18 -> 1 | D39: ='Lançamento Diário'!D17+'Lançamento Diário'!D18 -> 0 | E39: ='Lançamento Diário'!E17+'Lançamento Diário'!E18 -> 8 | F39: ='Lançamento Diário'!F17+'Lançamento Diário'!F18 -> 10 | G39: ='Lançamento Diário'!G17+'Lançamento Diário'!G18 -> 9 | H39: ='Lançamento Diário'!H17+'Lançamento Diário'!H18 -> 6 | I39: ='Lançamento Diário'!I17+'Lançamento Diário'!I18 -> 13 | J39: ='Lançamento Diário'!J17+'Lançamento Diário'!J18 -> 4 | ... AG39: ='Lançamento Diário'!AG17+'Lançamento Diário'!AG18 -> 6
B40: Stella d'Oro | C40: ='Lançamento Diário'!C25+'Lançamento Diário'!C26 -> 0 | D40: ='Lançamento Diário'!D25+'Lançamento Diário'!D26 -> 0 | E40: ='Lançamento Diário'!E25+'Lançamento Diário'!E26 -> 3 | F40: ='Lançamento Diário'!F25+'Lançamento Diário'!F26 -> 4 | G40: ='Lançamento Diário'!G25+'Lançamento Diário'!G26 -> 6 | H40: ='Lançamento Diário'!H25+'Lançamento Diário'!H26 -> 6 | I40: ='Lançamento Diário'!I25+'Lançamento Diário'!I26 -> 4 | J40: ='Lançamento Diário'!J25+'Lançamento Diário'!J26 -> 2 | ... AG40: ='Lançamento Diário'!AG25+'Lançamento Diário'!AG26 -> 3
B41: Sofruta | C41: ='Lançamento Diário'!C33+'Lançamento Diário'!C34 -> 1 | D41: ='Lançamento Diário'!D33+'Lançamento Diário'!D34 -> 2 | E41: ='Lançamento Diário'!E33+'Lançamento Diário'!E34 -> 11 | F41: ='Lançamento Diário'!F33+'Lançamento Diário'!F34 -> 10 | G41: ='Lançamento Diário'!G33+'Lançamento Diário'!G34 -> 10 | H41: ='Lançamento Diário'!H33+'Lançamento Diário'!H34 -> 13 | I41: ='Lançamento Diário'!I33+'Lançamento Diário'!I34 -> 12 | J41: ='Lançamento Diário'!J33+'Lançamento Diário'!J34 -> 5 | ... AG41: ='Lançamento Diário'!AG33+'Lançamento Diário'!AG34 -> 10
B42: Minas Mais | C42: ='Lançamento Diário'!C41+'Lançamento Diário'!C42 -> 4 | D42: ='Lançamento Diário'!D41+'Lançamento Diário'!D42 -> 0 | E42: ='Lançamento Diário'!E41+'Lançamento Diário'!E42 -> 14 | F42: ='Lançamento Diário'!F41+'Lançamento Diário'!F42 -> 8 | G42: ='Lançamento Diário'!G41+'Lançamento Diário'!G42 -> 12 | H42: ='Lançamento Diário'!H41+'Lançamento Diário'!H42 -> 9 | I42: ='Lançamento Diário'!I41+'Lançamento Diário'!I42 -> 12 | J42: ='Lançamento Diário'!J41+'Lançamento Diário'!J42 -> 7 | ... AG42: ='Lançamento Diário'!AG41+'Lançamento Diário'!AG42 -> 14
B43: Nordeste Mais | C43: ='Lançamento Diário'!C49+'Lançamento Diário'!C50 -> 3 | D43: ='Lançamento Diário'!D49+'Lançamento Diário'!D50 -> 0 | E43: ='Lançamento Diário'!E49+'Lançamento Diário'!E50 -> 5 | F43: ='Lançamento Diário'!F49+'Lançamento Diário'!F50 -> 3 | G43: ='Lançamento Diário'!G49+'Lançamento Diário'!G50 -> 2 | H43: ='Lançamento Diário'!H49+'Lançamento Diário'!H50 -> 2 | I43: ='Lançamento Diário'!I49+'Lançamento Diário'!I50 -> 5 | J43: ='Lançamento Diário'!J49+'Lançamento Diário'!J50 -> 0 | ... AG43: ='Lançamento Diário'!AG49+'Lançamento Diário'!AG50 -> 0
B44: TOTAL | C44: =SUM(C38:C43) -> 15 | D44: =SUM(D38:D43) -> 3 | E44: =SUM(E38:E43) -> 51 | F44: =SUM(F38:F43) -> 51 | G44: =SUM(G38:G43) -> 52 | H44: =SUM(H38:H43) -> 48 | I44: =SUM(I38:I43) -> 56 | J44: =SUM(J38:J43) -> 30 | ... AG44: =SUM(AG38:AG43) -> 43

Sheet Lançamento Diário
B1: LANÇAMENTO DIÁRIO DE CARREGAMENTOS — AGOSTO / 2026
B2: Área de entrada de dados. Digite apenas nas células amarelas. Totais, percentuais e o Dashboard são calculados automaticamente.
B4: DIA | C4: 46235 | D4: 46236 | E4: 46237 | F4: 46238 | G4: 46239 | H4: 46240 | I4: 46241 | J4: 46242 | K4: 46243 | L4: 46244 | M4: 46245 | N4: 46246 | O4: 46247 | P4: 46248 | Q4: 46249 | R4: 46250 | S4: 46251 | T4: 46252 | U4: 46253 | V4: 46254 | W4: 46255 | X4: 46256 | Y4: 46257 | Z4: 46258 | AA4: 46259 | AB4: 46260 | AC4: 46261 | AD4: 46262 | AE4: 46263 | AF4: 46264 | AG4: 46265 | AH4: TOTAL MÊS | AI4: % MÊS | AJ4: MÉDIA/DIA
B5: SEMANA | C5: sáb | D5: dom | E5: seg | F5: ter | G5: qua | H5: qui | I5: sex | J5: sáb | K5: dom | L5: seg | M5: ter | N5: qua | O5: qui | P5: sex | Q5: sáb | R5: dom | S5: seg | T5: ter | U5: qua | V5: qui | W5: sex | X5: sáb | Y5: dom | Z5: seg | AA5: ter | AB5: qua | AC5: qui | AD5: sex | AE5: sáb | AF5: dom | AG5: seg
B6: 1. PREDILECTA
B7: FROTA | C7: 15 | D7: 9 | E7: 12 | F7: 17 | G7: 20 | H7: 14 | I7: 17 | J7: 20 | K7: 0 | L7: 0 | M7: 16 | N7: 19 | O7: 16 | P7: 20 | Q7: 11 | R7: 0 | S7: 8 | T7: 15 | U7: 16 | V7: 16 | W7: 19 | X7: 15 | Y7: 0 | Z7: 13 | AA7: 10 | AB7: 22 | AC7: 16 | AD7: 16 | AE7: 15 | AF7: 0 | AG7: 2 | AH7: =SUM(C7:AG7) -> 389 | AI7: =IFERROR(AH7/$AH$12,0) -> 0.5509915 | AJ7: =IFERROR(AH7/COUNTIF($C$12:$AG$12,">0"),0) -> 14.961538
B8: TRANSPREDI | C8: 2 | D8: 3 | E8: 1 | F8: 4 | G8: 4 | H8: 5 | I8: 3 | J8: 1 | K8: 0 | L8: 0 | M8: 4 | N8: 2 | O8: 3 | P8: 4 | Q8: 2 | R8: 0 | S8: 0 | T8: 5 | U8: 1 | V8: 2 | W8: 3 | X8: 6 | Y8: 0 | Z8: 0 | AA8: 5 | AB8: 2 | AC8: 1 | AD8: 3 | AE8: 4 | AF8: 0 | AG8: 1 | AH8: =SUM(C8:AG8) -> 71 | AI8: =IFERROR(AH8/$AH$12,0) -> 0.10056657 | AJ8: =IFERROR(AH8/COUNTIF($C$12:$AG$12,">0"),0) -> 2.7307692
B9: TRANSPREDI CONTRATADO | C9: 1 | D9: 0 | E9: 3 | F9: 2 | G9: 0 | H9: 0 | I9: 1 | J9: 1 | K9: 0 | L9: 0 | M9: 1 | N9: 0 | O9: 0 | P9: 0 | Q9: 0 | R9: 0 | S9: 1 | T9: 1 | U9: 0 | V9: 0 | W9: 0 | X9: 0 | Y9: 0 | Z9: 1 | AA9: 1 | AB9: 0 | AC9: 0 | AD9: 0 | AE9: 0 | AF9: 0 | AG9: 1 | AH9: =SUM(C9:AG9) -> 14 | AI9: =IFERROR(AH9/$AH$12,0) -> 0.019830028 | AJ9: =IFERROR(AH9/COUNTIF($C$12:$AG$12,">0"),0) -> 0.53846154
B10: TERCEIROS | C10: 5 | D10: 1 | E10: 7 | F10: 14 | G10: 13 | H10: 12 | I10: 9 | J10: 11 | K10: 0 | L10: 0 | M10: 11 | N10: 8 | O10: 5 | P10: 5 | Q10: 5 | R10: 0 | S10: 7 | T10: 4 | U10: 9 | V10: 2 | W10: 5 | X10: 7 | Y10: 0 | Z10: 12 | AA10: 12 | AB10: 2 | AC10: 3 | AD10: 5 | AE10: 4 | AF10: 0 | AG10: 9 | AH10: =SUM(C10:AG10) -> 187 | AI10: =IFERROR(AH10/$AH$12,0) -> 0.26487252 | AJ10: =IFERROR(AH10/COUNTIF($C$12:$AG$12,">0"),0) -> 7.1923077
B11: FOB | C11: 1 | D11: 0 | E11: 1 | F11: 1 | G11: 1 | H11: 5 | I11: 2 | J11: 1 | K11: 0 | L11: 0 | M11: 2 | N11: 0 | O11: 4 | P11: 1 | Q11: 0 | R11: 0 | S11: 3 | T11: 3 | U11: 2 | V11: 4 | W11: 1 | X11: 0 | Y11: 0 | Z11: 3 | AA11: 1 | AB11: 2 | AC11: 3 | AD11: 1 | AE11: 0 | AF11: 0 | AG11: 3 | AH11: =SUM(C11:AG11) -> 45 | AI11: =IFERROR(AH11/$AH$12,0) -> 0.063739377 | AJ11: =IFERROR(AH11/COUNTIF($C$12:$AG$12,">0"),0) -> 1.7307692
B12: TOTAL | C12: =SUM(C7:C11) -> 24 | D12: =SUM(D7:D11) -> 13 | E12: =SUM(E7:E11) -> 24 | F12: =SUM(F7:F11) -> 38 | G12: =SUM(G7:G11) -> 38 | H12: =SUM(H7:H11) -> 36 | I12: =SUM(I7:I11) -> 32 | J12: =SUM(J7:J11) -> 34 | ... AH12: =SUM(AH7:AH11) -> 706 | AI12: =IFERROR(AH12/AH12,0) -> 1 | AJ12: =IFERROR(AH12/COUNTIF(C12:AG12,">0"),0) -> 27.153846
B14: 2. SALSARETTI
B15: FROTA | C15: 5 | D15: 0 | E15: 4 | F15: 7 | G15: 6 | H15: 4 | I15: 6 | J15: 3 | K15: 0 | L15: 4 | M15: 4 | N15: 4 | O15: 5 | P15: 2 | Q15: 7 | R15: 0 | S15: 1 | T15: 6 | U15: 4 | V15: 3 | W15: 3 | X15: 6 | Y15: 0 | Z15: 3 | AA15: 7 | AB15: 3 | AC15: 7 | AD15: 5 | AE15: 7 | AF15: 0 | AG15: 3 | AH15: =SUM(C15:AG15) -> 119 | AI15: =IFERROR(AH15/$AH$20,0) -> 0.37071651 | AJ15: =IFERROR(AH15/COUNTIF($C$20:$AG$20,">0"),0) -> 4.5769231
B16: TRANSPREDI | C16: 1 | D16: 0 | E16: 1 | F16: 1 | G16: 2 | H16: 2 | I16: 1 | J16: 2 | K16: 0 | L16: 0 | M16: 1 | N16: 1 | O16: 1 | P16: 2 | Q16: 1 | R16: 0 | S16: 1 | T16: 1 | U16: 1 | V16: 0 | W16: 1 | X16: 0 | Y16: 0 | Z16: 1 | AA16: 1 | AB16: 1 | AC16: 3 | AD16: 0 | AE16: 2 | AF16: 0 | AG16: 1 | AH16: =SUM(C16:AG16) -> 29 | AI16: =IFERROR(AH16/$AH$20,0) -> 0.090342679 | AJ16: =IFERROR(AH16/COUNTIF($C$20:$AG$20,">0"),0) -> 1.1153846
B17: TRANSPREDI CONTRATADO | C17: 0 | D17: 0 | E17: 5 | F17: 4 | G17: 5 | H17: 3 | I17: 4 | J17: 1 | K17: 0 | L17: 2 | M17: 5 | N17: 5 | O17: 1 | P17: 1 | Q17: 0 | R17: 0 | S17: 0 | T17: 3 | U17: 3 | V17: 2 | W17: 4 | X17: 0 | Y17: 0 | Z17: 3 | AA17: 2 | AB17: 2 | AC17: 6 | AD17: 3 | AE17: 1 | AF17: 0 | AG17: 3 | AH17: =SUM(C17:AG17) -> 68 | AI17: =IFERROR(AH17/$AH$20,0) -> 0.21183801 | AJ17: =IFERROR(AH17/COUNTIF($C$20:$AG$20,">0"),0) -> 2.6153846
B18: TERCEIROS | C18: 1 | D18: 0 | E18: 3 | F18: 6 | G18: 4 | H18: 3 | I18: 9 | J18: 3 | K18: 0 | L18: 1 | M18: 3 | N18: 3 | O18: 0 | P18: 2 | Q18: 6 | R18: 0 | S18: 6 | T18: 8 | U18: 6 | V18: 3 | W18: 1 | X18: 3 | Y18: 0 | Z18: 1 | AA18: 5 | AB18: 7 | AC18: 3 | AD18: 4 | AE18: 2 | AF18: 0 | AG18: 3 | AH18: =SUM(C18:AG18) -> 96 | AI18: =IFERROR(AH18/$AH$20,0) -> 0.29906542 | AJ18: =IFERROR(AH18/COUNTIF($C$20:$AG$20,">0"),0) -> 3.6923077
B19: FOB | C19: 0 | D19: 0 | E19: 3 | F19: 0 | G19: 0 | H19: 0 | I19: 0 | J19: 0 | K19: 0 | L19: 1 | M19: 0 | N19: 0 | O19: 0 | P19: 0 | Q19: 0 | R19: 0 | S19: 0 | T19: 0 | U19: 1 | V19: 0 | W19: 0 | X19: 0 | Y19: 0 | Z19: 0 | AA19: 0 | AB19: 0 | AC19: 0 | AD19: 0 | AE19: 0 | AF19: 0 | AG19: 4 | AH19: =SUM(C19:AG19) -> 9 | AI19: =IFERROR(AH19/$AH$20,0) -> 0.028037383 | AJ19: =IFERROR(AH19/COUNTIF($C$20:$AG$20,">0"),0) -> 0.34615385
B20: TOTAL | C20: =SUM(C15:C19) -> 7 | D20: =SUM(D15:D19) -> 0 | E20: =SUM(E15:E19) -> 16 | F20: =SUM(F15:F19) -> 18 | G20: =SUM(G15:G19) -> 17 | H20: =SUM(H15:H19) -> 12 | I20: =SUM(I15:I19) -> 20 | J20: =SUM(J15:J19) -> 9 | ... AH20: =SUM(AH15:AH19) -> 321 | AI20: =IFERROR(AH20/AH20,0) -> 1 | AJ20: =IFERROR(AH20/COUNTIF(C20:AG20,">0"),0) -> 12.346154
B22: 3. STELLA D'ORO
B23: FROTA | C23: 7 | D23: 4 | E23: 4 | F23: 6 | G23: 7 | H23: 8 | I23: 6 | J23: 8 | K23: 0 | L23: 6 | M23: 10 | N23: 12 | O23: 11 | P23: 7 | Q23: 7 | R23: 0 | S23: 6 | T23: 8 | U23: 11 | V23: 15 | W23: 7 | X23: 3 | Y23: 0 | Z23: 3 | AA23: 10 | AB23: 14 | AC23: 9 | AD23: 6 | AE23: 9 | AF23: 0 | AG23: 9 | AH23: =SUM(C23:AG23) -> 213 | AI23: =IFERROR(AH23/$AH$28,0) -> 0.56200528 | AJ23: =IFERROR(AH23/COUNTIF($C$28:$AG$28,">0"),0) -> 7.8888889
B24: TRANSPREDI | C24: 0 | D24: 1 | E24: 0 | F24: 2 | G24: 3 | H24: 2 | I24: 2 | J24: 0 | K24: 0 | L24: 1 | M24: 3 | N24: 1 | O24: 4 | P24: 0 | Q24: 2 | R24: 0 | S24: 2 | T24: 2 | U24: 1 | V24: 1 | W24: 0 | X24: 0 | Y24: 0 | Z24: 2 | AA24: 2 | AB24: 1 | AC24: 1 | AD24: 0 | AE24: 2 | AF24: 0 | AG24: 2 | AH24: =SUM(C24:AG24) -> 37 | AI24: =IFERROR(AH24/$AH$28,0) -> 0.09762533 | AJ24: =IFERROR(AH24/COUNTIF($C$28:$AG$28,">0"),0) -> 1.3703704
B25: TRANSPREDI CONTRATADO | E25: 0 | F25: 1 | G25: 0 | H25: 0 | I25: 1 | J25: 0 | K25: 0 | L25: 0 | M25: 0 | N25: 1 | O25: 1 | P25: 0 | Q25: 0 | R25: 0 | S25: 1 | T25: 1 | U25: 1 | V25: 0 | W25: 0 | X25: 0 | Y25: 0 | Z25: 0 | AA25: 0 | AB25: 0 | AC25: 0 | AD25: 0 | AE25: 0 | AF25: 0 | AG25: 0 | AH25: =SUM(C25:AG25) -> 7 | AI25: =IFERROR(AH25/$AH$28,0) -> 0.018469657 | AJ25: =IFERROR(AH25/COUNTIF($C$28:$AG$28,">0"),0) -> 0.25925926
B26: TERCEIROS | C26: 0 | D26: 0 | E26: 3 | F26: 3 | G26: 6 | H26: 6 | I26: 3 | J26: 2 | K26: 0 | L26: 4 | M26: 4 | N26: 7 | O26: 4 | P26: 7 | Q26: 0 | R26: 0 | S26: 1 | T26: 9 | U26: 4 | V26: 3 | W26: 5 | X26: 1 | Y26: 0 | Z26: 4 | AA26: 6 | AB26: 4 | AC26: 6 | AD26: 2 | AE26: 2 | AF26: 0 | AG26: 3 | AH26: =SUM(C26:AG26) -> 99 | AI26: =IFERROR(AH26/$AH$28,0) -> 0.26121372 | AJ26: =IFERROR(AH26/COUNTIF($C$28:$AG$28,">0"),0) -> 3.6666667
B27: FOB | C27: 3 | D27: 1 | E27: 2 | F27: 1 | G27: 1 | H27: 1 | I27: 0 | J27: 0 | K27: 0 | L27: 0 | M27: 0 | N27: 1 | O27: 0 | P27: 1 | Q27: 0 | R27: 0 | S27: 0 | T27: 1 | U27: 4 | V27: 0 | W27: 0 | X27: 0 | Y27: 0 | Z27: 3 | AA27: 1 | AB27: 0 | AC27: 0 | AD27: 2 | AE27: 0 | AF27: 0 | AG27: 1 | AH27: =SUM(C27:AG27) -> 23 | AI27: =IFERROR(AH27/$AH$28,0) -> 0.060686016 | AJ27: =IFERROR(AH27/COUNTIF($C$28:$AG$28,">0"),0) -> 0.85185185
B28: TOTAL | C28: =SUM(C23:C27) -> 10 | D28: =SUM(D23:D27) -> 6 | E28: =SUM(E23:E27) -> 9 | F28: =SUM(F23:F27) -> 13 | G28: =SUM(G23:G27) -> 17 | H28: =SUM(H23:H27) -> 17 | I28: =SUM(I23:I27) -> 12 | J28: =SUM(J23:J27) -> 10 | ... AH28: =SUM(AH23:AH27) -> 379 | AI28: =IFERROR(AH28/AH28,0) -> 1 | AJ28: =IFERROR(AH28/COUNTIF(C28:AG28,">0"),0) -> 14.037037
B30: 4. SOFRUTA
B31: FROTA | C31: 6 | D31: 4 | E31: 2 | F31: 8 | G31: 10 | H31: 8 | I31: 9 | J31: 9 | K31: 0 | L31: 6 | M31: 10 | N31: 11 | O31: 11 | P31: 9 | Q31: 6 | R31: 0 | S31: 5 | T31: 7 | U31: 15 | V31: 10 | W31: 13 | X31: 7 | Y31: 0 | Z31: 5 | AA31: 7 | AB31: 7 | AC31: 6 | AD31: 9 | AE31: 12 | AF31: 0 | AG31: 8 | AH31: =SUM(C31:AG31) -> 220 | AI31: =IFERROR(AH31/$AH$36,0) -> 0.46413502 | AJ31: =IFERROR(AH31/COUNTIF($C$36:$AG$36,">0"),0) -> 8.1481481
B32: TRANSPREDI | C32: 2 | D32: 3 | E32: 2 | F32: 3 | G32: 3 | H32: 3 | I32: 4 | J32: 2 | K32: 0 | L32: 1 | M32: 3 | N32: 3 | O32: 3 | P32: 0 | Q32: 4 | R32: 0 | S32: 3 | T32: 2 | U32: 2 | V32: 2 | W32: 0 | X32: 3 | Y32: 0 | Z32: 0 | AA32: 2 | AB32: 3 | AC32: 1 | AD32: 4 | AE32: 0 | AF32: 0 | AG32: 0 | AH32: =SUM(C32:AG32) -> 58 | AI32: =IFERROR(AH32/$AH$36,0) -> 0.12236287 | AJ32: =IFERROR(AH32/COUNTIF($C$36:$AG$36,">0"),0) -> 2.1481481
B33: TRANSPREDI CONTRATADO | D33: 1 | E33: 0 | F33: 1 | G33: 1 | H33: 1 | I33: 0 | J33: 0 | K33: 0 | L33: 1 | M33: 0 | N33: 0 | O33: 1 | P33: 0 | Q33: 0 | R33: 0 | S33: 1 | T33: 0 | U33: 0 | V33: 1 | W33: 0 | X33: 0 | Y33: 0 | Z33: 0 | AA33: 0 | AB33: 0 | AC33: 0 | AD33: 0 | AE33: 0 | AF33: 0 | AG33: 0 | AH33: =SUM(C33:AG33) -> 8 | AI33: =IFERROR(AH33/$AH$36,0) -> 0.016877637 | AJ33: =IFERROR(AH33/COUNTIF($C$36:$AG$36,">0"),0) -> 0.2962963
B34: TERCEIROS | C34: 1 | D34: 1 | E34: 11 | F34: 9 | G34: 9 | H34: 12 | I34: 12 | J34: 5 | K34: 0 | L34: 7 | M34: 5 | N34: 9 | O34: 4 | P34: 8 | Q34: 2 | R34: 0 | S34: 8 | T34: 6 | U34: 3 | V34: 5 | W34: 6 | X34: 7 | Y34: 0 | Z34: 10 | AA34: 5 | AB34: 1 | AC34: 3 | AD34: 4 | AE34: 3 | AF34: 0 | AG34: 10 | AH34: =SUM(C34:AG34) -> 166 | AI34: =IFERROR(AH34/$AH$36,0) -> 0.35021097 | AJ34: =IFERROR(AH34/COUNTIF($C$36:$AG$36,">0"),0) -> 6.1481481
B35: FOB | C35: 7 | D35: 0 | E35: 1 | F35: 0 | G35: 0 | H35: 1 | I35: 0 | J35: 0 | K35: 0 | L35: 1 | M35: 1 | N35: 2 | O35: 1 | P35: 0 | Q35: 0 | R35: 0 | S35: 1 | T35: 1 | U35: 0 | V35: 1 | W35: 0 | X35: 0 | Y35: 0 | Z35: 1 | AA35: 2 | AB35: 2 | AC35: 0 | AD35: 0 | AE35: 0 | AF35: 0 | AG35: 0 | AH35: =SUM(C35:AG35) -> 22 | AI35: =IFERROR(AH35/$AH$36,0) -> 0.046413502 | AJ35: =IFERROR(AH35/COUNTIF($C$36:$AG$36,">0"),0) -> 0.81481481
B36: TOTAL | C36: =SUM(C31:C35) -> 16 | D36: =SUM(D31:D35) -> 9 | E36: =SUM(E31:E35) -> 16 | F36: =SUM(F31:F35) -> 21 | G36: =SUM(G31:G35) -> 23 | H36: =SUM(H31:H35) -> 25 | I36: =SUM(I31:I35) -> 25 | J36: =SUM(J31:J35) -> 16 | ... AH36: =SUM(AH31:AH35) -> 474 | AI36: =IFERROR(AH36/AH36,0) -> 1 | AJ36: =IFERROR(AH36/COUNTIF(C36:AG36,">0"),0) -> 17.555556
B38: 5. MINAS MAIS
B39: FROTA | C39: 4 | D39: 0 | E39: 3 | F39: 6 | G39: 7 | H39: 7 | I39: 8 | J39: 6 | K39: 0 | L39: 4 | M39: 13 | N39: 3 | O39: 8 | P39: 11 | Q39: 0 | R39: 0 | S39: 5 | T39: 7 | U39: 5 | V39: 6 | W39: 4 | X39: 10 | Y39: 0 | Z39: 4 | AA39: 8 | AB39: 6 | AC39: 5 | AD39: 8 | AE39: 7 | AF39: 0 | AG39: 3 | AH39: =SUM(C39:AG39) -> 158 | AI39: =IFERROR(AH39/$AH$44,0) -> 0.41361257 | AJ39: =IFERROR(AH39/COUNTIF($C$44:$AG$44,">0"),0) -> 6.32
B40: TRANSPREDI | C40: 3 | D40: 0 | E40: 0 | F40: 3 | G40: 0 | H40: 1 | I40: 2 | J40: 0 | K40: 0 | L40: 1 | M40: 1 | N40: 2 | O40: 0 | P40: 3 | Q40: 0 | R40: 0 | S40: 0 | T40: 1 | U40: 2 | V40: 0 | W40: 0 | X40: 2 | Y40: 0 | Z40: 0 | AA40: 0 | AB40: 2 | AC40: 1 | AD40: 0 | AE40: 1 | AF40: 0 | AG40: 1 | AH40: =SUM(C40:AG40) -> 26 | AI40: =IFERROR(AH40/$AH$44,0) -> 0.068062827 | AJ40: =IFERROR(AH40/COUNTIF($C$44:$AG$44,">0"),0) -> 1.04
B41: TRANSPREDI CONTRATADO | C41: 2 | D41: 0 | E41: 3 | F41: 2 | G41: 1 | H41: 2 | I41: 2 | J41: 2 | K41: 0 | L41: 1 | M41: 2 | N41: 1 | O41: 1 | P41: 4 | Q41: 0 | R41: 0 | S41: 2 | T41: 1 | U41: 2 | V41: 1 | W41: 0 | X41: 0 | Y41: 0 | Z41: 2 | AA41: 2 | AB41: 3 | AC41: 0 | AD41: 1 | AE41: 0 | AF41: 0 | AG41: 4 | AH41: =SUM(C41:AG41) -> 41 | AI41: =IFERROR(AH41/$AH$44,0) -> 0.10732984 | AJ41: =IFERROR(AH41/COUNTIF($C$44:$AG$44,">0"),0) -> 1.64
B42: TERCEIROS | C42: 2 | D42: 0 | E42: 11 | F42: 6 | G42: 11 | H42: 7 | I42: 10 | J42: 5 | K42: 0 | L42: 5 | M42: 2 | N42: 4 | O42: 1 | P42: 5 | Q42: 0 | R42: 0 | S42: 5 | T42: 6 | U42: 1 | V42: 3 | W42: 9 | X42: 1 | Y42: 0 | Z42: 10 | AA42: 5 | AB42: 6 | AC42: 0 | AD42: 3 | AE42: 2 | AF42: 0 | AG42: 10 | AH42: =SUM(C42:AG42) -> 130 | AI42: =IFERROR(AH42/$AH$44,0) -> 0.34031414 | AJ42: =IFERROR(AH42/COUNTIF($C$44:$AG$44,">0"),0) -> 5.2
B43: FOB | C43: 1 | D43: 0 | E43: 0 | F43: 0 | G43: 0 | H43: 0 | I43: 1 | J43: 0 | K43: 0 | L43: 0 | M43: 1 | N43: 2 | O43: 0 | P43: 1 | Q43: 0 | R43: 0 | S43: 0 | T43: 0 | U43: 1 | V43: 3 | W43: 2 | X43: 0 | Y43: 0 | Z43: 1 | AA43: 3 | AB43: 0 | AC43: 3 | AD43: 4 | AE43: 2 | AF43: 0 | AG43: 2 | AH43: =SUM(C43:AG43) -> 27 | AI43: =IFERROR(AH43/$AH$44,0) -> 0.070680628 | AJ43: =IFERROR(AH43/COUNTIF($C$44:$AG$44,">0"),0) -> 1.08
B44: TOTAL | C44: =SUM(C39:C43) -> 12 | D44: =SUM(D39:D43) -> 0 | E44: =SUM(E39:E43) -> 17 | F44: =SUM(F39:F43) -> 17 | G44: =SUM(G39:G43) -> 19 | H44: =SUM(H39:H43) -> 17 | I44: =SUM(I39:I43) -> 23 | J44: =SUM(J39:J43) -> 13 | ... X44: =SUM(X39:X43) -> 13 | Y44: 0 | Z44: =SUM(Z39:Z43) -> 17 | AA44: =SUM(AA39:AA43) -> 18 | AB44: =SUM(AB39:AB43) -> 17 | AC44: =SUM(AC39:AC43) -> 9 | AD44: =SUM(AD39:AD43) -> 16 | AE44: =SUM(AE39:AE43) -> 12 | AF44: =SUM(AF39:AF43) -> 0 | AG44: =SUM(AG39:AG43) -> 20 | AH44: =SUM(AH39:AH43) -> 382 | AI44: =IFERROR(AH44/AH44,0) -> 1 | AJ44: =IFERROR(AH44/COUNTIF(C44:AG44,">0"),0) -> 15.28
B46: 6. NORDESTE MAIS
...

Sheet Frota
B1: FROTA DISPONÍVEL POR EMPRESA
B2: Área de entrada — atualize a quantidade de veículos quando houver mudança na frota.
B4: QUANTIDADE DE VEÍCULOS
B5: EMPRESA | C5: DISTRIBUIÇÃO | D5: COLETA / TRANSF. | E5: TOTAL DA FROTA | F5: PARTICIPAÇÃO %
B6: Predilecta | C6: 47 | D6: 9 | E6: =SUM(C6:D6) -> 56 | F6: =IFERROR(E6/$E$12,0) -> 0.39160839
B7: Salsaretti | C7: 12 | D7: 0 | E7: =SUM(C7:D7) -> 12 | F7: =IFERROR(E7/$E$12,0) -> 0.083916084
B8: Stella d'Oro | C8: 20 | D8: 3 | E8: =SUM(C8:D8) -> 23 | F8: =IFERROR(E8/$E$12,0) -> 0.16083916
B9: Sofruta | C9: 26 | D9: 1 | E9: =SUM(C9:D9) -> 27 | F9: =IFERROR(E9/$E$12,0) -> 0.18881119
B10: Minas Mais | C10: 20 | D10: 1 | E10: =SUM(C10:D10) -> 21 | F10: =IFERROR(E10/$E$12,0) -> 0.14685315
B11: Nordeste Mais | C11: 3 | D11: 1 | E11: =SUM(C11:D11) -> 4 | F11: =IFERROR(E11/$E$12,0) -> 0.027972028
B12: TOTAL | C12: =SUM(C6:C11) -> 128 | D12: =SUM(D6:D11) -> 15 | E12: =SUM(E6:E11) -> 143 | F12: =IFERROR(E12/E12,0) -> 1
B14: Legenda:
B15: • Células com fundo amarelo e número azul = entrada manual.
B16: • Demais células contêm fórmulas — não digitar sobre elas.
B17: • A coluna DISTRIBUIÇÃO é a base do cálculo de "viagens por veículo" no Consolidado.

Sheet Base de Dados
B1: BASE DE DADOS (formato tabela)
B2: Tabela normalizada, pronta para Tabela Dinâmica e filtros. Alimentada automaticamente pela aba Lançamento Diário.
B4: DATA | C4: DIA | D4: SEMANA | E4: EMPRESA | F4: MODALIDADE | G4: GRUPO | H4: CARREGAMENTOS
B5: 46235 | C5: 1 | D5: sáb | E5: Predilecta | F5: FROTA | G5: PRÓPRIO | H5: =IF('Lançamento Diário'!C7="","",'Lançamento Diário'!C7) -> 15
B6: 46236 | C6: 2 | D6: dom | E6: Predilecta | F6: FROTA | G6: PRÓPRIO | H6: =IF('Lançamento Diário'!D7="","",'Lançamento Diário'!D7) -> 9
B7: 46237 | C7: 3 | D7: seg | E7: Predilecta | F7: FROTA | G7: PRÓPRIO | H7: =IF('Lançamento Diário'!E7="","",'Lançamento Diário'!E7) -> 12
B8: 46238 | C8: 4 | D8: ter | E8: Predilecta | F8: FROTA | G8: PRÓPRIO | H8: =IF('Lançamento Diário'!F7="","",'Lançamento Diário'!F7) -> 17
B9: 46239 | C9: 5 | D9: qua | E9: Predilecta | F9: FROTA | G9: PRÓPRIO | H9: =IF('Lançamento Diário'!G7="","",'Lançamento Diário'!G7) -> 20
B10: 46240 | C10: 6 | D10: qui | E10: Predilecta | F10: FROTA | G10: PRÓPRIO | H10: =IF('Lançamento Diário'!H7="","",'Lançamento Diário'!H7) -> 14
B11: 46241 | C11: 7 | D11: sex | E11: Predilecta | F11: FROTA | G11: PRÓPRIO | H11: =IF('Lançamento Diário'!I7="","",'Lançamento Diário'!I7) -> 17
B12: 46242 | C12: 8 | D12: sáb | E12: Predilecta | F12: FROTA | G12: PRÓPRIO | H12: =IF('Lançamento Diário'!J7="","",'Lançamento Diário'!J7) -> 20
B13: 46243 | C13: 9 | D13: dom | E13: Predilecta | F13: FROTA | G13: PRÓPRIO | H13: =IF('Lançamento Diário'!K7="","",'Lançamento Diário'!K7) -> 0
B14: 46244 | C14: 10 | D14: seg | E14: Predilecta | F14: FROTA | G14: PRÓPRIO | H14: =IF('Lançamento Diário'!L7="","",'Lançamento Diário'!L7) -> 0
B15: 46245 | C15: 11 | D15: ter | E15: Predilecta | F15: FROTA | G15: PRÓPRIO | H15: =IF('Lançamento Diário'!M7="","",'Lançamento Diário'!M7) -> 16
B16: 46246 | C16: 12 | D16: qua | E16: Predilecta | F16: FROTA | G16: PRÓPRIO | H16: =IF('Lançamento Diário'!N7="","",'Lançamento Diário'!N7) -> 19
B17: 46247 | C17: 13 | D17: qui | E17: Predilecta | F17: FROTA | G17: PRÓPRIO | H17: =IF('Lançamento Diário'!O7="","",'Lançamento Diário'!O7) -> 16
B18: 46248 | C18: 14 | D18: sex | E18: Predilecta | F18: FROTA | G18: PRÓPRIO | H18: =IF('Lançamento Diário'!P7="","",'Lançamento Diário'!P7) -> 20
B19: 46249 | C19: 15 | D19: sáb | E19: Predilecta | F19: FROTA | G19: PRÓPRIO | H19: =IF('Lançamento Diário'!Q7="","",'Lançamento Diário'!Q7) -> 11
B20: 46250 | C20: 16 | D20: dom | E20: Predilecta | F20: FROTA | G20: PRÓPRIO | H20: =IF('Lançamento Diário'!R7="","",'Lançamento Diário'!R7) -> 0
B21: 46251 | C21: 17 | D21: seg | E21: Predilecta | F21: FROTA | G21: PRÓPRIO | H21: =IF('Lançamento Diário'!S7="","",'Lançamento Diário'!S7) -> 8
B22: 46252 | C22: 18 | D22: ter | E22: Predilecta | F22: FROTA | G22: PRÓPRIO | H22: =IF('Lançamento Diário'!T7="","",'Lançamento Diário'!T7) -> 15
B23: 46253 | C23: 19 | D23: qua | E23: Predilecta | F23: FROTA | G23: PRÓPRIO | H23: =IF('Lançamento Diário'!U7="","",'Lançamento Diário'!U7) -> 16
B24: 46254 | C24: 20 | D24: qui | E24: Predilecta | F24: FROTA | G24: PRÓPRIO | H24: =IF('Lançamento Diário'!V7="","",'Lançamento Diário'!V7) -> 16
B25: 46255 | C25: 21 | D25: sex | E25: Predilecta | F25: FROTA | G25: PRÓPRIO | H25: =IF('Lançamento Diário'!W7="","",'Lançamento Diário'!W7) -> 19
B26: 46256 | C26: 22 | D26: sáb | E26: Predilecta | F26: FROTA | G26: PRÓPRIO | H26: =IF('Lançamento Diário'!X7="","",'Lançamento Diário'!X7) -> 15
B27: 46257 | C27: 23 | D27: dom | E27: Predilecta | F27: FROTA | G27: PRÓPRIO | H27: =IF('Lançamento Diário'!Y7="","",'Lançamento Diário'!Y7) -> 0
B28: 46258 | C28: 24 | D28: seg | E28: Predilecta | F28: FROTA | G28: PRÓPRIO | H28: =IF('Lançamento Diário'!Z7="","",'Lançamento Diário'!Z7) -> 13
B29: 46259 | C29: 25 | D29: ter | E29: Predilecta | F29: FROTA | G29: PRÓPRIO | H29: =IF('Lançamento Diário'!AA7="","",'Lançamento Diário'!AA7) -> 10
B30: 46260 | C30: 26 | D30: qua | E30: Predilecta | F30: FROTA | G30: PRÓPRIO | H30: =IF('Lançamento Diário'!AB7="","",'Lançamento Diário'!AB7) -> 22
B31: 46261 | C31: 27 | D31: qui | E31: Predilecta | F31: FROTA | G31: PRÓPRIO | H31: =IF('Lançamento Diário'!AC7="","",'Lançamento Diário'!AC7) -> 16
B32: 46262 | C32: 28 | D32: sex | E32: Predilecta | F32: FROTA | G32: PRÓPRIO | H32: =IF('Lançamento Diário'!AD7="","",'Lançamento Diário'!AD7) -> 16
B33: 46263 | C33: 29 | D33: sáb | E33: Predilecta | F33: FROTA | G33: PRÓPRIO | H33: =IF('Lançamento Diário'!AE7="","",'Lançamento Diário'!AE7) -> 15
B34: 46264 | C34: 30 | D34: dom | E34: Predilecta | F34: FROTA | G34: PRÓPRIO | H34: =IF('Lançamento Diário'!AF7="","",'Lançamento Diário'!AF7) -> 0
B35: 46265 | C35: 31 | D35: seg | E35: Predilecta | F35: FROTA | G35: PRÓPRIO | H35: =IF('Lançamento Diário'!AG7="","",'Lançamento Diário'!AG7) -> 2
B36: 46235 | C36: 1 | D36: sáb | E36: Predilecta | F36: TRANSPREDI | G36: PRÓPRIO | H36: =IF('Lançamento Diário'!C8="","",'Lançamento Diário'!C8) -> 2
B37: 46236 | C37: 2 | D37: dom | E37: Predilecta | F37: TRANSPREDI | G37: PRÓPRIO | H37: =IF('Lançamento Diário'!D8="","",'Lançamento Diário'!D8) -> 3
B38: 46237 | C38: 3 | D38: seg | E38: Predilecta | F38: TRANSPREDI | G38: PRÓPRIO | H38: =IF('Lançamento Diário'!E8="","",'Lançamento Diário'!E8) -> 1
B39: 46238 | C39: 4 | D39: ter | E39: Predilecta | F39: TRANSPREDI | G39: PRÓPRIO | H39: =IF('Lançamento Diário'!F8="","",'Lançamento Diário'!F8) -> 4
B40: 46239 | C40: 5 | D40: qua | E40: Predilecta | F40: TRANSPREDI | G40: PRÓPRIO | H40: =IF('Lançamento Diário'!G8="","",'Lançamento Diário'!G8) -> 4
B41: 46240 | C41: 6 | D41: qui | E41: Predilecta | F41: TRANSPREDI | G41: PRÓPRIO | H41: =IF('Lançamento Diário'!H8="","",'Lançamento Diário'!H8) -> 5
...

Sheet Notas e Critérios
B1: NOTAS E CRITÉRIOS
B4: ESTRUTURA DO ARQUIVO
B5: Dashboard | C5: Painel gerencial com indicadores-chave e cinco gráficos. Somente leitura.
B6: Consolidado | C6: Resumo do mês: carregamentos por empresa e modalidade, próprio x terceiro x FOB, aproveitamento da frota e indicadores auxiliares que alimentam o Dashboard.
B7: Divulgação Diária | C7: Página única, pronta para impressão ou PDF, com o resultado acumulado do mês. Atualiza sozinha a cada lançamento.
B8: Totais Diários | C8: Visão dia a dia por modalidade e por empresa, com escala de cores para identificar picos e vales de operação.
B9: Lançamento Diário | C9: Única aba de digitação do movimento. Um bloco por empresa e um bloco de total geral calculado.
B10: Base de Dados | C10: Mesma informação em formato de tabela (930 linhas), pronta para Tabela Dinâmica e filtros.
B11: Frota | C11: Quantidade de veículos por empresa, separada entre Distribuição e Coleta/Transferência.
B12: Notas e Critérios | C12: Esta aba.
B14: CRITÉRIOS DE CÁLCULO
B15: FROTA PRÓPRIA | C15: FROTA + TRANSPREDI. É o indicador de destaque do grupo — aparece primeiro e em vermelho na página de divulgação.
B16: TERCEIRO | C16: TERCEIROS + TRANSPREDI CONTRATADO.
B17: FOB | C17: Fica FORA do comparativo próprio x terceiro, pois a carga é retirada pelo cliente e não consome frota. Aparece sempre como número à parte.
B18: Base do comparativo | C18: % Frota própria e % Terceiro são calculados sobre PRÓPRIO + TERCEIRO, sem o FOB. O total geral (com FOB) é exibido em coluna separada.
B19: Marcas | C19: Cada empresa aparece com seu logotipo e sua cor institucional na página de divulgação e na aba Frota.
B20: Viagens por veículo (mês) | C20: Carregamentos PRÓPRIOS ÷ veículos de Distribuição da aba Frota — mesma fórmula do campo "Média Viagens" original.
B21: Dias com operação | C21: Quantidade de dias com pelo menos um carregamento lançado. Domingos e dias ainda não preenchidos não entram nas médias.
B22: Percentuais | C22: Sempre calculados sobre o total da própria empresa ou do grupo, com proteção contra divisão por zero (IFERROR).
B24: CORREÇÕES APLICADAS EM RELAÇÃO AO ARQUIVO ORIGINAL
B25: Erro de referência | C25: A linha de total geral da frota própria retornava erro de referência na coluna do dia 18. A fórmula foi refeita.
B26: Totais gerais incompletos | C26: As linhas de total geral somavam apenas 5 das 6 empresas — Nordeste Mais ficava de fora do movimento diário. Agora as 6 empresas são somadas.
B27: Referências deslocadas | C27: No dia 18, as linhas de TRANSPREDI, CONTRATADO, TERCEIROS e FOB do total geral apontavam para a modalidade errada. Corrigido.
B28: Vínculo externo quebrado | C28: A linha de total do dia dependia do arquivo "Comparativo Jun x Jul", que não acompanha a planilha. Substituído por soma interna.
B29: Percentuais com base errada | C29: No bloco da Minas Mais, três percentuais dividiam pelo total da Predilecta. Corrigido para o total da própria empresa.
B30: Totais fixos digitados | C30: Células de total dos dias 3 e 26 estavam com valor 0 digitado por cima da fórmula. Restauradas como fórmula.
B31: Total da frota Nordeste Mais | C31: O total somava indevidamente a frota da Minas Mais. Corrigido para considerar apenas a própria empresa.
B32: Veículos Nordeste Mais | C32: O cálculo de média usava 3 veículos, enquanto a tabela de frota informa 4. Passou a usar a tabela de frota (4). Se o correto for 3, basta ajustar na aba Frota.
B33: Identificação das empresas | C33: As empresas eram identificadas apenas por logotipos flutuantes. Agora cada bloco tem o nome escrito, o que permite consolidar e filtrar os dados.
B35: COMO USAR NO DIA A DIA
B36: 1. Lançar | C36: Abra a aba Lançamento Diário e preencha as células amarelas na coluna do dia correspondente.
B37: 2. Conferir | C37: Os totais por empresa e o total geral são atualizados na hora.
B38: 3. Analisar | C38: O Dashboard e o Consolidado se atualizam automaticamente — nenhuma fórmula precisa ser refeita.
B39: 4. Novo mês | C39: Salve uma cópia do arquivo, apague apenas as células amarelas da aba Lançamento Diário e ajuste as datas da linha 4.
