Workbook

Sheet PREDILECTA
B1: 46174 | C1: 46175 | D1: 46176 | E1: 46177 | F1: 46178 | G1: 46179 | H1: 46180 | I1: 46181 | J1: 46182 | K1: 46183 | L1: 46184 | M1: 46185 | N1: 46186 | O1: 46187 | P1: 46188 | Q1: 46189 | R1: 46190 | S1: 46191 | T1: 46192 | U1: 46193 | V1: 46194 | W1: 46195 | X1: 46196 | Y1: 46197 | Z1: 46198 | AA1: 46199 | AB1: 46200 | AC1: 46201 | AD1: 46202 | AE1: 46203 | AF1: TOTAL | AG1: % | AH1: PROP X TERC | AI1: % | AJ1: Qtd Veículos | AK1: Média Viagens
B2: seg | C2: ter | D2: qua | E2: qui | F2: sex | G2: sáb | H2: dom | I2: seg | J2: ter | K2: qua | L2: qui | M2: sex | N2: sáb | O2: dom | P2: seg | Q2: ter | R2: qua | S2: qui | T2: sex | U2: sáb | V2: dom | W2: seg | X2: ter | Y2: qua | Z2: qui | AA2: sex | AB2: sáb | AC2: dom | AD2: seg | AE2: ter
A3: FROTA | B3: 15 | C3: 15 | D3: 19 | E3: 13 | F3: 13 | G3: 17 | H3: 0 | I3: 12 | J3: 16 | K3: 16 | L3: 15 | M3: 13 | N3: 15 | O3: 0 | P3: 9 | Q3: 20 | R3: 11 | S3: 15 | T3: 26 | U3: 16 | V3: 0 | W3: 10 | X3: 18 | Y3: 24 | Z3: 17 | AA3: 22 | AB3: 17 | AC3: 0 | AD3: 2 | AE3: 14 | AF3: =SUM(B3:AE3) -> 400 | AG3: =AF3/$AF$7 -> 0.55555556 | AH3: =AF3+AF4 -> 473 | AI3: =AH3/AH7 -> 0.70386905 | AJ3: 47 | AK3: =AH3/AJ3 -> 10.06383
A4: TRANSPREDI | B4: 3 | C4: 3 | D4: 3 | E4: 1 | F4: 3 | G4: 5 | H4: 0 | I4: 1 | J4: 4 | K4: 3 | L4: 4 | M4: 5 | N4: 1 | O4: 0 | P4: 1 | Q4: 1 | R4: 4 | S4: 3 | T4: 3 | U4: 3 | V4: 0 | W4: 1 | X4: 2 | Y4: 3 | Z4: 4 | AA4: 4 | AB4: 3 | AC4: 0 | AD4: 1 | AE4: 4 | AF4: =SUM(B4:AE4) -> 73 | AG4: =AF4/$AF$7 -> 0.10138889 | AH4: =AF5 -> 199 | AI4: =AH4/AH7 -> 0.29613095
A5: TERCEIROS | B5: 8 | C5: 8 | D5: 15 | E5: 12 | F5: 9 | G5: 11 | H5: 0 | I5: 3 | J5: 1 | K5: 7 | L5: 7 | M5: 0 | N5: 1 | O5: 0 | P5: 9 | Q5: 15 | R5: 8 | S5: 2 | T5: 5 | U5: 0 | V5: 0 | W5: 7 | X5: 9 | Y5: 4 | Z5: 10 | AA5: 8 | AB5: 7 | AC5: 0 | AD5: 17 | AE5: 16 | AF5: =SUM(B5:AE5) -> 199 | AG5: =AF5/$AF$7 -> 0.27638889
A6: FOB | B6: 1 | C6: 6 | D6: 3 | E6: 0 | F6: 0 | G6: 0 | H6: 0 | I6: 2 | J6: 3 | K6: 3 | L6: 2 | M6: 1 | N6: 0 | O6: 0 | P6: 2 | Q6: 3 | R6: 2 | S6: 2 | T6: 3 | U6: 1 | V6: 0 | W6: 3 | X6: 2 | Y6: 2 | Z6: 2 | AA6: 0 | AB6: 0 | AC6: 0 | AD6: 4 | AE6: 1 | AF6: =SUM(B6:AE6) -> 48 | AG6: =AF6/$AF$7 -> 0.066666667
B7: =SUM(B3:B6) -> 27 | C7: =SUM(C3:C6) -> 32 | D7: =SUM(D3:D6) -> 40 | E7: =SUM(E3:E6) -> 26 | F7: =SUM(F3:F6) -> 25 | G7: =SUM(G3:G6) -> 33 | H7: =SUM(H3:H6) -> 0 | I7: =SUM(I3:I6) -> 18 | ... AH7: =SUM(AH3:AH6) -> 672 | AI7: =SUM(AI3:AI4) -> 1
A8: FROTA | B8: =B3/B$7 -> 0.55555556 | C8: =C3/C$7 -> 0.46875 | D8: =D3/D$7 -> 0.475 | E8: =E3/E$7 -> 0.5 | F8: =F3/F$7 -> 0.52 | G8: =G3/G$7 -> 0.51515152 | H8: =H3/H$7 -> #DIV/0! | I8: =I3/I$7 -> 0.66666667 | ... AF8: =AF3/AF$7 -> 0.55555556
A9: TRANSPREDI | B9: =B4/B$7 -> 0.11111111 | C9: =C4/C$7 -> 0.09375 | D9: =D4/D$7 -> 0.075 | E9: =E4/E$7 -> 0.038461538 | F9: =F4/F$7 -> 0.12 | G9: =G4/G$7 -> 0.15151515 | H9: =H4/H$7 -> #DIV/0! | I9: =I4/I$7 -> 0.055555556 | ... AF9: =AF4/AF$7 -> 0.10138889
A10: TERCEIROS | B10: =B5/B$7 -> 0.2962963 | C10: =C5/C$7 -> 0.25 | D10: =D5/D$7 -> 0.375 | E10: =E5/E$7 -> 0.46153846 | F10: =F5/F$7 -> 0.36 | G10: =G5/G$7 -> 0.33333333 | H10: =H5/H$7 -> #DIV/0! | I10: =I5/I$7 -> 0.16666667 | ... AF10: =AF5/AF$7 -> 0.27638889
A11: FOB | B11: =B6/B$7 -> 0.037037037 | C11: =C6/C$7 -> 0.1875 | D11: =D6/D$7 -> 0.075 | E11: =E6/E$7 -> 0 | F11: =F6/F$7 -> 0 | G11: =G6/G$7 -> 0 | H11: =H6/H$7 -> #DIV/0! | I11: =I6/I$7 -> 0.11111111 | ... AF11: =AF6/AF$7 -> 0.066666667
B12: =SUM(B8:B11) -> 1 | C12: =SUM(C8:C11) -> 1 | D12: =SUM(D8:D11) -> 1 | E12: =SUM(E8:E11) -> 1 | F12: =SUM(F8:F11) -> 1 | G12: =SUM(G8:G11) -> 1 | H12: =SUM(H8:H11) -> #DIV/0! | I12: =SUM(I8:I11) -> 1 | ... AF12: =SUM(AF8:AF11) -> 1
A13: FROTA | B13: 15 | C13: =B13+C3 -> 30 | D13: =C13+D3 -> 49 | E13: =D13+E3 -> 62 | F13: =E13+F3 -> 75 | G13: =F13+G3 -> 92 | H13: =G13+H3 -> 92 | I13: =H13+I3 -> 104 | J13: =I13+J3 -> 120 | ... AE13: =AD13+AE3 -> 400
A14: TRANSPREDI | B14: 3 | C14: =B14+C4 -> 6 | D14: =C14+D4 -> 9 | E14: =D14+E4 -> 10 | F14: =E14+F4 -> 13 | G14: =F14+G4 -> 18 | H14: =G14+H4 -> 18 | I14: =H14+I4 -> 19 | J14: =I14+J4 -> 23 | ... AE14: =AD14+AE4 -> 73
A15: TERCEIROS | B15: 8 | C15: =B15+C5 -> 16 | D15: =C15+D5 -> 31 | E15: =D15+E5 -> 43 | F15: =E15+F5 -> 52 | G15: =F15+G5 -> 63 | H15: =G15+H5 -> 63 | I15: =H15+I5 -> 66 | J15: =I15+J5 -> 67 | ... AE15: =AD15+AE5 -> 199
A16: FOB | B16: 1 | C16: =B16+C6 -> 7 | D16: =C16+D6 -> 10 | E16: =D16+E6 -> 10 | F16: =E16+F6 -> 10 | G16: =F16+G6 -> 10 | H16: =G16+H6 -> 10 | I16: =H16+I6 -> 12 | J16: =I16+J6 -> 15 | ... AE16: =AD16+AE6 -> 48
B17: =SUM(B13:B16) -> 27 | C17: =SUM(C13:C16) -> 59 | D17: =SUM(D13:D16) -> 99 | E17: =SUM(E13:E16) -> 125 | F17: =SUM(F13:F16) -> 150 | G17: =SUM(G13:G16) -> 183 | H17: =SUM(H13:H16) -> 183 | I17: =SUM(I13:I16) -> 201 | ... AE17: =SUM(AE13:AE16) -> 720
A18: FROTA | B18: =B13/B$17 -> 0.55555556 | C18: =C13/C17 -> 0.50847458 | D18: =D13/D17 -> 0.49494949 | E18: =E13/E17 -> 0.496 | F18: =F13/F17 -> 0.5 | G18: =G13/G17 -> 0.50273224 | H18: =H13/H17 -> 0.50273224 | I18: =I13/I17 -> 0.51741294 | J18: =J13/J17 -> 0.53333333 | ... AE18: =AE13/AE17 -> 0.55555556
A19: TRANSPREDI | B19: =B14/B$17 -> 0.11111111 | C19: =C14/C$17 -> 0.10169492 | D19: =D14/D$17 -> 0.090909091 | E19: =E14/E$17 -> 0.08 | F19: =F14/F$17 -> 0.086666667 | G19: =G14/G$17 -> 0.098360656 | H19: =H14/H$17 -> 0.098360656 | I19: =I14/I$17 -> 0.094527363 | ... AE19: =AE14/AE$17 -> 0.10138889
A20: TERCEIROS | B20: =B15/B$17 -> 0.2962963 | C20: =C15/C$17 -> 0.27118644 | D20: =D15/D$17 -> 0.31313131 | E20: =E15/E$17 -> 0.344 | F20: =F15/F$17 -> 0.34666667 | G20: =G15/G$17 -> 0.3442623 | H20: =H15/H$17 -> 0.3442623 | I20: =I15/I$17 -> 0.32835821 | ... AE20: =AE15/AE$17 -> 0.27638889
A21: FOB | B21: =B16/B$17 -> 0.037037037 | C21: =C16/C$17 -> 0.11864407 | D21: =D16/D$17 -> 0.1010101 | E21: =E16/E$17 -> 0.08 | F21: =F16/F$17 -> 0.066666667 | G21: =G16/G$17 -> 0.054644809 | H21: =H16/H$17 -> 0.054644809 | I21: =I16/I$17 -> 0.059701493 | ... AE21: =AE16/AE$17 -> 0.066666667
B22: =SUM(B18:B21) -> 1 | C22: =SUM(C18:C21) -> 1 | D22: =SUM(D18:D21) -> 1 | E22: =SUM(E18:E21) -> 1 | F22: =SUM(F18:F21) -> 1 | G22: =SUM(G18:G21) -> 1 | H22: =SUM(H18:H21) -> 1 | I22: =SUM(I18:I21) -> 1 | ... AF22: =SUM(AF18:AF21) -> 0
A23: FROTA/TRANSPREDI | B23: =B3+B4 -> 18 | C23: =C3+C4 -> 18 | D23: =D3+D4 -> 22 | E23: =E3+E4 -> 14 | F23: =F3+F4 -> 16 | G23: =G3+G4 -> 22 | H23: =H3+H4 -> 0 | I23: =I3+I4 -> 13 | ... AE23: =AE3+AE4 -> 18 | AF23: =SUM(B23:AE23) -> 473
A24: TERCEIROS | B24: =B5 -> 8 | C24: =C5 -> 8 | D24: =D5 -> 15 | E24: =E5 -> 12 | F24: =F5 -> 9 | G24: =G5 -> 11 | H24: =H5 -> 0 | I24: =I5 -> 3 | ... AE24: =AE5 -> 16 | AF24: =SUM(B24:AE24) -> 199
A25: FOB | B25: =B6 -> 1 | C25: =C6 -> 6 | D25: =D6 -> 3 | E25: =E6 -> 0 | F25: =F6 -> 0 | G25: =G6 -> 0 | H25: =H6 -> 0 | I25: =I6 -> 2 | ... AE25: =AE6 -> 1 | AF25: =SUM(B25:AE25) -> 48
B26: =SUM(B23:B25) -> 27 | C26: =SUM(C23:C25) -> 32 | D26: =SUM(D23:D25) -> 40 | E26: =SUM(E23:E25) -> 26 | F26: =SUM(F23:F25) -> 25 | G26: =SUM(G23:G25) -> 33 | H26: =SUM(H23:H25) -> 0 | I26: =SUM(I23:I25) -> 18 | ... AF26: =SUM(AF23:AF25) -> 720
A27: FROTA/TRANSPREDI | B27: =B23/B$26 -> 0.66666667 | C27: =C23/C$26 -> 0.5625 | D27: =D23/D$26 -> 0.55 | E27: =E23/E$26 -> 0.53846154 | F27: =F23/F$26 -> 0.64 | G27: =G23/G$26 -> 0.66666667 | H27: =H23/H$26 -> #DIV/0! | I27: =I23/I$26 -> 0.72222222 | ... AF27: =AF23/AF$26 -> 0.65694444
A28: TERCEIROS | B28: =B24/B$26 -> 0.2962963 | C28: =C24/C$26 -> 0.25 | D28: =D24/D$26 -> 0.375 | E28: =E24/E$26 -> 0.46153846 | F28: =F24/F$26 -> 0.36 | G28: =G24/G$26 -> 0.33333333 | H28: =H24/H$26 -> #DIV/0! | I28: =I24/I$26 -> 0.16666667 | ... AF28: =AF24/AF$26 -> 0.27638889
A29: FOB | B29: =B25/B$26 -> 0.037037037 | C29: =C25/C$26 -> 0.1875 | D29: =D25/D$26 -> 0.075 | E29: =E25/E$26 -> 0 | F29: =F25/F$26 -> 0 | G29: =G25/G$26 -> 0 | H29: =H25/H$26 -> #DIV/0! | I29: =I25/I$26 -> 0.11111111 | ... AF29: =AF25/AF$26 -> 0.066666667
B30: =SUM(B27:B29) -> 1 | C30: =SUM(C27:C29) -> 1 | D30: =SUM(D27:D29) -> 1 | E30: =SUM(E27:E29) -> 1 | F30: =SUM(F27:F29) -> 1 | G30: =SUM(G27:G29) -> 1 | H30: =SUM(H27:H29) -> #DIV/0! | I30: =SUM(I27:I29) -> 1 | ... AF30: =SUM(AF27:AF29) -> 1
B31: 47 | H31: 1

Sheet Carreg Julho_26
C2: 46204 | D2: 46205 | E2: 46206 | F2: 46207 | G2: 46208 | H2: 46209 | I2: 46210 | J2: 46211 | K2: 46212 | L2: 46213 | M2: 46214 | N2: 46215 | O2: 46216 | P2: 46217 | Q2: 46218 | R2: 46219 | S2: 46220 | T2: 46221 | U2: 46222 | V2: 46223 | W2: 46224 | X2: 46225 | Y2: 46226 | Z2: 46227 | AA2: 46228 | AB2: 46229 | AC2: 46230 | AD2: 46231 | AE2: 46232 | AF2: 46233 | AG2: 46234 | AH2: TOTAL | AI2: % | AJ2: PROP X TERC | AK2: % | AL2: Qtd Veículos | AM2: Média Viagens
C3: qua | D3: qui | E3: sex | F3: sáb | G3: dom | H3: seg | I3: ter | J3: qua | K3: qui | L3: sex | M3: sáb | N3: dom | O3: seg | P3: ter | Q3: qua | R3: qui | S3: sex | T3: sáb | U3: dom | V3: seg | W3: ter | X3: qua | Y3: qui | Z3: sex | AA3: sáb | AB3: dom | AC3: seg | AD3: ter | AE3: qua | AF3: qui | AG3: sex
B4: FROTA | C4: 18 | D4: 29 | E4: 15 | F4: 12 | G4: 10 | H4: 16 | I4: 19 | J4: 20 | K4: 13 | L4: 18 | M4: 15 | N4: 0 | O4: 7 | P4: 20 | Q4: 23 | R4: 18 | S4: 16 | T4: 18 | U4: 11 | V4: 13 | W4: 23 | X4: 18 | Y4: 20 | Z4: 15 | AA4: 25 | AB4: 0 | AC4: 7 | AD4: 26 | AE4: 21 | AF4: 18 | AG4: 19 | AH4: =SUM(C4:AG4) -> 503 | AI4: =AH4/$AH$8 -> 0.61566707 | AJ4: =AH4 -> 503 | AK4: =AJ4/AJ8 -> 0.65494792 | AL4: 47 | AM4: =AJ4/AL4 -> 10.702128 | AO4: =503-AJ4 -> 0
B5: TRANSPREDI | C5: 0 | D5: 0 | E5: 0 | F5: 1 | G5: 0 | H5: 1 | I5: 4 | J5: 2 | K5: 1 | L5: 0 | M5: 2 | N5: 0 | O5: 1 | P5: 1 | Q5: 3 | R5: 2 | S5: 3 | T5: 0 | U5: 0 | V5: 0 | W5: 1 | X5: 1 | Y5: 0 | Z5: 0 | AA5: 0 | AB5: 0 | AC5: 0 | AD5: 0 | AE5: 1 | AF5: 1 | AG5: 0 | AH5: =SUM(C5:AG5) -> 25 | AI5: =AH5/$AH$8 -> 0.030599755 | AJ5: =AH6+AH5 -> 265 | AK5: =AJ5/AJ8 -> 0.34505208
B6: TERCEIROS | C6: 13 | D6: 14 | E6: 12 | F6: 11 | G6: 4 | H6: 13 | I6: 8 | J6: 7 | K6: 3 | L6: 7 | M6: 4 | N6: 0 | O6: 10 | P6: 9 | Q6: 10 | R6: 8 | S6: 8 | T6: 7 | U6: 1 | V6: 5 | W6: 10 | X6: 9 | Y6: 9 | Z6: 7 | AA6: 4 | AB6: 0 | AC6: 12 | AD6: 7 | AE6: 6 | AF6: 8 | AG6: 14 | AH6: =SUM(C6:AG6) -> 240 | AI6: =AH6/$AH$8 -> 0.29375765
B7: FOB | C7: 1 | D7: 1 | E7: 2 | F7: 1 | G7: 0 | H7: 2 | I7: 3 | J7: 4 | K7: 0 | L7: 3 | M7: 1 | N7: 0 | O7: 1 | P7: 4 | Q7: 1 | R7: 1 | S7: 2 | T7: 2 | U7: 0 | V7: 2 | W7: 3 | X7: 2 | Y7: 2 | Z7: 2 | AA7: 0 | AB7: 0 | AC7: 1 | AD7: 1 | AE7: 1 | AF7: 5 | AG7: 1 | AH7: =SUM(C7:AG7) -> 49 | AI7: =AH7/$AH$8 -> 0.05997552
B8: TOTAL | C8: =SUM(C4:C7) -> 32 | D8: =SUM(D4:D7) -> 44 | E8: =SUM(E4:E7) -> 29 | F8: =SUM(F4:F7) -> 25 | G8: =SUM(G4:G7) -> 14 | H8: =SUM(H4:H7) -> 32 | I8: =SUM(I4:I7) -> 34 | J8: =SUM(J4:J7) -> 33 | ... AA8: =SUM(AA4:AA7) -> 29 | AB8: 0 | AC8: =SUM(AC4:AC7) -> 20 | AD8: =SUM(AD4:AD7) -> 34 | AE8: =SUM(AE4:AE7) -> 29 | AF8: =SUM(AF4:AF7) -> 32 | AG8: =SUM(AG4:AG7) -> 34 | AH8: =SUM(AH4:AH7) -> 817 | AI8: =SUM(AI4:AI7) -> 1 | AJ8: =SUM(AJ4:AJ7) -> 768
G9: =E4+F4+G4 -> 37 | N9: =L4+M4+N4 -> 33 | U9: =S4+T4+U4 -> 45 | AB9: =Z4+AA4+AB4 -> 40
AH10: TOTAL | AI10: % | AJ10: PROP X TERC | AK10: % | AL10: Qtd Veículos | AM10: Média Viagens
B11: FROTA | C11: 2 | D11: 3 | E11: 5 | H11: 4 | I11: 5 | J11: 3 | K11: 3 | L11: 4 | M11: 7 | O11: 5 | P11: 6 | Q11: 7 | R11: 5 | S11: 6 | T11: 7 | U11: 0 | V11: 6 | W11: 5 | X11: 5 | Y11: 4 | Z11: 3 | AA11: 6 | AB11: 0 | AC11: 4 | AD11: 6 | AE11: 3 | AF11: 5 | AG11: 3 | AH11: =SUM(C11:AG11) -> 122 | AI11: =AH11/$AH$15 -> 0.48031496 | AJ11: =AH11 -> 122 | AK11: =AJ11/AJ15 -> 0.49593496 | AL11: =C60 -> 12 | AM11: =AJ11/AL11 -> 10.166667
B12: TRANSPREDI | C12: 0 | D12: 1 | E12: 0 | H12: 2 | I12: 2 | J12: 3 | K12: 0 | L12: 0 | M12: 0 | O12: 1 | P12: 1 | Q12: 0 | R12: 1 | S12: 3 | T12: 0 | U12: 0 | V12: 3 | W12: 1 | X12: 2 | Y12: 2 | Z12: 1 | AA12: 0 | AB12: 0 | AC12: 2 | AD12: 4 | AE12: 4 | AF12: 2 | AG12: 4 | AH12: =SUM(C12:AG12) -> 39 | AI12: =AH12/$AH$15 -> 0.15354331 | AJ12: =AH12+AH13 -> 124 | AK12: =AJ12/AJ15 -> 0.50406504
B13: TERCEIROS | C13: 10 | D13: 3 | E13: 5 | H13: 2 | I13: 7 | J13: 7 | K13: 6 | L13: 5 | M13: 1 | O13: 3 | P13: 4 | Q13: 7 | R13: 1 | S13: 6 | T13: 2 | U13: 0 | V13: 1 | W13: 3 | X13: 1 | Y13: 1 | Z13: 0 | AA13: 1 | AB13: 0 | AC13: 1 | AD13: 2 | AE13: 2 | AF13: 0 | AG13: 4 | AH13: =SUM(C13:AG13) -> 85 | AI13: =AH13/$AH$15 -> 0.33464567
B14: FOB | C14: 0 | D14: 0 | E14: 0 | H14: 1 | I14: 2 | J14: 2 | K14: 0 | L14: 0 | M14: 0 | O14: 0 | P14: 0 | Q14: 1 | R14: 1 | S14: 0 | T14: 0 | U14: 0 | V14: 0 | W14: 0 | X14: 0 | Y14: 0 | Z14: 0 | AA14: 0 | AB14: 0 | AC14: 0 | AD14: 0 | AE14: 0 | AF14: 0 | AG14: 1 | AH14: =SUM(C14:AG14) -> 8 | AI14: =AH14/$AH$15 -> 0.031496063
B15: TOTAL | C15: =SUM(C11:C14) -> 12 | D15: =SUM(D11:D14) -> 7 | E15: =SUM(E11:E14) -> 10 | F15: =SUM(F11:F14) -> 0 | G15: =SUM(G11:G14) -> 0 | H15: =SUM(H11:H14) -> 9 | I15: =SUM(I11:I14) -> 16 | J15: =SUM(J11:J14) -> 15 | ... AA15: =SUM(AA11:AA14) -> 7 | AB15: 0 | AC15: =SUM(AC11:AC14) -> 7 | AD15: =SUM(AD11:AD14) -> 12 | AE15: =SUM(AE11:AE14) -> 9 | AF15: =SUM(AF11:AF14) -> 7 | AG15: =SUM(AG11:AG14) -> 12 | AH15: =SUM(AH11:AH14) -> 254 | AI15: =AH15/$AH$15 -> 1 | AJ15: =SUM(AJ11:AJ14) -> 246
G16: =E11+F11+G11 -> 5 | N16: =L11+M11+N11 -> 11 | U16: =S11+T11+U11 -> 13 | AB16: =Z11+AA11+AB11 -> 9
AH17: TOTAL | AI17: % | AJ17: PROP X TERC | AK17: % | AL17: Qtd Veículos | AM17: Média Viagens
B18: FROTA | C18: 8 | D18: 6 | E18: 8 | F18: 11 | G18: 0 | H18: 8 | I18: 9 | J18: 12 | K18: 9 | L18: 0 | M18: 15 | N18: 3 | O18: 11 | P18: 11 | Q18: 7 | R18: 8 | S18: 5 | T18: 12 | U18: 0 | V18: 6 | W18: 9 | X18: 14 | Y18: 13 | Z18: 6 | AA18: 15 | AB18: 0 | AC18: 8 | AD18: 9 | AE18: 13 | AF18: 7 | AG18: 11 | AH18: =SUM(C18:AG18) -> 254 | AI18: =AH18/$AH$22 -> 0.65463918 | AJ18: =AH18 -> 254 | AK18: =AJ18/AJ22 -> 0.69398907 | AL18: =C63 -> 20 | AM18: =AJ18/AL18 -> 12.7
B19: TRANSPREDI | C19: 0 | D19: 0 | E19: 0 | F19: 1 | G19: 0 | H19: 0 | I19: 0 | J19: 2 | K19: 1 | L19: 3 | M19: 2 | N19: 0 | O19: 0 | P19: 3 | Q19: 5 | R19: 5 | S19: 1 | T19: 0 | U19: 0 | V19: 0 | W19: 1 | X19: 1 | Y19: 0 | Z19: 0 | AA19: 0 | AB19: 0 | AC19: 0 | AD19: 0 | AE19: 0 | AF19: 0 | AG19: 0 | AH19: =SUM(C19:AG19) -> 25 | AI19: =AH19/$AH$22 -> 0.06443299 | AJ19: =AH19+AH20 -> 112 | AK19: =AJ19/AJ22 -> 0.30601093
B20: TERCEIROS | C20: 6 | D20: 2 | E20: 5 | F20: 2 | G20: 0 | H20: 7 | I20: 5 | J20: 3 | K20: 6 | L20: 3 | M20: 1 | N20: 0 | O20: 1 | P20: 2 | Q20: 3 | R20: 3 | S20: 2 | T20: 2 | U20: 0 | V20: 5 | W20: 6 | X20: 3 | Y20: 4 | Z20: 3 | AA20: 0 | AB20: 0 | AC20: 1 | AD20: 2 | AE20: 2 | AF20: 2 | AG20: 6 | AH20: =SUM(C20:AG20) -> 87 | AI20: =AH20/$AH$22 -> 0.2242268
B21: FOB | C21: 0 | D21: 0 | E21: 2 | F21: 0 | G21: 0 | H21: 1 | I21: 2 | J21: 0 | K21: 0 | L21: 1 | M21: 0 | N21: 0 | O21: 1 | P21: 3 | Q21: 1 | R21: 0 | S21: 1 | T21: 0 | U21: 0 | V21: 0 | W21: 2 | X21: 3 | Y21: 0 | Z21: 0 | AA21: 0 | AB21: 0 | AC21: 1 | AD21: 0 | AE21: 0 | AF21: 3 | AG21: 1 | AH21: =SUM(C21:AG21) -> 22 | AI21: =AH21/$AH$22 -> 0.056701031
B22: TOTAL | C22: =SUM(C18:C21) -> 14 | D22: =SUM(D18:D21) -> 8 | E22: =SUM(E18:E21) -> 15 | F22: =SUM(F18:F21) -> 14 | G22: =SUM(G18:G21) -> 0 | H22: =SUM(H18:H21) -> 16 | I22: =SUM(I18:I21) -> 16 | J22: =SUM(J18:J21) -> 17 | ... T22: =SUM(T18:T21) -> 14 | U22: 0 | V22: =SUM(V18:V21) -> 11 | W22: =SUM(W18:W21) -> 18 | X22: =SUM(X18:X21) -> 21 | Y22: =SUM(Y18:Y21) -> 17 | Z22: =SUM(Z18:Z21) -> 9 | AA22: =SUM(AA18:AA21) -> 15 | AB22: 0 | AC22: =SUM(AC18:AC21) -> 10 | AD22: =SUM(AD18:AD21) -> 11 | AE22: =SUM(AE18:AE21) -> 15 | AF22: =SUM(AF18:AF21) -> 12 | AG22: =SUM(AG18:AG21) -> 18 | AH22: =SUM(AH18:AH21) -> 388 | AI22: =SUM(AI18:AI21) -> 1 | AJ22: =SUM(AJ18:AJ21) -> 366
G23: =E18+F18+G18 -> 19 | N23: =L18+M18+N18 -> 18 | U23: =S18+T18+U18 -> 17 | AB23: =Z18+AA18+AB18 -> 21
AH24: TOTAL | AI24: % | AJ24: PROP X TERC | AK24: % | AL24: Qtd Veículos | AM24: Média Viagens
B25: FROTA | C25: 10 | D25: 13 | E25: 3 | F25: 6 | G25: 5 | H25: 11 | I25: 7 | J25: 11 | K25: 8 | L25: 5 | M25: 5 | N25: 4 | O25: 0 | P25: 13 | Q25: 8 | R25: 10 | S25: 9 | T25: 15 | U25: 2 | V25: 5 | W25: 9 | X25: 9 | Y25: 11 | Z25: 8 | AA25: 11 | AB25: 0 | AC25: 9 | AD25: 8 | AE25: 9 | AF25: 10 | AG25: 8 | AH25: =SUM(C25:AG25) -> 242 | AI25: =AH25/$AH$29 -> 0.55504587 | AJ25: =AH25 -> 242 | AK25: =AJ25/AJ29 -> 0.58173077 | AL25: =C66 -> 26 | AM25: =AJ25/AL25 -> 9.3076923
B26: TRANSPREDI | C26: 0 | D26: 0 | E26: 0 | F26: 0 | G26: 0 | H26: 1 | I26: 4 | J26: 3 | K26: 3 | L26: 0 | M26: 2 | N26: 0 | O26: 0 | P26: 2 | Q26: 2 | R26: 2 | S26: 3 | T26: 0 | U26: 0 | V26: 0 | W26: 0 | X26: 1 | Y26: 1 | Z26: 2 | AA26: 0 | AB26: 0 | AC26: 0 | AD26: 0 | AE26: 0 | AF26: 1 | AG26: 0 | AH26: =SUM(C26:AG26) -> 27 | AI26: =AH26/$AH$29 -> 0.061926606 | AJ26: =AH26+AH27 -> 174 | AK26: =AJ26/AJ29 -> 0.41826923
B27: TERCEIROS | C27: 8 | D27: 5 | E27: 13 | F27: 8 | G27: 2 | H27: 2 | I27: 6 | J27: 4 | K27: 3 | L27: 7 | M27: 3 | N27: 0 | O27: 0 | P27: 3 | Q27: 10 | R27: 5 | S27: 7 | T27: 4 | U27: 1 | V27: 7 | W27: 10 | X27: 6 | Y27: 8 | Z27: 1 | AA27: 1 | AB27: 0 | AC27: 5 | AD27: 2 | AE27: 8 | AF27: 3 | AG27: 5 | AH27: =SUM(C27:AG27) -> 147 | AI27: =AH27/$AH$29 -> 0.33715596
B28: FOB | C28: 1 | D28: 1 | E28: 3 | F28: 0 | G28: 0 | H28: 0 | I28: 0 | J28: 0 | K28: 1 | L28: 1 | M28: 0 | N28: 0 | O28: 0 | P28: 2 | Q28: 0 | R28: 1 | S28: 0 | T28: 0 | U28: 0 | V28: 1 | W28: 0 | X28: 0 | Y28: 2 | Z28: 3 | AA28: 0 | AB28: 0 | AC28: 1 | AD28: 1 | AE28: 0 | AF28: 1 | AG28: 1 | AH28: =SUM(C28:AG28) -> 20 | AI28: =AH28/$AH$29 -> 0.04587156
C29: =SUM(C25:C28) -> 19 | D29: =SUM(D25:D28) -> 19 | E29: =SUM(E25:E28) -> 19 | F29: =SUM(F25:F28) -> 14 | G29: =SUM(G25:G28) -> 7 | H29: =SUM(H25:H28) -> 14 | I29: =SUM(I25:I28) -> 17 | J29: =SUM(J25:J28) -> 18 | ... AA29: =SUM(AA25:AA28) -> 12 | AB29: 0 | AC29: =SUM(AC25:AC28) -> 15 | AD29: =SUM(AD25:AD28) -> 11 | AE29: =SUM(AE25:AE28) -> 17 | AF29: =SUM(AF25:AF28) -> 15 | AG29: =SUM(AG25:AG28) -> 14 | AH29: =SUM(AH25:AH28) -> 436 | AI29: =SUM(AI25:AI28) -> 1 | AJ29: =SUM(AJ25:AJ28) -> 416
AH31: TOTAL | AI31: % | AJ31: PROP X TERC | AK31: % | AL31: Qtd Veículos | AM31: Média Viagens
B32: FROTA | C32: 9 | D32: 7 | E32: 11 | F32: 7 | H32: 5 | I32: 8 | J32: 7 | K32: 9 | L32: 8 | M32: 4 | N32: 0 | O32: 5 | P32: 9 | Q32: 9 | R32: 4 | S32: 7 | T32: 8 | U32: 0 | V32: 6 | W32: 8 | X32: 5 | Y32: 5 | Z32: 9 | AA32: 7 | AB32: 0 | AC32: 1 | AD32: 5 | AE32: 8 | AF32: 7 | AG32: 8 | AH32: =SUM(C32:AG32) -> 186 | AI32: =AH32/$AH$36 -> 0.42272727 | AJ32: =AH32 -> 186 | AK32: =AJ32/AJ36 -> 0.44819277 | AL32: =C69 -> 20 | AM32: =AJ32/AL32 -> 9.3
B33: TRANSPREDI | C33: 0 | D33: 1 | E33: 1 | F33: 1 | H33: 1 | I33: 3 | J33: 2 | K33: 3 | L33: 3 | M33: 1 | N33: 0 | O33: 2 | P33: 6 | Q33: 0 | R33: 3 | S33: 1 | T33: 1 | U33: 0 | V33: 2 | W33: 2 | X33: 4 | Y33: 0 | Z33: 3 | AA33: 1 | AB33: 0 | AC33: 3 | AD33: 3 | AE33: 4 | AF33: 1 | AG33: 3 | AH33: =SUM(C33:AG33) -> 55 | AI33: =AH33/$AH$36 -> 0.125 | AJ33: =AH33+AH34 -> 229 | AK33: =AJ33/AJ36 -> 0.55180723
B34: TERCEIROS | C34: 11 | D34: 5 | E34: 10 | F34: 2 | H34: 9 | I34: 6 | J34: 11 | K34: 7 | L34: 7 | M34: 7 | N34: 0 | O34: 6 | P34: 6 | Q34: 3 | R34: 3 | S34: 5 | T34: 4 | U34: 0 | V34: 5 | W34: 6 | X34: 3 | Y34: 2 | Z34: 4 | AA34: 5 | AB34: 0 | AC34: 5 | AD34: 9 | AE34: 9 | AF34: 13 | AG34: 11 | AH34: =SUM(C34:AG34) -> 174 | AI34: =AH34/$AH$36 -> 0.39545455
B35: FOB | C35: 1 | D35: 2 | E35: 1 | F35: 0 | H35: 0 | I35: 0 | J35: 3 | K35: 1 | L35: 2 | M35: 0 | N35: 0 | O35: 0 | P35: 1 | Q35: 1 | R35: 0 | S35: 1 | T35: 0 | U35: 0 | V35: 1 | W35: 1 | X35: 3 | Y35: 0 | Z35: 0 | AA35: 0 | AB35: 0 | AC35: 1 | AD35: 2 | AE35: 3 | AF35: 1 | AG35: 0 | AH35: =SUM(C35:AG35) -> 25 | AI35: =AH35/$AH$36 -> 0.056818182
C36: =SUM(C32:C35) -> 21 | D36: =SUM(D32:D35) -> 15 | E36: =SUM(E32:E35) -> 23 | F36: =SUM(F32:F35) -> 10 | G36: =SUM(G32:G35) -> 0 | H36: =SUM(H32:H35) -> 15 | I36: =SUM(I32:I35) -> 17 | J36: =SUM(J32:J35) -> 23 | ... AA36: =SUM(AA32:AA35) -> 13 | AB36: 0 | AC36: =SUM(AC32:AC35) -> 10 | AD36: =SUM(AD32:AD35) -> 19 | AE36: =SUM(AE32:AE35) -> 24 | AF36: =SUM(AF32:AF35) -> 22 | AG36: =SUM(AG32:AG35) -> 22 | AH36: =SUM(AH32:AH35) -> 440 | AI36: =AH36/$AH$36 -> 1 | AJ36: =SUM(AJ32:AJ35) -> 415
AH38: TOTAL | AI38: % | AJ38: PROP X TERC | AK38: % | AL38: Qtd Veículos | AM38: Média Viagens
B39: FROTA | C39: 1 | D39: 3 | E39: 0 | F39: 0 | G39: 0 | H39: 3 | I39: 1 | J39: 1 | K39: 3 | L39: 0 | M39: 2 | N39: 0 | O39: 1 | P39: 0 | Q39: 2 | R39: 1 | S39: 3 | T39: 0 | U39: 0 | V39: 3 | W39: 3 | X39: 2 | Y39: 0 | Z39: 1 | AA39: 3 | AB39: 0 | AC39: 1 | AD39: 1 | AE39: 0 | AF39: 2 | AG39: 0 | AH39: =SUM(C39:AG39) -> 37 | AI39: =AH39/$AH$36 -> 0.084090909 | AJ39: =AH39 -> 37 | AK39: =AJ39/AJ43 -> 0.31623932 | AL39: 3 | AM39: =AJ39/AL39 -> 12.333333
B40: TRANSPREDI | C40: 0 | D40: 0 | E40: 0 | F40: 0 | G40: 0 | H40: 0 | I40: 0 | J40: 0 | K40: 0 | L40: 0 | M40: 2 | N40: 0 | O40: 1 | P40: 0 | Q40: 1 | R40: 0 | S40: 1 | T40: 0 | U40: 0 | V40: 0 | W40: 0 | X40: 2 | Y40: 2 | Z40: 0 | AA40: 0 | AB40: 0 | AC40: 1 | AD40: 1 | AE40: 1 | AF40: 1 | AG40: 3 | AH40: =SUM(C40:AG40) -> 16 | AI40: =AH40/$AH$36 -> 0.036363636 | AJ40: =AH40+AH41 -> 80 | AK40: =AJ40/AJ43 -> 0.68376068
B41: TERCEIROS | C41: 2 | D41: 3 | E41: 2 | F41: 0 | G41: 0 | H41: 3 | I41: 5 | J41: 3 | K41: 2 | L41: 8 | M41: 5 | N41: 0 | O41: 0 | P41: 8 | Q41: 3 | R41: 3 | S41: 1 | T41: 0 | U41: 0 | V41: 0 | W41: 0 | X41: 1 | Y41: 2 | Z41: 1 | AA41: 0 | AB41: 0 | AC41: 2 | AD41: 2 | AE41: 3 | AF41: 4 | AG41: 1 | AH41: =SUM(C41:AG41) -> 64 | AI41: =AH41/$AH$36 -> 0.14545455
B42: FOB | C42: 0 | D42: 0 | E42: 0 | F42: 0 | G42: 0 | H42: 1 | I42: 0 | J42: 0 | K42: 0 | L42: 0 | M42: 0 | N42: 0 | O42: 0 | P42: 1 | Q42: 0 | R42: 0 | S42: 0 | T42: 0 | U42: 0 | V42: 0 | W42: 0 | X42: 0 | Y42: 1 | Z42: 1 | AA42: 0 | AB42: 0 | AC42: 0 | AD42: 0 | AE42: 0 | AF42: 0 | AG42: 0 | AH42: =SUM(C42:AG42) -> 4 | AI42: =AH42/$AH$36 -> 0.0090909091
C43: =SUM(C39:C42) -> 3 | D43: =SUM(D39:D42) -> 6 | E43: =SUM(E39:E42) -> 2 | F43: =SUM(F39:F42) -> 0 | G43: =SUM(G39:G42) -> 0 | H43: =SUM(H39:H42) -> 7 | I43: =SUM(I39:I42) -> 6 | J43: =SUM(J39:J42) -> 4 | ... AA43: =SUM(AA39:AA42) -> 3 | AB43: 0 | AC43: =SUM(AC39:AC42) -> 4 | AD43: =SUM(AD39:AD42) -> 4 | AE43: =SUM(AE39:AE42) -> 4 | AF43: =SUM(AF39:AF42) -> 7 | AG43: =SUM(AG39:AG42) -> 4 | AH43: =SUM(AH39:AH42) -> 121 | AI43: =AH43/$AH$36 -> 0.275 | AJ43: =SUM(AJ39:AJ42) -> 117
...

Sheet SALSARETTI
B1: 46174 | C1: 46175 | D1: 46176 | E1: 46177 | F1: 46178 | G1: 46179 | H1: 46180 | I1: 46181 | J1: 46182 | K1: 46183 | L1: 46184 | M1: 46185 | N1: 46186 | O1: 46187 | P1: 46188 | Q1: 46189 | R1: 46190 | S1: 46191 | T1: 46192 | U1: 46193 | V1: 46194 | W1: 46195 | X1: 46196 | Y1: 46197 | Z1: 46198 | AA1: 46199 | AB1: 46200 | AC1: 46201 | AD1: 46202 | AE1: 46203 | AF1: TOTAL
A2: FROTA | B2: 0 | C2: 3 | D2: 6 | E2: 3 | F2: 3 | G2: 1 | H2: 6 | I2: 0 | J2: 3 | K2: 5 | L2: 4 | M2: 2 | N2: 2 | O2: 4 | P2: 0 | Q2: 4 | R2: 2 | S2: 5 | T2: 3 | U2: 3 | V2: 0 | W2: 0 | X2: 5 | Y2: 1 | Z2: 5 | AA2: 2 | AB2: 3 | AC2: 5 | AD2: 0 | AE2: 1 | AF2: =SUM(B2:AE2) -> 81
A3: TRANSPREDI | B3: 0 | C3: 11 | D3: 9 | E3: 9 | F3: 12 | G3: 10 | H3: 3 | I3: 0 | J3: 11 | K3: 6 | L3: 7 | M3: 10 | N3: 7 | O3: 4 | P3: 0 | Q3: 5 | R3: 5 | S3: 6 | T3: 9 | U3: 6 | V3: 0 | W3: 0 | X3: 6 | Y3: 11 | Z3: 4 | AA3: 7 | AB3: 3 | AC3: 3 | AD3: 0 | AE3: 4 | AF3: =SUM(B3:AE3) -> 168
A4: TERCEIROS | B4: 0 | C4: 2 | D4: 0 | E4: 1 | F4: 0 | G4: 0 | H4: 2 | I4: 0 | J4: 1 | K4: 0 | L4: 2 | M4: 0 | N4: 1 | O4: 0 | P4: 0 | Q4: 0 | R4: 1 | S4: 2 | T4: 2 | U4: 2 | V4: 0 | W4: 0 | X4: 7 | Y4: 2 | Z4: 0 | AA4: 2 | AB4: 1 | AC4: 1 | AD4: 0 | AE4: 3 | AF4: =SUM(B4:AE4) -> 32
A5: FOB | B5: 0 | C5: 0 | D5: 0 | E5: 0 | F5: 0 | G5: 0 | H5: 0 | I5: 0 | J5: 0 | K5: 1 | L5: 0 | M5: 1 | N5: 0 | O5: 0 | P5: 0 | Q5: 0 | R5: 0 | S5: 0 | T5: 0 | U5: 0 | V5: 0 | W5: 0 | X5: 0 | Y5: 2 | Z5: 1 | AA5: 0 | AB5: 0 | AC5: 0 | AD5: 0 | AE5: 1 | AF5: =SUM(B5:AE5) -> 6
B6: =SUM(B2:B5) -> 0 | C6: =SUM(C2:C5) -> 16 | D6: =SUM(D2:D5) -> 15 | E6: =SUM(E2:E5) -> 13 | F6: =SUM(F2:F5) -> 15 | G6: =SUM(G2:G5) -> 11 | H6: =SUM(H2:H5) -> 11 | I6: =SUM(I2:I5) -> 0 | ... AF6: =SUM(AF2:AF5) -> 287
A7: FROTA | B7: =B2/B$6 -> #DIV/0! | C7: =C2/C$6 -> 0.1875 | D7: =D2/D$6 -> 0.4 | E7: =E2/E$6 -> 0.23076923 | F7: =F2/F$6 -> 0.2 | G7: =G2/G$6 -> 0.090909091 | H7: =H2/H$6 -> 0.54545455 | I7: =I2/I$6 -> #DIV/0! | ... AF7: =AF2/AF$6 -> 0.28222997
A8: TRANSPREDI | B8: =B3/B$6 -> #DIV/0! | C8: =C3/C$6 -> 0.6875 | D8: =D3/D$6 -> 0.6 | E8: =E3/E$6 -> 0.69230769 | F8: =F3/F$6 -> 0.8 | G8: =G3/G$6 -> 0.90909091 | H8: =H3/H$6 -> 0.27272727 | I8: =I3/I$6 -> #DIV/0! | ... AF8: =AF3/AF$6 -> 0.58536585
A9: TERCEIROS | B9: =B4/B$6 -> #DIV/0! | C9: =C4/C$6 -> 0.125 | D9: =D4/D$6 -> 0 | E9: =E4/E$6 -> 0.076923077 | F9: =F4/F$6 -> 0 | G9: =G4/G$6 -> 0 | H9: =H4/H$6 -> 0.18181818 | I9: =I4/I$6 -> #DIV/0! | ... AF9: =AF4/AF$6 -> 0.11149826
A10: FOB | B10: =B5/B$6 -> #DIV/0! | C10: =C5/C$6 -> 0 | D10: =D5/D$6 -> 0 | E10: =E5/E$6 -> 0 | F10: =F5/F$6 -> 0 | G10: =G5/G$6 -> 0 | H10: =H5/H$6 -> 0 | I10: =I5/I$6 -> #DIV/0! | ... AF10: =AF5/AF$6 -> 0.020905923
B11: =SUM(B7:B10) -> #DIV/0! | C11: =SUM(C7:C10) -> 1 | D11: =SUM(D7:D10) -> 1 | E11: =SUM(E7:E10) -> 1 | F11: =SUM(F7:F10) -> 1 | G11: =SUM(G7:G10) -> 1 | H11: =SUM(H7:H10) -> 1 | I11: =SUM(I7:I10) -> #DIV/0! | ... AF11: =SUM(AF7:AF10) -> 1
A12: FROTA | B12: 0 | C12: =B12+C2 -> 3 | D12: =C12+D2 -> 9 | E12: =D12+E2 -> 12 | F12: =E12+F2 -> 15 | G12: =F12+G2 -> 16 | H12: =G12+H2 -> 22 | I12: =H12+I2 -> 22 | J12: =I12+J2 -> 25 | ... AE12: =AD12+AE2 -> 81
A13: TRANSPREDI | B13: 0 | C13: =B13+C3 -> 11 | D13: =C13+D3 -> 20 | E13: =D13+E3 -> 29 | F13: =E13+F3 -> 41 | G13: =F13+G3 -> 51 | H13: =G13+H3 -> 54 | I13: =H13+I3 -> 54 | J13: =I13+J3 -> 65 | ... AE13: =AD13+AE3 -> 168
A14: TERCEIROS | B14: 0 | C14: =B14+C4 -> 2 | D14: =C14+D4 -> 2 | E14: =D14+E4 -> 3 | F14: =E14+F4 -> 3 | G14: =F14+G4 -> 3 | H14: =G14+H4 -> 5 | I14: =H14+I4 -> 5 | J14: =I14+J4 -> 6 | ... AE14: =AD14+AE4 -> 32
A15: FOB | B15: 0 | C15: =B15+C5 -> 0 | D15: =C15+D5 -> 0 | E15: =D15+E5 -> 0 | F15: =E15+F5 -> 0 | G15: =F15+G5 -> 0 | H15: =G15+H5 -> 0 | I15: =H15+I5 -> 0 | J15: =I15+J5 -> 0 | ... AE15: =AD15+AE5 -> 6
B16: =SUM(B12:B15) -> 0 | C16: =SUM(C12:C15) -> 16 | D16: =SUM(D12:D15) -> 31 | E16: =SUM(E12:E15) -> 44 | F16: =SUM(F12:F15) -> 59 | G16: =SUM(G12:G15) -> 70 | H16: =SUM(H12:H15) -> 81 | I16: =SUM(I12:I15) -> 81 | ... AE16: =SUM(AE12:AE15) -> 287
A17: FROTA | B17: =B12/B$16 -> #DIV/0! | C17: =C12/C16 -> 0.1875 | D17: =D12/D16 -> 0.29032258 | E17: =E12/E16 -> 0.27272727 | F17: =F12/F16 -> 0.25423729 | G17: =G12/G16 -> 0.22857143 | H17: =H12/H16 -> 0.27160494 | I17: =I12/I16 -> 0.27160494 | J17: =J12/J16 -> 0.26041667 | ... AE17: =AE12/AE16 -> 0.28222997
A18: TRANSPREDI | B18: =B13/B$16 -> #DIV/0! | C18: =C13/C$16 -> 0.6875 | D18: =D13/D$16 -> 0.64516129 | E18: =E13/E$16 -> 0.65909091 | F18: =F13/F$16 -> 0.69491525 | G18: =G13/G$16 -> 0.72857143 | H18: =H13/H$16 -> 0.66666667 | I18: =I13/I$16 -> 0.66666667 | ... AE18: =AE13/AE$16 -> 0.58536585
A19: TERCEIROS | B19: =B14/B$16 -> #DIV/0! | C19: =C14/C$16 -> 0.125 | D19: =D14/D$16 -> 0.064516129 | E19: =E14/E$16 -> 0.068181818 | F19: =F14/F$16 -> 0.050847458 | G19: =G14/G$16 -> 0.042857143 | H19: =H14/H$16 -> 0.061728395 | I19: =I14/I$16 -> 0.061728395 | ... AE19: =AE14/AE$16 -> 0.11149826
A20: FOB | B20: =B15/B$16 -> #DIV/0! | C20: =C15/C$16 -> 0 | D20: =D15/D$16 -> 0 | E20: =E15/E$16 -> 0 | F20: =F15/F$16 -> 0 | G20: =G15/G$16 -> 0 | H20: =H15/H$16 -> 0 | I20: =I15/I$16 -> 0 | ... AE20: =AE15/AE$16 -> 0.020905923
B21: =SUM(B17:B20) -> #DIV/0! | C21: =SUM(C17:C20) -> 1 | D21: =SUM(D17:D20) -> 1 | E21: =SUM(E17:E20) -> 1 | F21: =SUM(F17:F20) -> 1 | G21: =SUM(G17:G20) -> 1 | H21: =SUM(H17:H20) -> 1 | I21: =SUM(I17:I20) -> 1 | ... AF21: =SUM(AF17:AF20) -> 0
A22: FROTA/TRANSPREDI | B22: =B2+B3 -> 0 | C22: =C2+C3 -> 14 | D22: =D2+D3 -> 15 | E22: =E2+E3 -> 12 | F22: =F2+F3 -> 15 | G22: =G2+G3 -> 11 | H22: =H2+H3 -> 9 | I22: =I2+I3 -> 0 | ... AE22: =AE2+AE3 -> 5 | AF22: =SUM(B22:AE22) -> 249
A23: TERCEIROS | B23: =B4 -> 0 | C23: =C4 -> 2 | D23: =D4 -> 0 | E23: =E4 -> 1 | F23: =F4 -> 0 | G23: =G4 -> 0 | H23: =H4 -> 2 | I23: =I4 -> 0 | ... AE23: =AE4 -> 3 | AF23: =SUM(B23:AE23) -> 32
A24: FOB | B24: =B5 -> 0 | C24: =C5 -> 0 | D24: =D5 -> 0 | E24: =E5 -> 0 | F24: =F5 -> 0 | G24: =G5 -> 0 | H24: =H5 -> 0 | I24: =I5 -> 0 | ... AE24: =AE5 -> 1 | AF24: =SUM(B24:AE24) -> 6
B25: =SUM(B22:B24) -> 0 | C25: =SUM(C22:C24) -> 16 | D25: =SUM(D22:D24) -> 15 | E25: =SUM(E22:E24) -> 13 | F25: =SUM(F22:F24) -> 15 | G25: =SUM(G22:G24) -> 11 | H25: =SUM(H22:H24) -> 11 | I25: =SUM(I22:I24) -> 0 | ... AF25: =SUM(AF22:AF24) -> 287
A26: FROTA/TRANSPREDI | B26: =B22/B$25 -> #DIV/0! | C26: =C22/C$25 -> 0.875 | D26: =D22/D$25 -> 1 | E26: =E22/E$25 -> 0.92307692 | F26: =F22/F$25 -> 1 | G26: =G22/G$25 -> 1 | H26: =H22/H$25 -> 0.81818182 | I26: =I22/I$25 -> #DIV/0! | ... AF26: =AF22/AF$25 -> 0.86759582
A27: TERCEIROS | B27: =B23/B$25 -> #DIV/0! | C27: =C23/C$25 -> 0.125 | D27: =D23/D$25 -> 0 | E27: =E23/E$25 -> 0.076923077 | F27: =F23/F$25 -> 0 | G27: =G23/G$25 -> 0 | H27: =H23/H$25 -> 0.18181818 | I27: =I23/I$25 -> #DIV/0! | ... AF27: =AF23/AF$25 -> 0.11149826
A28: FOB | B28: =B24/B$25 -> #DIV/0! | C28: =C24/C$25 -> 0 | D28: =D24/D$25 -> 0 | E28: =E24/E$25 -> 0 | F28: =F24/F$25 -> 0 | G28: =G24/G$25 -> 0 | H28: =H24/H$25 -> 0 | I28: =I24/I$25 -> #DIV/0! | ... AF28: =AF24/AF$25 -> 0.020905923
B29: =SUM(B26:B28) -> #DIV/0! | C29: =SUM(C26:C28) -> 1 | D29: =SUM(D26:D28) -> 1 | E29: =SUM(E26:E28) -> 1 | F29: =SUM(F26:F28) -> 1 | G29: =SUM(G26:G28) -> 1 | H29: =SUM(H26:H28) -> 1 | I29: =SUM(I26:I28) -> #DIV/0! | ... AF29: =SUM(AF26:AF28) -> 1
H30: 1

Sheet Analise
B2: CARREGAMENTO GRUPO PREDILECTA - MAIO/26
B3: Empresa | C3: Frota | D3: % | E3: Transpredi | F3: % | G3: Frota+Transpredi | H3: % | I3: Terceiro | J3: % | K3: FOB | L3: % | M3: Total
B4: Predilecta | C4: 293 | D4: 0.43 | E4: 73 | F4: 0.11 | G4: =C4+E4 -> 366 | H4: =G4/M4 -> 0.54142012 | I4: 273 | J4: 0.4 | K4: 37 | L4: 0.05 | M4: 676
B5: Sófruta | C5: 155 | D5: 0.41 | E5: 32 | F5: 0.09 | G5: =C5+E5 -> 187 | H5: =G5/M5 -> 0.49734043 | I5: 181 | J5: 0.48 | K5: 8 | L5: 0.02 | M5: 376
B6: Stella | C6: 233 | D6: 0.55 | E6: 23 | F6: 0.05 | G6: =C6+E6 -> 256 | H6: =G6/M6 -> 0.60093897 | I6: 144 | J6: 0.34 | K6: 26 | L6: 0.06 | M6: 426
B7: Minas | C7: 130 | D7: 0.34 | E7: 11 | F7: 0.03 | G7: =C7+E7 -> 141 | H7: =G7/M7 -> 0.37301587 | I7: 224 | J7: 0.59 | K7: 13 | L7: 0.03 | M7: 378
B8: Salsaretti | C8: 106 | D8: 0.41 | E8: 0 | F8: 0 | G8: =C8+E8 -> 106 | H8: =G8/M8 -> 0.41085271 | I8: 144 | J8: 0.56 | K8: 8 | L8: 0.03 | M8: 258
B9: Nordeste | C9: 21 | D9: 0.36 | E9: 0 | F9: 0 | G9: =C9+E9 -> 21 | H9: =G9/M9 -> 0.3559322 | I9: 35 | J9: 0.59 | K9: 3 | L9: 0.05 | M9: 59
B10: Goias | C10: 4 | D10: 0.14 | E10: 0 | F10: 0 | G10: =C10+E10 -> 4 | H10: =G10/M10 -> 0.13793103 | I10: 24 | J10: 0.83 | K10: 1 | L10: 0.03 | M10: 29
B11: TOTAL | C11: =SUM(C4:C10) -> 942 | D11: =C11/M11 -> 0.42779292 | E11: =SUM(E4:E10) -> 139 | F11: =E11/M11 -> 0.063124432 | G11: =C11+E11 -> 1081 | H11: =G11/M11 -> 0.49091735 | I11: =SUM(I4:I10) -> 1025 | J11: =I11/M11 -> 0.46548592 | K11: =SUM(K4:K10) -> 96 | L11: =K11/M11 -> 0.04359673 | M11: =SUM(M4:M10) -> 2202 | N11: =G11/129 -> 8.379845
B13: CARREGAMENTO GRUPO PREDILECTA - JUNHO/26
C14: FROTA | D14: % | E14: TRANSPREDI | F14: % | G14: Frota+Transpredi | H14: % | I14: TERCEIROS | J14: % | K14: FOB | L14: % | M14: Total
B15: Predilecta | C15: 400 | D15: =C15/M15 -> 0.55555556 | E15: 73 | F15: =E15/M15 -> 0.10138889 | G15: =C15+E15 -> 473 | H15: =G15/M15 -> 0.65694444 | I15: 199 | J15: =I15/M15 -> 0.27638889 | K15: 48 | L15: =K15/M15 -> 0.066666667 | M15: =C15+E15+I15+K15 -> 720
B16: SóFruta | C16: 164 | D16: =C16/M16 -> 0.46067416 | E16: 42 | F16: =E16/M16 -> 0.11797753 | G16: =C16+E16 -> 206 | H16: =G16/M16 -> 0.57865169 | I16: 139 | J16: =I16/M16 -> 0.39044944 | K16: 11 | L16: =K16/M16 -> 0.030898876 | M16: =C16+E16+I16+K16 -> 356
B17: StellaDóro | C17: 187 | D17: =C17/M17 -> 0.51092896 | E17: 44 | F17: =E17/M17 -> 0.12021858 | G17: =C17+E17 -> 231 | H17: =G17/M17 -> 0.63114754 | I17: 125 | J17: =I17/M17 -> 0.34153005 | K17: 10 | L17: =K17/M17 -> 0.027322404 | M17: =C17+E17+I17+K17 -> 366
B18: Minas+ | C18: 152 | D18: =C18/M18 -> 0.46769231 | E18: 11 | F18: =E18/M18 -> 0.033846154 | G18: =C18+E18 -> 163 | H18: =G18/M18 -> 0.50153846 | I18: 140 | J18: =I18/M18 -> 0.43076923 | K18: 22 | L18: =K18/M18 -> 0.067692308 | M18: =C18+E18+I18+K18 -> 325
B19: Salsaretti | C19: 83 | D19: =C19/M19 -> 0.35021097 | E19: 21 | F19: =E19/M19 -> 0.088607595 | G19: =C19+E19 -> 104 | H19: =G19/M19 -> 0.43881857 | I19: 124 | J19: =I19/M19 -> 0.52320675 | K19: 9 | L19: =K19/M19 -> 0.037974684 | M19: =C19+E19+I19+K19 -> 237
B20: Nordeste | C20: 37 | D20: =C20/M20 -> 0.38947368 | E20: 0 | F20: =E20/M20 -> 0 | G20: =C20+E20 -> 37 | H20: =G20/M20 -> 0.38947368 | I20: 48 | J20: =I20/M20 -> 0.50526316 | K20: 10 | L20: =K20/M20 -> 0.10526316 | M20: =C20+E20+I20+K20 -> 95
B21: Goiás | C21: 1 | D21: =C21/M21 -> 0.018518519 | E21: 0 | F21: =E21/M21 -> 0 | G21: =C21+E21 -> 1 | H21: =G21/M21 -> 0.018518519 | I21: 53 | J21: =I21/M21 -> 0.98148148 | K21: 0 | L21: =K21/M21 -> 0 | M21: =C21+E21+I21+K21 -> 54
B22: TOTAL | C22: =SUM(C15:C21) -> 1024 | D22: =C22/M22 -> 0.47561542 | E22: =SUM(E15:E21) -> 191 | F22: =E22/M22 -> 0.088713423 | G22: =C22+E22 -> 1215 | H22: =G22/M22 -> 0.56432884 | I22: =SUM(I15:I21) -> 828 | J22: =I22/M22 -> 0.38457966 | K22: =SUM(K15:K21) -> 110 | L22: =K22/M22 -> 0.0510915 | M22: =SUM(M15:M21) -> 2153 | N22: =G22/129 -> 9.4186047
B24: CARREGAMENTO GRUPO PREDILECTA - JULHO/26
C25: FROTA | D25: % | E25: TRANSPREDI | F25: % | G25: Frota+Transpredi | H25: % | I25: TERCEIROS | J25: % | K25: FOB | L25: % | M25: Total
B26: Predilecta | C26: 503 | D26: =C26/M26 -> 0.61566707 | E26: 25 | F26: =E26/M26 -> 0.030599755 | H26: =G26/M26 -> 0 | I26: 240 | J26: =I26/M26 -> 0.29375765 | K26: 49 | L26: =K26/M26 -> 0.05997552 | M26: =C26+E26+I26+K26 -> 817
B27: SóFruta | C27: 242 | D27: =C27/M27 -> 0.55504587 | E27: 27 | F27: =E27/M27 -> 0.061926606 | H27: =G27/M27 -> 0 | I27: 147 | J27: =I27/M27 -> 0.33715596 | K27: 20 | L27: =K27/M27 -> 0.04587156 | M27: =C27+E27+I27+K27 -> 436
B28: StellaDóro | C28: 254 | D28: =C28/M28 -> 0.65463918 | E28: 25 | F28: =E28/M28 -> 0.06443299 | H28: =G28/M28 -> 0 | I28: 87 | J28: =I28/M28 -> 0.2242268 | K28: 22 | L28: =K28/M28 -> 0.056701031 | M28: =C28+E28+I28+K28 -> 388
B29: Minas+ | C29: 186 | D29: =C29/M29 -> 0.42272727 | E29: 55 | F29: =E29/M29 -> 0.125 | H29: =G29/M29 -> 0 | I29: 174 | J29: =I29/M29 -> 0.39545455 | K29: 25 | L29: =K29/M29 -> 0.056818182 | M29: =C29+E29+I29+K29 -> 440 | O29: =C33-G22 -> 129
B30: Salsaretti | C30: 122 | D30: =C30/M30 -> 0.48031496 | E30: 39 | F30: =E30/M30 -> 0.15354331 | H30: =G30/M30 -> 0 | I30: 85 | J30: =I30/M30 -> 0.33464567 | K30: 8 | L30: =K30/M30 -> 0.031496063 | M30: =C30+E30+I30+K30 -> 254
B31: Nordeste | C31: 37 | D31: =C31/M31 -> 0.30578512 | E31: 16 | F31: =E31/M31 -> 0.1322314 | H31: =G31/M31 -> 0 | I31: 64 | J31: =I31/M31 -> 0.52892562 | K31: 4 | L31: =K31/M31 -> 0.033057851 | M31: =C31+E31+I31+K31 -> 121
B32: Goiás | C32: 0 | D32: =C32/M32 -> 0 | E32: 0 | F32: =E32/M32 -> 0 | H32: =G32/M32 -> 0 | I32: 1 | J32: =I32/M32 -> 1 | K32: 0 | L32: =K32/M32 -> 0 | M32: =C32+E32+I32+K32 -> 1
B33: TOTAL | C33: =SUM(C26:C32) -> 1344 | D33: =C33/M33 -> 0.54700855 | E33: =SUM(E26:E32) -> 187 | F33: =E33/M33 -> 0.076109076 | H33: =G33/M33 -> 0 | I33: =SUM(I26:I32) -> 798 | J33: =I33/M33 -> 0.32478632 | K33: =SUM(K26:K32) -> 128 | L33: =K33/M33 -> 0.052096052 | M33: =SUM(M26:M32) -> 2457
I34: =I33+E33 -> 985
B36: MAIO X JUNHO
B37: Maio x Junho | C37: =C22-C11 -> 82 | D37: =D22-D11 -> 0.047822505 | E37: =E22-E11 -> 52 | F37: =F22-F11 -> 0.025588991 | G37: =G22-G11 -> 134 | H37: =H22-H11 -> 0.073411496 | I37: =I22-I11 -> -197 | J37: =J22-J11 -> -0.080906266 | ... M37: =M22-M11 -> -49
B39: JUNHO X JULHO
B40: Maio x Julho | C40: =C33-G22 -> 129 | D40: =C40/C33 -> 0.095982143 | E40: =(E33+I33)-I22 -> 157 | F40: =E40/I34 -> 0.15939086 | G40: =G25-G14 -> #VALUE! | H40: =H25-H14 -> #VALUE! | I40: =I25-I14 -> #VALUE! | J40: =J25-J14 -> #VALUE! | K40: =K25-K14 -> #VALUE! | L40: =L25-L14 -> #VALUE! | M40: =M25-M14 -> #VALUE!

Sheet Comparativo Jun x Jul
A1: PREDILECTA | B1: 46174 | C1: 46175 | D1: 46176 | E1: 46177 | F1: 46178 | G1: 46179 | H1: 46180 | I1: 46181 | J1: 46182 | K1: 46183 | L1: 46184 | M1: 46185 | N1: 46186 | O1: 46187 | P1: 46188 | Q1: 46189 | R1: 46190 | S1: TOTAL | T1: P X TERC | U1: % P x % TERC
A2: FROTA | B2: 15 | C2: 15 | D2: 19 | E2: 13 | F2: 13 | G2: 17 | H2: 0 | I2: 12 | J2: 16 | K2: 16 | L2: 15 | M2: 13 | N2: 15 | O2: 0 | P2: 9 | Q2: 20 | R2: 11 | S2: =SUM(B2:R2) -> 219 | T2: =S2+S3 -> 261 | U2: =T2/T6 -> 0.696
A3: TRANSPREDI | B3: 3 | C3: 3 | D3: 3 | E3: 1 | F3: 3 | G3: 5 | H3: 0 | I3: 1 | J3: 4 | K3: 3 | L3: 4 | M3: 5 | N3: 1 | O3: 0 | P3: 1 | Q3: 1 | R3: 4 | S3: =SUM(B3:R3) -> 42 | T3: =S4 -> 114 | U3: =T3/T6 -> 0.304
A4: TERCEIROS | B4: 8 | C4: 8 | D4: 15 | E4: 12 | F4: 9 | G4: 11 | H4: 0 | I4: 3 | J4: 1 | K4: 7 | L4: 7 | M4: 0 | N4: 1 | O4: 0 | P4: 9 | Q4: 15 | R4: 8 | S4: =SUM(B4:R4) -> 114
A5: FOB | B5: 1 | C5: 6 | D5: 3 | E5: 0 | F5: 0 | G5: 0 | H5: 0 | I5: 2 | J5: 3 | K5: 3 | L5: 2 | M5: 1 | N5: 0 | O5: 0 | P5: 2 | Q5: 3 | R5: 2 | S5: =SUM(B5:R5) -> 28 | V5: Aumento Geral | W5: %
B6: =SUM(B2:B5) -> 27 | C6: =SUM(C2:C5) -> 32 | D6: =SUM(D2:D5) -> 40 | E6: =SUM(E2:E5) -> 26 | F6: =SUM(F2:F5) -> 25 | G6: =SUM(G2:G5) -> 33 | H6: =SUM(H2:H5) -> 0 | I6: =SUM(I2:I5) -> 18 | ... R6: =SUM(R2:R5) -> 25 | S6: =SUM(B6:R6) -> 403 | T6: =SUM(T2:T5) -> 375 | V6: =S12-S6 -> 55 | W6: =V6/S12 -> 0.12008734
A7: PREDILECTA | B7: 46204 | C7: 46205 | D7: 46206 | E7: 46207 | F7: 46208 | G7: 46209 | H7: 46210 | I7: 46211 | J7: 46212 | K7: 46213 | L7: 46214 | M7: 46215 | N7: 46216 | O7: 46217 | P7: 46218 | Q7: 46219 | R7: 46220 | S7: TOTAL | T7: P X TERC | U7: % P x % TERC | V7: =T8-T2 -> 8 | W7: =V7/T8 -> 0.029739777
A8: FROTA | B8: 18 | C8: 29 | D8: 15 | E8: 12 | F8: 10 | G8: 16 | H8: 19 | I8: 20 | J8: 13 | K8: 18 | L8: 15 | N8: 7 | O8: 20 | P8: 23 | Q8: 18 | R8: 16 | S8: =SUM(B8:R8) -> 269 | T8: =S8 -> 269 | U8: =T8/T12 -> 0.62412993
A9: TRANSPREDI | B9: 0 | C9: 0 | D9: 0 | E9: 1 | F9: 0 | G9: 1 | H9: 4 | I9: 2 | J9: 1 | K9: 0 | L9: 2 | N9: 1 | O9: 1 | P9: 3 | Q9: 2 | R9: 3 | S9: =SUM(B9:R9) -> 21 | T9: =S10+S9 -> 162 | U9: =T9/T12 -> 0.37587007
A10: TERCEIROS | B10: 13 | C10: 14 | D10: 12 | E10: 11 | F10: 4 | G10: 13 | H10: 8 | I10: 7 | J10: 3 | K10: 7 | L10: 4 | N10: 10 | O10: 9 | P10: 10 | Q10: 8 | R10: 8 | S10: =SUM(B10:R10) -> 141
A11: FOB | B11: 1 | C11: 1 | D11: 2 | E11: 1 | F11: 0 | G11: 2 | H11: 3 | I11: 4 | J11: 0 | K11: 3 | L11: 1 | N11: 1 | O11: 4 | P11: 1 | Q11: 1 | R11: 2 | S11: =SUM(B11:R11) -> 27
A12: TOTAL | B12: =SUM(B8:B11) -> 32 | C12: =SUM(C8:C11) -> 44 | D12: =SUM(D8:D11) -> 29 | E12: =SUM(E8:E11) -> 25 | F12: =SUM(F8:F11) -> 14 | G12: =SUM(G8:G11) -> 32 | H12: =SUM(H8:H11) -> 34 | I12: =SUM(I8:I11) -> 33 | ... R12: =SUM(R8:R11) -> 29 | S12: =SUM(B12:R12) -> 458 | T12: =SUM(T8:T11) -> 431
