Workbook

Sheet Leia-me
B2: PAINEL DE GESTÃO LOGÍSTICA — FROTA PRÓPRIA x TRANSPREDI x TERCEIROS
B3: Base histórica: mai/26 a ago/26 • Controle diário preventivo • Plano de ação
B5: ABA | C5: PARA QUE SERVE / O QUE FAZER
B6: Base Mai-Ago | C6: Histórico consolidado dos 6 indicadores nos 4 meses. Células em AZUL são os dados originais do relatório enviado; as variações são calculadas. Ao fechar um novo mês, insira uma coluna e replique as fórmulas.
B7: Diagnóstico | C7: Leitura dos números: o que melhorou, o que piorou e onde está o dinheiro. Somente leitura (fórmulas ligadas à aba Base).
B8: Parâmetros | C8: AJUSTE AQUI ANTES DE USAR. Metas por empresa, dias operacionais no mês e a tabela de motivos de terceirização (define o que é EVITÁVEL). Tudo em azul é editável.
B9: Controle Diário | C9: CORAÇÃO DO PROCESSO. Uma linha por empresa por dia. Preencher o BLOCO A (planejamento) até as 8h — ele acusa o gap de capacidade ANTES de contratar terceiro. Fechar os BLOCOS B e C no fim do dia. Os blocos cinza são calculados.
B10: Painel Diário | C10: Consolida o Controle Diário no período que você escolher e compara com a meta (semáforo). Só preencha as datas de início e fim.
B11: Plano de Ação | C11: 5W2H das ações recomendadas. Atualize status e responsáveis semanalmente.
B13: LEGENDA DE CORES
B14: Azul | C14: Você preenche (dado de entrada ou premissa).
B15: Preto | C15: Calculado por fórmula — não digitar por cima.
B16: Fundo amarelo | C16: Meta / premissa crítica a validar com a operação.
B17: Verde / Vermelho | C17: Semáforo automático contra a meta da aba Parâmetros.
B19: OBSERVAÇÃO SOBRE A BASE | C19: Jun/26 e jul/26 aparecem com valores diferentes em relatórios de meses distintos (ex.: Salsaretti — 7,92 viagens no fechamento de junho x 9,08 no de julho). Foi adotado sempre o fechamento MAIS RECENTE de cada mês. Recomenda-se travar o fechamento mensal para eliminar reprocessamentos.

Sheet Base Mai-Ago
B2: BASE CONSOLIDADA — mai/26 a ago/26
B4: Média de Viagens por Veículo - Frota Própria
B5: Empresa | C5: mai/26 | D5: jun/26 | E5: jul/26 | F5: ago/26 | G5: Δ abs. mai→ago | H5: Δ% mai→ago | I5: Δ% jul→ago
B6: Predilecta | C6: 9.05 | D6: 9.51 | E6: 9.74 | F6: 10.35 | G6: =F6-C6 -> 1.3 | H6: =IFERROR(F6/C6-1,"n/a") -> 0.14364641 | I6: =IFERROR(F6/E6-1,"n/a") -> 0.062628337
B7: Só Fruta | C7: 7.37 | D7: 8.36 | E7: 9.33 | F7: 10.67 | G7: =F7-C7 -> 3.3 | H7: =IFERROR(F7/C7-1,"n/a") -> 0.44776119 | I7: =IFERROR(F7/E7-1,"n/a") -> 0.14362272
B8: Stella | C8: 7.65 | D8: 8.67 | E8: 10.71 | F8: 10.19 | G8: =F8-C8 -> 2.54 | H8: =IFERROR(F8/C8-1,"n/a") -> 0.33202614 | I8: =IFERROR(F8/E8-1,"n/a") -> -0.048552754
B9: Salsaretti | C9: 7.75 | D9: 9.08 | E9: 9.58 | F9: 10.17 | G9: =F9-C9 -> 2.42 | H9: =IFERROR(F9/C9-1,"n/a") -> 0.31225806 | I9: =IFERROR(F9/E9-1,"n/a") -> 0.061586639
B10: Minas Mais | C10: 8.8 | D10: 8.52 | E10: 10.24 | F10: 10.05 | G10: =F10-C10 -> 1.25 | H10: =IFERROR(F10/C10-1,"n/a") -> 0.14204545 | I10: =IFERROR(F10/E10-1,"n/a") -> -0.018554688
B11: Nordeste Mais | C11: 7.67 | D11: 11.67 | E11: 12 | F11: 12.67 | G11: =F11-C11 -> 5 | H11: =IFERROR(F11/C11-1,"n/a") -> 0.65189048 | I11: =IFERROR(F11/E11-1,"n/a") -> 0.055833333
B12: Média do grupo | C12: =IFERROR(AVERAGE(C6:C11),"") -> 8.0483333 | D12: =IFERROR(AVERAGE(D6:D11),"") -> 9.3016667 | E12: =IFERROR(AVERAGE(E6:E11),"") -> 10.266667 | F12: =IFERROR(AVERAGE(F6:F11),"") -> 10.683333 | G12: =IFERROR(AVERAGE(G6:G11),"") -> 2.635 | H12: =IFERROR(AVERAGE(H6:H11),"") -> 0.33827129 | I12: =IFERROR(AVERAGE(I6:I11),"") -> 0.042760598
B15: Custo do KM - Frota Própria (R$/km)
B16: Empresa | C16: mai/26 | D16: jun/26 | E16: jul/26 | F16: ago/26 | G16: Δ abs. mai→ago | H16: Δ% mai→ago | I16: Δ% jul→ago
B17: Predilecta | C17: 5.01 | D17: 4.7 | E17: 4.66 | F17: 5.25 | G17: =F17-C17 -> 0.24 | H17: =IFERROR(F17/C17-1,"n/a") -> 0.047904192 | I17: =IFERROR(F17/E17-1,"n/a") -> 0.12660944
B18: Só Fruta | C18: 6.06 | D18: 5.81 | E18: 5.34 | F18: 5.54 | G18: =F18-C18 -> -0.52 | H18: =IFERROR(F18/C18-1,"n/a") -> -0.085808581 | I18: =IFERROR(F18/E18-1,"n/a") -> 0.037453184
B19: Stella | C19: 5.4 | D19: 4.98 | E19: 4.2 | F19: 4.83 | G19: =F19-C19 -> -0.57 | H19: =IFERROR(F19/C19-1,"n/a") -> -0.10555556 | I19: =IFERROR(F19/E19-1,"n/a") -> 0.15
B20: Salsaretti | C20: 4.58 | D20: 4.77 | E20: 4.61 | F20: 4.3 | G20: =F20-C20 -> -0.28 | H20: =IFERROR(F20/C20-1,"n/a") -> -0.061135371 | I20: =IFERROR(F20/E20-1,"n/a") -> -0.067245119
B21: Minas Mais | C21: 5.44 | D21: 5.72 | E21: 5.32 | F21: 5.77 | G21: =F21-C21 -> 0.33 | H21: =IFERROR(F21/C21-1,"n/a") -> 0.060661765 | I21: =IFERROR(F21/E21-1,"n/a") -> 0.084586466
B22: Nordeste Mais | C22: 4.95 | D22: 4.84 | E22: 4.12 | F22: 4.61 | G22: =F22-C22 -> -0.34 | H22: =IFERROR(F22/C22-1,"n/a") -> -0.068686869 | I22: =IFERROR(F22/E22-1,"n/a") -> 0.11893204
B23: Média do grupo | C23: =IFERROR(AVERAGE(C17:C22),"") -> 5.24 | D23: =IFERROR(AVERAGE(D17:D22),"") -> 5.1366667 | E23: =IFERROR(AVERAGE(E17:E22),"") -> 4.7083333 | F23: =IFERROR(AVERAGE(F17:F22),"") -> 5.05 | G23: =IFERROR(AVERAGE(G17:G22),"") -> -0.19 | H23: =IFERROR(AVERAGE(H17:H22),"") -> -0.035436737 | I23: =IFERROR(AVERAGE(I17:I22),"") -> 0.075056002
B26: Participação Frota Própria (%)
B27: Empresa | C27: mai/26 | D27: jun/26 | E27: jul/26 | F27: ago/26 | G27: Δ abs. mai→ago | H27: Δ% mai→ago | I27: Δ% jul→ago
B28: Predilecta | C28: 0.4156 | D28: 0.4435 | E28: 0.4005 | F28: 0.4398 | G28: =F28-C28 -> 0.0242 | H28: =IFERROR(F28/C28-1,"n/a") -> 0.058229066 | I28: =IFERROR(F28/E28-1,"n/a") -> 0.098127341
B29: Só Fruta | C29: 0.363 | D29: 0.4373 | E29: 0.4005 | F29: 0.458 | G29: =F29-C29 -> 0.095 | H29: =IFERROR(F29/C29-1,"n/a") -> 0.26170799 | I29: =IFERROR(F29/E29-1,"n/a") -> 0.14357054
B30: Stella | C30: 0.3702 | D30: 0.4329 | E30: 0.4234 | F30: 0.4064 | G30: =F30-C30 -> 0.0362 | H30: =IFERROR(F30/C30-1,"n/a") -> 0.097784981 | I30: =IFERROR(F30/E30-1,"n/a") -> -0.040151157
B31: Salsaretti | C31: 0.2643 | D31: 0.3097 | E31: 0.316 | F31: 0.3025 | G31: =F31-C31 -> 0.0382 | H31: =IFERROR(F31/C31-1,"n/a") -> 0.14453273 | I31: =IFERROR(F31/E31-1,"n/a") -> -0.042721519
B32: Minas Mais | C32: 0.3573 | D32: 0.4135 | E32: 0.3087 | F32: 0.3661 | G32: =F32-C32 -> 0.0088 | H32: =IFERROR(F32/C32-1,"n/a") -> 0.024629163 | I32: =IFERROR(F32/E32-1,"n/a") -> 0.18594104
B33: Nordeste Mais | C33: 0.1625 | D33: 0.2432 | E33: 0.1865 | F33: 0.2382 | G33: =F33-C33 -> 0.0757 | H33: =IFERROR(F33/C33-1,"n/a") -> 0.46584615 | I33: =IFERROR(F33/E33-1,"n/a") -> 0.2772118
B34: Média do grupo | C34: =IFERROR(AVERAGE(C28:C33),"") -> 0.32215 | D34: =IFERROR(AVERAGE(D28:D33),"") -> 0.38001667 | E34: =IFERROR(AVERAGE(E28:E33),"") -> 0.33926667 | F34: =IFERROR(AVERAGE(F28:F33),"") -> 0.3685 | G34: =IFERROR(AVERAGE(G28:G33),"") -> 0.04635 | H34: =IFERROR(AVERAGE(H28:H33),"") -> 0.17545501 | I34: =IFERROR(AVERAGE(I28:I33),"") -> 0.10366301
B37: Participação Transpredi (%)
B38: Empresa | C38: mai/26 | D38: jun/26 | E38: jul/26 | F38: ago/26 | G38: Δ abs. mai→ago | H38: Δ% mai→ago | I38: Δ% jul→ago
B39: Predilecta | C39: 0.1214 | D39: 0.1385 | E39: 0.1462 | F39: 0.1366 | G39: =F39-C39 -> 0.0152 | H39: =IFERROR(F39/C39-1,"n/a") -> 0.12520593 | I39: =IFERROR(F39/E39-1,"n/a") -> -0.065663475
B40: Só Fruta | C40: 0.104 | D40: 0.1292 | E40: 0.1634 | F40: 0.1322 | G40: =F40-C40 -> 0.0282 | H40: =IFERROR(F40/C40-1,"n/a") -> 0.27115385 | I40: =IFERROR(F40/E40-1,"n/a") -> -0.19094247
B41: Stella | C41: 0.1149 | D41: 0.1362 | E41: 0.1591 | F41: 0.1223 | G41: =F41-C41 -> 0.0074 | H41: =IFERROR(F41/C41-1,"n/a") -> 0.064403829 | I41: =IFERROR(F41/E41-1,"n/a") -> -0.23130107
B42: Salsaretti | C42: 0.0937 | D42: 0.0832 | E42: 0.2737 | F42: 0.2783 | G42: =F42-C42 -> 0.1846 | H42: =IFERROR(F42/C42-1,"n/a") -> 1.9701174 | I42: =IFERROR(F42/E42-1,"n/a") -> 0.016806723
B43: Minas Mais | C43: 0.1796 | D43: 0.2139 | E43: 0.2414 | F43: 0.2743 | G43: =F43-C43 -> 0.0947 | H43: =IFERROR(F43/C43-1,"n/a") -> 0.52728285 | I43: =IFERROR(F43/E43-1,"n/a") -> 0.13628832
B44: Nordeste Mais | C44: 0 | D44: 0 | E44: 0.0898 | F44: 0.262 | G44: =F44-C44 -> 0.262 | H44: =IFERROR(F44/C44-1,"n/a") -> n/a | I44: =IFERROR(F44/E44-1,"n/a") -> 1.9175947
B45: Média do grupo | C45: =IFERROR(AVERAGE(C39:C44),"") -> 0.10226667 | D45: =IFERROR(AVERAGE(D39:D44),"") -> 0.11683333 | E45: =IFERROR(AVERAGE(E39:E44),"") -> 0.17893333 | F45: =IFERROR(AVERAGE(F39:F44),"") -> 0.20095 | G45: =IFERROR(AVERAGE(G39:G44),"") -> 0.098683333 | H45: =IFERROR(AVERAGE(H39:H44),"") -> 0.59163277 | I45: =IFERROR(AVERAGE(I39:I44),"") -> 0.26379711
B48: Participação de Terceiros (%)
B49: Empresa | C49: mai/26 | D49: jun/26 | E49: jul/26 | F49: ago/26 | G49: Δ abs. mai→ago | H49: Δ% mai→ago | I49: Δ% jul→ago
B50: Predilecta | C50: 0.463 | D50: 0.418 | E50: 0.4533 | F50: 0.4236 | G50: =F50-C50 -> -0.0394 | H50: =IFERROR(F50/C50-1,"n/a") -> -0.085097192 | I50: =IFERROR(F50/E50-1,"n/a") -> -0.065519523
...

Sheet Diagnóstico
B2: DIAGNÓSTICO — mai/26 a ago/26
B4: # | C4: Achado | D4: Valor | E4: Leitura e implicação
B5: 1 | C5: Produtividade da frota subiu forte | D5: ='Base Mai-Ago'!F12/'Base Mai-Ago'!C12-1 -> 0.32739698 | E5: A média de viagens por veículo saiu de 8,05 (mai) para 10,68 (ago). Nordeste Mais +65%, Só Fruta +45%, Stella +33%. O ativo passou a girar mais — o esforço de utilização funcionou.
B6: 2 | C6: MAS o custo/km voltou a subir em agosto | D6: ='Base Mai-Ago'!F23/'Base Mai-Ago'!E23-1 -> 0.072566372 | E6: De mai a jul o custo/km caiu de R$ 5,24 para R$ 4,71 (-10%). Em agosto voltou a R$ 5,05. Cinco das seis empresas pioraram (Stella +15,0%, Predilecta +12,7%, Nordeste +11,9%). Mais viagens com custo/km maior sugere queda da distância média por viagem: a frota está absorvendo rota curta e o terceiro fica com a longa. VALIDAR com km médio por viagem.
B7: 3 | C7: Terceiros caíram 14,5 p.p. no período | D7: ='Base Mai-Ago'!F56-'Base Mai-Ago'!C56 -> -0.14498333 | E7: A participação de terceiros caiu de 57,6% (mai) para 43,1% (ago). Nordeste Mais é o destaque absoluto: 83,8% → 50,0% (-33,8 p.p.). Salsaretti: 64,2% → 41,9%.
B8: 4 | C8: Porém quem absorveu foi a Transpredi, não a frota | D8: ='Base Mai-Ago'!F45-'Base Mai-Ago'!C45 -> 0.098683333 | E8: Dos 14,5 p.p. que saíram de terceiros, 9,9 p.p. foram para a Transpredi e apenas 4,6 p.p. para a frota própria (32,2% → 36,9%). Ou seja, ~68% da redução foi TROCA DE FORNECEDOR, não aproveitamento de ativo. Casos críticos: Salsaretti (8,3% → 27,8%) e Nordeste Mais (0% → 26,2%) em dois meses.
B9: 5 | C9: A economia unitária não foi capturada | D9: ='Base Mai-Ago'!F67-'Base Mai-Ago'!C67 -> 0.00105 | E9: O volume com terceiros caiu 25%, mas o % de frete de terceiros sobre faturamento ficou praticamente igual (10,24% → 10,35%). Predilecta piorou (12,03% → 12,24%) e Nordeste Mais também (9,50% → 10,45%), apesar de ter cortado 34 p.p. de volume. Sinal clássico de seleção adversa: internalizamos a carga fácil e o terceiro remanescente cobra caro pela rota ruim — sem renegociação de tabela.
B10: 6 | C10: Dispersão de custo entre empresas é grande | D10: =5.77-4.3 -> 1.47 | E10: Em agosto o custo/km vai de R$ 4,30 (Salsaretti) a R$ 5,77 (Minas Mais) — 34% de diferença. Minas Mais e Predilecta são as únicas com custo/km ACIMA de maio. Salsaretti é a única que melhorou em agosto (-6,7%), mas tem a menor participação de frota do grupo (30,3%).
B11: 7 | C11: Risco de governança do dado | D11: — | E11: Jun/26 e jul/26 foram reapresentados com números diferentes entre relatórios (Salsaretti: 7,92 → 9,08 viagens; participação de frota jul: 32,5% → 31,6%). Sem base travada, nenhuma meta é auditável.
C13: CONCLUSÃO | E13: O grupo ganhou PRODUTIVIDADE (viagens) e ganhou MIX (menos terceiros), mas não converteu isso em CUSTO. As três alavancas ainda abertas são: (a) parar a migração automática para Transpredi e testar preço contra terceiro e contra custo interno; (b) renegociar a tabela do terceiro remanescente, que hoje custa mais por unidade; (c) atacar a queda da distância média por viagem, que é o que está empurrando o custo/km para cima.

Sheet Parâmetros
B2: PARÂMETROS E METAS — ajustar antes de operar
B4: Empresa | C4: Meta viagens/veíc./mês | D4: Teto custo R$/km | E4: Piso % Frota | F4: Teto % Transpredi | G4: Teto % Terceiros | H4: Teto % frete terc./fat. | I4: Piso ocupação % | K4: Motivo da contratação de terceiro | L4: Classificação | M4: Ação preventiva
B5: Predilecta | C5: 11 | D5: 4.66 | E5: 0.48 | F5: 0.14 | G5: 0.38 | H5: 0.1203 | I5: 0.9 | K5: 1. Pico de demanda não previsto | L5: Evitável | M5: Nivelar carteira: fechar corte de pedidos D-1 e alisar o pico da semana
B6: Só Fruta | C6: 11.5 | D6: 5.34 | E6: 0.5 | F6: 0.14 | G6: 0.37 | H6: 0.1053 | I6: 0.9 | K6: 2. Veículo em manutenção corretiva | L6: Evitável | M6: Plano de manutenção preventiva e controle de disponibilidade da frota
B7: Stella | C7: 11.5 | D7: 4.2 | E7: 0.45 | F7: 0.13 | G7: 0.43 | H7: 0.1045 | I7: 0.9 | K7: 3. Falta de motorista / escala | L7: Evitável | M7: Escala reserva, banco de horas e cobertura de férias planejada
B8: Salsaretti | C8: 11 | D8: 4.3 | E8: 0.35 | F8: 0.24 | G8: 0.38 | H8: 0.0877 | I8: 0.9 | K8: 4. Carga liberada fora da janela de roteirização | L8: Evitável | M8: Travar horário de liberação da produção/expedição
B9: Minas Mais | C9: 11 | D9: 5.32 | E9: 0.41 | F9: 0.24 | G9: 0.32 | H9: 0.0891 | I9: 0.9 | K9: 5. Baixa ocupação — carga fracionada | L9: Parcial | M9: Consolidação de cargas, milk-run e agrupamento por região
B10: Nordeste Mais | C10: 13.5 | D10: 4.12 | E10: 0.28 | F10: 0.22 | G10: 0.45 | H10: 0.0848 | I10: 0.9 | K10: 6. Sazonalidade / pico programado | L10: Parcial | M10: Contratar frota spot com antecedência e preço fechado
B11: Critério das metas: teto de custo/km e teto de % frete de terceiros = MELHOR mês realizado entre mai e ago/26. Piso de % frota = ago/26 + 4 p.p. Teto de % Transpredi = ago/26 (congelar). Ocupação de 90% é premissa — confirmar com a operação. | K11: 7. Janela de entrega do cliente incompatível | L11: Parcial | M11: Renegociar janela ou agendamento com o cliente
K12: 8. Rota fora da malha da frota | L12: Não evitável | M12: Avaliar backhaul, redespacho ou parceria dedicada
B13: Dias operacionais no mês | C13: 26 | D13: Converte a meta mensal de viagens em capacidade/dia | K13: 9. Avaria / sinistro | L13: Não evitável | M13: Registrar e acompanhar em indicador de indisponibilidade
K14: 10. Restrição legal / licença / cliente exclusivo | L14: Não evitável | M14: Registrar para justificar o mix
B15: Limite de alerta do GAP (viagens) | C15: 2 | D15: Acima disso o Controle Diário marca ATENÇÃO no início do dia
K16: 'Evitável' = a contratação decorre de falha interna de planejamento. É esse número que deve ir a zero.
T20: Empresas | U20: Motivos
T21: Predilecta | U21: 1. Pico de demanda não previsto
T22: Só Fruta | U22: 2. Veículo em manutenção corretiva
T23: Stella | U23: 3. Falta de motorista / escala
T24: Salsaretti | U24: 4. Carga liberada fora da janela de roteirização
T25: Minas Mais | U25: 5. Baixa ocupação — carga fracionada
T26: Nordeste Mais | U26: 6. Sazonalidade / pico programado
U27: 7. Janela de entrega do cliente incompatível
U28: 8. Rota fora da malha da frota
U29: 9. Avaria / sinistro
U30: 10. Restrição legal / licença / cliente exclusivo

Sheet Controle Diário
B2: CONTROLE DIÁRIO DAS OPERAÇÕES LOGÍSTICAS
B3: BLOCO A até as 8h (planejamento — é aqui que a terceirização é evitada) • BLOCOS B e C no fechamento do dia • BLOCO D é automático
B4: BLOCO A — PLANEJAMENTO (até 8h) | L4: BLOCO B — ALOCAÇÃO | Q4: BLOCO C — REALIZADO (fechamento) | X4: BLOCO D — INDICADORES AUTOMÁTICOS
B5: Data | C5: Empresa | D5: Unidade / CD | E5: Cargas a expedir (nº) | F5: Peso previsto (t) | G5: Veíc. próprios disponíveis | H5: Veíc. parados / manutenção | I5: Capac. frota no dia (viagens) | J5: GAP frota vs meta do dia | K5: Risco de terceirização | L5: Cargas Frota | M5: Cargas Transpredi | N5: Cargas Terceiros | O5: Motivo principal do terceiro | P5: Cargas terceiro EVITÁVEIS (nº) | Q5: Viagens realizadas frota | R5: KM rodado frota | S5: Custo total frota (R$) | T5: Custo total terceiros (R$) | U5: Valor NF expedida (R$) | V5: Ocupação média frota | W5: Retornos vazios (nº) | X5: % Frota | Y5: % Transpredi | Z5: % Terceiros | AA5: Custo R$/km frota | AB5: Viagens/veíc./dia | AC5: % frete terc./fat. | AD5: Custo EVITÁVEL do dia (R$) | AE5: Status do dia
B6: =DATE(2026,9,1) -> 46266 | C6: =Parâmetros!B5 -> Predilecta | D6: CD Matão | E6: 42 | F6: 780 | G6: 40 | H6: 3 | I6: =IF($B6="","",IFERROR($G6*IFERROR(INDEX(Parâmetros!$C$5:$C$10,MATCH($C6,Parâmetros!$B$5:$B$10,0)),"")/Parâmetros!$C$13,"")) -> 16.923077 | J6: =IF($B6="","",IFERROR($E6*IFERROR(INDEX(Parâmetros!$E$5:$E$10,MATCH($C6,Parâmetros!$B$5:$B$10,0)),"")-$I6,"")) -> 3.2369231 | K6: =IF($B6="","",IF(NOT(ISNUMBER($J6)),"",IF($J6<=0,"OK - frota cobre a meta do dia",IF($J6<=Parâmetros!$C$15,"ATENCAO - faltam "&TEXT($J6,"0")&" viagem(ns) de frota","CRITICO - faltam "&TEXT($J6,"0")&" viagens: acionar plano")))) -> CRITICO - faltam 3 viagens: acionar plano | L6: 18 | M6: 6 | N6: 18 | O6: =Parâmetros!K5 -> 1. Pico de demanda não previsto | P6: 3 | Q6: 18 | R6: 4140 | S6: 20700 | T6: 39600 | U6: 348000 | V6: 0.88 | W6: 2 | X6: =IF($B6="","",IFERROR($L6/($L6+$M6+$N6),"")) -> 0.42857143 | Y6: =IF($B6="","",IFERROR($M6/($L6+$M6+$N6),"")) -> 0.14285714 | Z6: =IF($B6="","",IFERROR($N6/($L6+$M6+$N6),"")) -> 0.42857143 | AA6: =IF($B6="","",IFERROR($S6/$R6,"")) -> 5 | AB6: =IF($B6="","",IFERROR($Q6/$G6,"")) -> 0.45 | AC6: =IF($B6="","",IFERROR($T6/$U6,"")) -> 0.1137931 | AD6: =IF($B6="","",IFERROR(IF(AND($N6>0,$L6>0),$P6*(($T6/$N6)-($S6/$L6)),0),0)) -> 3150 | AE6: =IF($B6="","",IF(NOT(ISNUMBER($AA6)),"Aguardando fechamento",IF($P6>0,"ACAO: "&TEXT($P6,"0")&" carga(s) terceirizada(s) de forma evitavel",IF(IF(ISNUMBER($Z6),$Z6,0)>IFERROR(INDEX(Parâmetros!$G$5:$G$10,MATCH($C6,Parâmetros!$B$5:$B$10,0)),""),"ALERTA: terceiros acima da meta",IF($AA6>IFERROR(INDEX(Parâmetros!$D$5:$D$10,MATCH($C6,Parâmetros!$B$5:$B$10,0)),""),"ALERTA: custo/km acima da meta","OK - dentro das metas"))))) -> ACAO: 3 carga(s) terceirizada(s) de forma evitavel
I7: =IF($B7="","",IFERROR($G7*IFERROR(INDEX(Parâmetros!$C$5:$C$10,MATCH($C7,Parâmetros!$B$5:$B$10,0)),"")/Parâmetros!$C$13,"")) | J7: =IF($B7="","",IFERROR($E7*IFERROR(INDEX(Parâmetros!$E$5:$E$10,MATCH($C7,Parâmetros!$B$5:$B$10,0)),"")-$I7,"")) | K7: =IF($B7="","",IF(NOT(ISNUMBER($J7)),"",IF($J7<=0,"OK - frota cobre a meta do dia",IF($J7<=Parâmetros!$C$15,"ATENCAO - faltam "&TEXT($J7,"0")&" viagem(ns) de frota","CRITICO - faltam "&TEXT($J7,"0")&" viagens: acionar plano")))) | X7: =IF($B7="","",IFERROR($L7/($L7+$M7+$N7),"")) | Y7: =IF($B7="","",IFERROR($M7/($L7+$M7+$N7),"")) | Z7: =IF($B7="","",IFERROR($N7/($L7+$M7+$N7),"")) | AA7: =IF($B7="","",IFERROR($S7/$R7,"")) | AB7: =IF($B7="","",IFERROR($Q7/$G7,"")) | AC7: =IF($B7="","",IFERROR($T7/$U7,"")) | AD7: =IF($B7="","",IFERROR(IF(AND($N7>0,$L7>0),$P7*(($T7/$N7)-($S7/$L7)),0),0)) | AE7: =IF($B7="","",IF(NOT(ISNUMBER($AA7)),"Aguardando fechamento",IF($P7>0,"ACAO: "&TEXT($P7,"0")&" carga(s) terceirizada(s) de forma evitavel",IF(IF(ISNUMBER($Z7),$Z7,0)>IFERROR(INDEX(Parâmetros!$G$5:$G$10,MATCH($C7,Parâmetros!$B$5:$B$10,0)),""),"ALERTA: terceiros acima da meta",IF($AA7>IFERROR(INDEX(Parâmetros!$D$5:$D$10,MATCH($C7,Parâmetros!$B$5:$B$10,0)),""),"ALERTA: custo/km acima da meta","OK - dentro das metas")))))
I8: =IF($B8="","",IFERROR($G8*IFERROR(INDEX(Parâmetros!$C$5:$C$10,MATCH($C8,Parâmetros!$B$5:$B$10,0)),"")/Parâmetros!$C$13,"")) | J8: =IF($B8="","",IFERROR($E8*IFERROR(INDEX(Parâmetros!$E$5:$E$10,MATCH($C8,Parâmetros!$B$5:$B$10,0)),"")-$I8,"")) | K8: =IF($B8="","",IF(NOT(ISNUMBER($J8)),"",IF($J8<=0,"OK - frota cobre a meta do dia",IF($J8<=Parâmetros!$C$15,"ATENCAO - faltam "&TEXT($J8,"0")&" viagem(ns) de frota","CRITICO - faltam "&TEXT($J8,"0")&" viagens: acionar plano")))) | X8: =IF($B8="","",IFERROR($L8/($L8+$M8+$N8),"")) | Y8: =IF($B8="","",IFERROR($M8/($L8+$M8+$N8),"")) | Z8: =IF($B8="","",IFERROR($N8/($L8+$M8+$N8),"")) | AA8: =IF($B8="","",IFERROR($S8/$R8,"")) | AB8: =IF($B8="","",IFERROR($Q8/$G8,"")) | AC8: =IF($B8="","",IFERROR($T8/$U8,"")) | AD8: =IF($B8="","",IFERROR(IF(AND($N8>0,$L8>0),$P8*(($T8/$N8)-($S8/$L8)),0),0)) | AE8: =IF($B8="","",IF(NOT(ISNUMBER($AA8)),"Aguardando fechamento",IF($P8>0,"ACAO: "&TEXT($P8,"0")&" carga(s) terceirizada(s) de forma evitavel",IF(IF(ISNUMBER($Z8),$Z8,0)>IFERROR(INDEX(Parâmetros!$G$5:$G$10,MATCH($C8,Parâmetros!$B$5:$B$10,0)),""),"ALERTA: terceiros acima da meta",IF($AA8>IFERROR(INDEX(Parâmetros!$D$5:$D$10,MATCH($C8,Parâmetros!$B$5:$B$10,0)),""),"ALERTA: custo/km acima da meta","OK - dentro das metas")))))
I9: =IF($B9="","",IFERROR($G9*IFERROR(INDEX(Parâmetros!$C$5:$C$10,MATCH($C9,Parâmetros!$B$5:$B$10,0)),"")/Parâmetros!$C$13,"")) | J9: =IF($B9="","",IFERROR($E9*IFERROR(INDEX(Parâmetros!$E$5:$E$10,MATCH($C9,Parâmetros!$B$5:$B$10,0)),"")-$I9,"")) | K9: =IF($B9="","",IF(NOT(ISNUMBER($J9)),"",IF($J9<=0,"OK - frota cobre a meta do dia",IF($J9<=Parâmetros!$C$15,"ATENCAO - faltam "&TEXT($J9,"0")&" viagem(ns) de frota","CRITICO - faltam "&TEXT($J9,"0")&" viagens: acionar plano")))) | X9: =IF($B9="","",IFERROR($L9/($L9+$M9+$N9),"")) | Y9: =IF($B9="","",IFERROR($M9/($L9+$M9+$N9),"")) | Z9: =IF($B9="","",IFERROR($N9/($L9+$M9+$N9),"")) | AA9: =IF($B9="","",IFERROR($S9/$R9,"")) | AB9: =IF($B9="","",IFERROR($Q9/$G9,"")) | AC9: =IF($B9="","",IFERROR($T9/$U9,"")) | AD9: =IF($B9="","",IFERROR(IF(AND($N9>0,$L9>0),$P9*(($T9/$N9)-($S9/$L9)),0),0)) | AE9: =IF($B9="","",IF(NOT(ISNUMBER($AA9)),"Aguardando fechamento",IF($P9>0,"ACAO: "&TEXT($P9,"0")&" carga(s) terceirizada(s) de forma evitavel",IF(IF(ISNUMBER($Z9),$Z9,0)>IFERROR(INDEX(Parâmetros!$G$5:$G$10,MATCH($C9,Parâmetros!$B$5:$B$10,0)),""),"ALERTA: terceiros acima da meta",IF($AA9>IFERROR(INDEX(Parâmetros!$D$5:$D$10,MATCH($C9,Parâmetros!$B$5:$B$10,0)),""),"ALERTA: custo/km acima da meta","OK - dentro das metas")))))
I10: =IF($B10="","",IFERROR($G10*IFERROR(INDEX(Parâmetros!$C$5:$C$10,MATCH($C10,Parâmetros!$B$5:$B$10,0)),"")/Parâmetros!$C$13,"")) | J10: =IF($B10="","",IFERROR($E10*IFERROR(INDEX(Parâmetros!$E$5:$E$10,MATCH($C10,Parâmetros!$B$5:$B$10,0)),"")-$I10,"")) | K10: =IF($B10="","",IF(NOT(ISNUMBER($J10)),"",IF($J10<=0,"OK - frota cobre a meta do dia",IF($J10<=Parâmetros!$C$15,"ATENCAO - faltam "&TEXT($J10,"0")&" viagem(ns) de frota","CRITICO - faltam "&TEXT($J10,"0")&" viagens: acionar plano")))) | X10: =IF($B10="","",IFERROR($L10/($L10+$M10+$N10),"")) | Y10: =IF($B10="","",IFERROR($M10/($L10+$M10+$N10),"")) | Z10: =IF($B10="","",IFERROR($N10/($L10+$M10+$N10),"")) | AA10: =IF($B10="","",IFERROR($S10/$R10,"")) | AB10: =IF($B10="","",IFERROR($Q10/$G10,"")) | AC10: =IF($B10="","",IFERROR($T10/$U10,"")) | AD10: =IF($B10="","",IFERROR(IF(AND($N10>0,$L10>0),$P10*(($T10/$N10)-($S10/$L10)),0),0)) | AE10: =IF($B10="","",IF(NOT(ISNUMBER($AA10)),"Aguardando fechamento",IF($P10>0,"ACAO: "&TEXT($P10,"0")&" carga(s) terceirizada(s) de forma evitavel",IF(IF(ISNUMBER($Z10),$Z10,0)>IFERROR(INDEX(Parâmetros!$G$5:$G$10,MATCH($C10,Parâmetros!$B$5:$B$10,0)),""),"ALERTA: terceiros acima da meta",IF($AA10>IFERROR(INDEX(Parâmetros!$D$5:$D$10,MATCH($C10,Parâmetros!$B$5:$B$10,0)),""),"ALERTA: custo/km acima da meta","OK - dentro das metas")))))
I11: =IF($B11="","",IFERROR($G11*IFERROR(INDEX(Parâmetros!$C$5:$C$10,MATCH($C11,Parâmetros!$B$5:$B$10,0)),"")/Parâmetros!$C$13,"")) | J11: =IF($B11="","",IFERROR($E11*IFERROR(INDEX(Parâmetros!$E$5:$E$10,MATCH($C11,Parâmetros!$B$5:$B$10,0)),"")-$I11,"")) | K11: =IF($B11="","",IF(NOT(ISNUMBER($J11)),"",IF($J11<=0,"OK - frota cobre a meta do dia",IF($J11<=Parâmetros!$C$15,"ATENCAO - faltam "&TEXT($J11,"0")&" viagem(ns) de frota","CRITICO - faltam "&TEXT($J11,"0")&" viagens: acionar plano")))) | X11: =IF($B11="","",IFERROR($L11/($L11+$M11+$N11),"")) | Y11: =IF($B11="","",IFERROR($M11/($L11+$M11+$N11),"")) | Z11: =IF($B11="","",IFERROR($N11/($L11+$M11+$N11),"")) | AA11: =IF($B11="","",IFERROR($S11/$R11,"")) | AB11: =IF($B11="","",IFERROR($Q11/$G11,"")) | AC11: =IF($B11="","",IFERROR($T11/$U11,"")) | AD11: =IF($B11="","",IFERROR(IF(AND($N11>0,$L11>0),$P11*(($T11/$N11)-($S11/$L11)),0),0)) | AE11: =IF($B11="","",IF(NOT(ISNUMBER($AA11)),"Aguardando fechamento",IF($P11>0,"ACAO: "&TEXT($P11,"0")&" carga(s) terceirizada(s) de forma evitavel",IF(IF(ISNUMBER($Z11),$Z11,0)>IFERROR(INDEX(Parâmetros!$G$5:$G$10,MATCH($C11,Parâmetros!$B$5:$B$10,0)),""),"ALERTA: terceiros acima da meta",IF($AA11>IFERROR(INDEX(Parâmetros!$D$5:$D$10,MATCH($C11,Parâmetros!$B$5:$B$10,0)),""),"ALERTA: custo/km acima da meta","OK - dentro das metas")))))
I12: =IF($B12="","",IFERROR($G12*IFERROR(INDEX(Parâmetros!$C$5:$C$10,MATCH($C12,Parâmetros!$B$5:$B$10,0)),"")/Parâmetros!$C$13,"")) | J12: =IF($B12="","",IFERROR($E12*IFERROR(INDEX(Parâmetros!$E$5:$E$10,MATCH($C12,Parâmetros!$B$5:$B$10,0)),"")-$I12,"")) | K12: =IF($B12="","",IF(NOT(ISNUMBER($J12)),"",IF($J12<=0,"OK - frota cobre a meta do dia",IF($J12<=Parâmetros!$C$15,"ATENCAO - faltam "&TEXT($J12,"0")&" viagem(ns) de frota","CRITICO - faltam "&TEXT($J12,"0")&" viagens: acionar plano")))) | X12: =IF($B12="","",IFERROR($L12/($L12+$M12+$N12),"")) | Y12: =IF($B12="","",IFERROR($M12/($L12+$M12+$N12),"")) | Z12: =IF($B12="","",IFERROR($N12/($L12+$M12+$N12),"")) | AA12: =IF($B12="","",IFERROR($S12/$R12,"")) | AB12: =IF($B12="","",IFERROR($Q12/$G12,"")) | AC12: =IF($B12="","",IFERROR($T12/$U12,"")) | AD12: =IF($B12="","",IFERROR(IF(AND($N12>0,$L12>0),$P12*(($T12/$N12)-($S12/$L12)),0),0)) | AE12: =IF($B12="","",IF(NOT(ISNUMBER($AA12)),"Aguardando fechamento",IF($P12>0,"ACAO: "&TEXT($P12,"0")&" carga(s) terceirizada(s) de forma evitavel",IF(IF(ISNUMBER($Z12),$Z12,0)>IFERROR(INDEX(Parâmetros!$G$5:$G$10,MATCH($C12,Parâmetros!$B$5:$B$10,0)),""),"ALERTA: terceiros acima da meta",IF($AA12>IFERROR(INDEX(Parâmetros!$D$5:$D$10,MATCH($C12,Parâmetros!$B$5:$B$10,0)),""),"ALERTA: custo/km acima da meta","OK - dentro das metas")))))
I13: =IF($B13="","",IFERROR($G13*IFERROR(INDEX(Parâmetros!$C$5:$C$10,MATCH($C13,Parâmetros!$B$5:$B$10,0)),"")/Parâmetros!$C$13,"")) | J13: =IF($B13="","",IFERROR($E13*IFERROR(INDEX(Parâmetros!$E$5:$E$10,MATCH($C13,Parâmetros!$B$5:$B$10,0)),"")-$I13,"")) | K13: =IF($B13="","",IF(NOT(ISNUMBER($J13)),"",IF($J13<=0,"OK - frota cobre a meta do dia",IF($J13<=Parâmetros!$C$15,"ATENCAO - faltam "&TEXT($J13,"0")&" viagem(ns) de frota","CRITICO - faltam "&TEXT($J13,"0")&" viagens: acionar plano")))) | X13: =IF($B13="","",IFERROR($L13/($L13+$M13+$N13),"")) | Y13: =IF($B13="","",IFERROR($M13/($L13+$M13+$N13),"")) | Z13: =IF($B13="","",IFERROR($N13/($L13+$M13+$N13),"")) | AA13: =IF($B13="","",IFERROR($S13/$R13,"")) | AB13: =IF($B13="","",IFERROR($Q13/$G13,"")) | AC13: =IF($B13="","",IFERROR($T13/$U13,"")) | AD13: =IF($B13="","",IFERROR(IF(AND($N13>0,$L13>0),$P13*(($T13/$N13)-($S13/$L13)),0),0)) | AE13: =IF($B13="","",IF(NOT(ISNUMBER($AA13)),"Aguardando fechamento",IF($P13>0,"ACAO: "&TEXT($P13,"0")&" carga(s) terceirizada(s) de forma evitavel",IF(IF(ISNUMBER($Z13),$Z13,0)>IFERROR(INDEX(Parâmetros!$G$5:$G$10,MATCH($C13,Parâmetros!$B$5:$B$10,0)),""),"ALERTA: terceiros acima da meta",IF($AA13>IFERROR(INDEX(Parâmetros!$D$5:$D$10,MATCH($C13,Parâmetros!$B$5:$B$10,0)),""),"ALERTA: custo/km acima da meta","OK - dentro das metas")))))
I14: =IF($B14="","",IFERROR($G14*IFERROR(INDEX(Parâmetros!$C$5:$C$10,MATCH($C14,Parâmetros!$B$5:$B$10,0)),"")/Parâmetros!$C$13,"")) | J14: =IF($B14="","",IFERROR($E14*IFERROR(INDEX(Parâmetros!$E$5:$E$10,MATCH($C14,Parâmetros!$B$5:$B$10,0)),"")-$I14,"")) | K14: =IF($B14="","",IF(NOT(ISNUMBER($J14)),"",IF($J14<=0,"OK - frota cobre a meta do dia",IF($J14<=Parâmetros!$C$15,"ATENCAO - faltam "&TEXT($J14,"0")&" viagem(ns) de frota","CRITICO - faltam "&TEXT($J14,"0")&" viagens: acionar plano")))) | X14: =IF($B14="","",IFERROR($L14/($L14+$M14+$N14),"")) | Y14: =IF($B14="","",IFERROR($M14/($L14+$M14+$N14),"")) | Z14: =IF($B14="","",IFERROR($N14/($L14+$M14+$N14),"")) | AA14: =IF($B14="","",IFERROR($S14/$R14,"")) | AB14: =IF($B14="","",IFERROR($Q14/$G14,"")) | AC14: =IF($B14="","",IFERROR($T14/$U14,"")) | AD14: =IF($B14="","",IFERROR(IF(AND($N14>0,$L14>0),$P14*(($T14/$N14)-($S14/$L14)),0),0)) | AE14: =IF($B14="","",IF(NOT(ISNUMBER($AA14)),"Aguardando fechamento",IF($P14>0,"ACAO: "&TEXT($P14,"0")&" carga(s) terceirizada(s) de forma evitavel",IF(IF(ISNUMBER($Z14),$Z14,0)>IFERROR(INDEX(Parâmetros!$G$5:$G$10,MATCH($C14,Parâmetros!$B$5:$B$10,0)),""),"ALERTA: terceiros acima da meta",IF($AA14>IFERROR(INDEX(Parâmetros!$D$5:$D$10,MATCH($C14,Parâmetros!$B$5:$B$10,0)),""),"ALERTA: custo/km acima da meta","OK - dentro das metas")))))
I15: =IF($B15="","",IFERROR($G15*IFERROR(INDEX(Parâmetros!$C$5:$C$10,MATCH($C15,Parâmetros!$B$5:$B$10,0)),"")/Parâmetros!$C$13,"")) | J15: =IF($B15="","",IFERROR($E15*IFERROR(INDEX(Parâmetros!$E$5:$E$10,MATCH($C15,Parâmetros!$B$5:$B$10,0)),"")-$I15,"")) | K15: =IF($B15="","",IF(NOT(ISNUMBER($J15)),"",IF($J15<=0,"OK - frota cobre a meta do dia",IF($J15<=Parâmetros!$C$15,"ATENCAO - faltam "&TEXT($J15,"0")&" viagem(ns) de frota","CRITICO - faltam "&TEXT($J15,"0")&" viagens: acionar plano")))) | X15: =IF($B15="","",IFERROR($L15/($L15+$M15+$N15),"")) | Y15: =IF($B15="","",IFERROR($M15/($L15+$M15+$N15),"")) | Z15: =IF($B15="","",IFERROR($N15/($L15+$M15+$N15),"")) | AA15: =IF($B15="","",IFERROR($S15/$R15,"")) | AB15: =IF($B15="","",IFERROR($Q15/$G15,"")) | AC15: =IF($B15="","",IFERROR($T15/$U15,"")) | AD15: =IF($B15="","",IFERROR(IF(AND($N15>0,$L15>0),$P15*(($T15/$N15)-($S15/$L15)),0),0)) | AE15: =IF($B15="","",IF(NOT(ISNUMBER($AA15)),"Aguardando fechamento",IF($P15>0,"ACAO: "&TEXT($P15,"0")&" carga(s) terceirizada(s) de forma evitavel",IF(IF(ISNUMBER($Z15),$Z15,0)>IFERROR(INDEX(Parâmetros!$G$5:$G$10,MATCH($C15,Parâmetros!$B$5:$B$10,0)),""),"ALERTA: terceiros acima da meta",IF($AA15>IFERROR(INDEX(Parâmetros!$D$5:$D$10,MATCH($C15,Parâmetros!$B$5:$B$10,0)),""),"ALERTA: custo/km acima da meta","OK - dentro das metas")))))
I16: =IF($B16="","",IFERROR($G16*IFERROR(INDEX(Parâmetros!$C$5:$C$10,MATCH($C16,Parâmetros!$B$5:$B$10,0)),"")/Parâmetros!$C$13,"")) | J16: =IF($B16="","",IFERROR($E16*IFERROR(INDEX(Parâmetros!$E$5:$E$10,MATCH($C16,Parâmetros!$B$5:$B$10,0)),"")-$I16,"")) | K16: =IF($B16="","",IF(NOT(ISNUMBER($J16)),"",IF($J16<=0,"OK - frota cobre a meta do dia",IF($J16<=Parâmetros!$C$15,"ATENCAO - faltam "&TEXT($J16,"0")&" viagem(ns) de frota","CRITICO - faltam "&TEXT($J16,"0")&" viagens: acionar plano")))) | X16: =IF($B16="","",IFERROR($L16/($L16+$M16+$N16),"")) | Y16: =IF($B16="","",IFERROR($M16/($L16+$M16+$N16),"")) | Z16: =IF($B16="","",IFERROR($N16/($L16+$M16+$N16),"")) | AA16: =IF($B16="","",IFERROR($S16/$R16,"")) | AB16: =IF($B16="","",IFERROR($Q16/$G16,"")) | AC16: =IF($B16="","",IFERROR($T16/$U16,"")) | AD16: =IF($B16="","",IFERROR(IF(AND($N16>0,$L16>0),$P16*(($T16/$N16)-($S16/$L16)),0),0)) | AE16: =IF($B16="","",IF(NOT(ISNUMBER($AA16)),"Aguardando fechamento",IF($P16>0,"ACAO: "&TEXT($P16,"0")&" carga(s) terceirizada(s) de forma evitavel",IF(IF(ISNUMBER($Z16),$Z16,0)>IFERROR(INDEX(Parâmetros!$G$5:$G$10,MATCH($C16,Parâmetros!$B$5:$B$10,0)),""),"ALERTA: terceiros acima da meta",IF($AA16>IFERROR(INDEX(Parâmetros!$D$5:$D$10,MATCH($C16,Parâmetros!$B$5:$B$10,0)),""),"ALERTA: custo/km acima da meta","OK - dentro das metas")))))
I17: =IF($B17="","",IFERROR($G17*IFERROR(INDEX(Parâmetros!$C$5:$C$10,MATCH($C17,Parâmetros!$B$5:$B$10,0)),"")/Parâmetros!$C$13,"")) | J17: =IF($B17="","",IFERROR($E17*IFERROR(INDEX(Parâmetros!$E$5:$E$10,MATCH($C17,Parâmetros!$B$5:$B$10,0)),"")-$I17,"")) | K17: =IF($B17="","",IF(NOT(ISNUMBER($J17)),"",IF($J17<=0,"OK - frota cobre a meta do dia",IF($J17<=Parâmetros!$C$15,"ATENCAO - faltam "&TEXT($J17,"0")&" viagem(ns) de frota","CRITICO - faltam "&TEXT($J17,"0")&" viagens: acionar plano")))) | X17: =IF($B17="","",IFERROR($L17/($L17+$M17+$N17),"")) | Y17: =IF($B17="","",IFERROR($M17/($L17+$M17+$N17),"")) | Z17: =IF($B17="","",IFERROR($N17/($L17+$M17+$N17),"")) | AA17: =IF($B17="","",IFERROR($S17/$R17,"")) | AB17: =IF($B17="","",IFERROR($Q17/$G17,"")) | AC17: =IF($B17="","",IFERROR($T17/$U17,"")) | AD17: =IF($B17="","",IFERROR(IF(AND($N17>0,$L17>0),$P17*(($T17/$N17)-($S17/$L17)),0),0)) | AE17: =IF($B17="","",IF(NOT(ISNUMBER($AA17)),"Aguardando fechamento",IF($P17>0,"ACAO: "&TEXT($P17,"0")&" carga(s) terceirizada(s) de forma evitavel",IF(IF(ISNUMBER($Z17),$Z17,0)>IFERROR(INDEX(Parâmetros!$G$5:$G$10,MATCH($C17,Parâmetros!$B$5:$B$10,0)),""),"ALERTA: terceiros acima da meta",IF($AA17>IFERROR(INDEX(Parâmetros!$D$5:$D$10,MATCH($C17,Parâmetros!$B$5:$B$10,0)),""),"ALERTA: custo/km acima da meta","OK - dentro das metas")))))
I18: =IF($B18="","",IFERROR($G18*IFERROR(INDEX(Parâmetros!$C$5:$C$10,MATCH($C18,Parâmetros!$B$5:$B$10,0)),"")/Parâmetros!$C$13,"")) | J18: =IF($B18="","",IFERROR($E18*IFERROR(INDEX(Parâmetros!$E$5:$E$10,MATCH($C18,Parâmetros!$B$5:$B$10,0)),"")-$I18,"")) | K18: =IF($B18="","",IF(NOT(ISNUMBER($J18)),"",IF($J18<=0,"OK - frota cobre a meta do dia",IF($J18<=Parâmetros!$C$15,"ATENCAO - faltam "&TEXT($J18,"0")&" viagem(ns) de frota","CRITICO - faltam "&TEXT($J18,"0")&" viagens: acionar plano")))) | X18: =IF($B18="","",IFERROR($L18/($L18+$M18+$N18),"")) | Y18: =IF($B18="","",IFERROR($M18/($L18+$M18+$N18),"")) | Z18: =IF($B18="","",IFERROR($N18/($L18+$M18+$N18),"")) | AA18: =IF($B18="","",IFERROR($S18/$R18,"")) | AB18: =IF($B18="","",IFERROR($Q18/$G18,"")) | AC18: =IF($B18="","",IFERROR($T18/$U18,"")) | AD18: =IF($B18="","",IFERROR(IF(AND($N18>0,$L18>0),$P18*(($T18/$N18)-($S18/$L18)),0),0)) | AE18: =IF($B18="","",IF(NOT(ISNUMBER($AA18)),"Aguardando fechamento",IF($P18>0,"ACAO: "&TEXT($P18,"0")&" carga(s) terceirizada(s) de forma evitavel",IF(IF(ISNUMBER($Z18),$Z18,0)>IFERROR(INDEX(Parâmetros!$G$5:$G$10,MATCH($C18,Parâmetros!$B$5:$B$10,0)),""),"ALERTA: terceiros acima da meta",IF($AA18>IFERROR(INDEX(Parâmetros!$D$5:$D$10,MATCH($C18,Parâmetros!$B$5:$B$10,0)),""),"ALERTA: custo/km acima da meta","OK - dentro das metas")))))
... I255: =IF($B255="","",IFERROR($G255*IFERROR(INDEX(Parâmetros!$C$5:$C$10,MATCH($C255,Parâmetros!$B$5:$B$10,0)),"")/Parâmetros!$C$13,"")) | J255: =IF($B255="","",IFERROR($E255*IFERROR(INDEX(Parâmetros!$E$5:$E$10,MATCH($C255,Parâmetros!$B$5:$B$10,0)),"")-$I255,"")) | K255: =IF($B255="","",IF(NOT(ISNUMBER($J255)),"",IF($J255<=0,"OK - frota cobre a meta do dia",IF($J255<=Parâmetros!$C$15,"ATENCAO - faltam "&TEXT($J255,"0")&" viagem(ns) de frota","CRITICO - faltam "&TEXT($J255,"0")&" viagens: acionar plano")))) | X255: =IF($B255="","",IFERROR($L255/($L255+$M255+$N255),"")) | Y255: =IF($B255="","",IFERROR($M255/($L255+$M255+$N255),"")) | Z255: =IF($B255="","",IFERROR($N255/($L255+$M255+$N255),"")) | AA255: =IF($B255="","",IFERROR($S255/$R255,"")) | AB255: =IF($B255="","",IFERROR($Q255/$G255,"")) | AC255: =IF($B255="","",IFERROR($T255/$U255,"")) | AD255: =IF($B255="","",IFERROR(IF(AND($N255>0,$L255>0),$P255*(($T255/$N255)-($S255/$L255)),0),0)) | AE255: =IF($B255="","",IF(NOT(ISNUMBER($AA255)),"Aguardando fechamento",IF($P255>0,"ACAO: "&TEXT($P255,"0")&" carga(s) terceirizada(s) de forma evitavel",IF(IF(ISNUMBER($Z255),$Z255,0)>IFERROR(INDEX(Parâmetros!$G$5:$G$10,MATCH($C255,Parâmetros!$B$5:$B$10,0)),""),"ALERTA: terceiros acima da meta",IF($AA255>IFERROR(INDEX(Parâmetros!$D$5:$D$10,MATCH($C255,Parâmetros!$B$5:$B$10,0)),""),"ALERTA: custo/km acima da meta","OK - dentro das metas")))))

Sheet Painel Diário
B2: PAINEL DE ACOMPANHAMENTO — PERÍODO SELECIONADO
B4: Data inicial | C4: =DATE(2026,9,1) -> 46266 | D4: ← altere as datas para recalcular todo o painel
B5: Data final | C5: =DATE(2026,9,30) -> 46295
B7: Empresa | C7: Cargas expedidas | D7: % Frota | E7: Piso meta | F7: % Transpredi | G7: % Terceiros | H7: Teto meta | I7: Custo R$/km | J7: Teto meta | K7: % frete terc./fat. | L7: Custo evitável (R$) | M7: Semáforo
B8: Predilecta | C8: =(SUMIFS('Controle Diário'!$L$6:$L$255,'Controle Diário'!$C$6:$C$255,$B8,'Controle Diário'!$B$6:$B$255,">="&$C$4,'Controle Diário'!$B$6:$B$255,"<="&$C$5)+SUMIFS('Controle Diário'!$M$6:$M$255,'Controle Diário'!$C$6:$C$255,$B8,'Controle Diário'!$B$6:$B$255,">="&$C$4,'Controle Diário'!$B$6:$B$255,"<="&$C$5)+SUMIFS('Controle Diário'!$N$6:$N$255,'Controle Diário'!$C$6:$C$255,$B8,'Controle Diário'!$B$6:$B$255,">="&$C$4,'Controle Diário'!$B$6:$B$255,"<="&$C$5)) -> 42 | D8: =IFERROR(SUMIFS('Controle Diário'!$L$6:$L$255,'Controle Diário'!$C$6:$C$255,$B8,'Controle Diário'!$B$6:$B$255,">="&$C$4,'Controle Diário'!$B$6:$B$255,"<="&$C$5)/(SUMIFS('Controle Diário'!$L$6:$L$255,'Controle Diário'!$C$6:$C$255,$B8,'Controle Diário'!$B$6:$B$255,">="&$C$4,'Controle Diário'!$B$6:$B$255,"<="&$C$5)+SUMIFS('Controle Diário'!$M$6:$M$255,'Controle Diário'!$C$6:$C$255,$B8,'Controle Diário'!$B$6:$B$255,">="&$C$4,'Controle Diário'!$B$6:$B$255,"<="&$C$5)+SUMIFS('Controle Diário'!$N$6:$N$255,'Controle Diário'!$C$6:$C$255,$B8,'Controle Diário'!$B$6:$B$255,">="&$C$4,'Controle Diário'!$B$6:$B$255,"<="&$C$5)),"") -> 0.42857143 | E8: =IFERROR(INDEX(Parâmetros!$E$5:$E$10,MATCH($B8,Parâmetros!$B$5:$B$10,0)),"") -> 0.48 | F8: =IFERROR(SUMIFS('Controle Diário'!$M$6:$M$255,'Controle Diário'!$C$6:$C$255,$B8,'Controle Diário'!$B$6:$B$255,">="&$C$4,'Controle Diário'!$B$6:$B$255,"<="&$C$5)/(SUMIFS('Controle Diário'!$L$6:$L$255,'Controle Diário'!$C$6:$C$255,$B8,'Controle Diário'!$B$6:$B$255,">="&$C$4,'Controle Diário'!$B$6:$B$255,"<="&$C$5)+SUMIFS('Controle Diário'!$M$6:$M$255,'Controle Diário'!$C$6:$C$255,$B8,'Controle Diário'!$B$6:$B$255,">="&$C$4,'Controle Diário'!$B$6:$B$255,"<="&$C$5)+SUMIFS('Controle Diário'!$N$6:$N$255,'Controle Diário'!$C$6:$C$255,$B8,'Controle Diário'!$B$6:$B$255,">="&$C$4,'Controle Diário'!$B$6:$B$255,"<="&$C$5)),"") -> 0.14285714 | G8: =IFERROR(SUMIFS('Controle Diário'!$N$6:$N$255,'Controle Diário'!$C$6:$C$255,$B8,'Controle Diário'!$B$6:$B$255,">="&$C$4,'Controle Diário'!$B$6:$B$255,"<="&$C$5)/(SUMIFS('Controle Diário'!$L$6:$L$255,'Controle Diário'!$C$6:$C$255,$B8,'Controle Diário'!$B$6:$B$255,">="&$C$4,'Controle Diário'!$B$6:$B$255,"<="&$C$5)+SUMIFS('Controle Diário'!$M$6:$M$255,'Controle Diário'!$C$6:$C$255,$B8,'Controle Diário'!$B$6:$B$255,">="&$C$4,'Controle Diário'!$B$6:$B$255,"<="&$C$5)+SUMIFS('Controle Diário'!$N$6:$N$255,'Controle Diário'!$C$6:$C$255,$B8,'Controle Diário'!$B$6:$B$255,">="&$C$4,'Controle Diário'!$B$6:$B$255,"<="&$C$5)),"") -> 0.42857143 | H8: =IFERROR(INDEX(Parâmetros!$G$5:$G$10,MATCH($B8,Parâmetros!$B$5:$B$10,0)),"") -> 0.38 | I8: =IFERROR(SUMIFS('Controle Diário'!$S$6:$S$255,'Controle Diário'!$C$6:$C$255,$B8,'Controle Diário'!$B$6:$B$255,">="&$C$4,'Controle Diário'!$B$6:$B$255,"<="&$C$5)/SUMIFS('Controle Diário'!$R$6:$R$255,'Controle Diário'!$C$6:$C$255,$B8,'Controle Diário'!$B$6:$B$255,">="&$C$4,'Controle Diário'!$B$6:$B$255,"<="&$C$5),"") -> 5 | J8: =IFERROR(INDEX(Parâmetros!$D$5:$D$10,MATCH($B8,Parâmetros!$B$5:$B$10,0)),"") -> 4.66 | K8: =IFERROR(SUMIFS('Controle Diário'!$T$6:$T$255,'Controle Diário'!$C$6:$C$255,$B8,'Controle Diário'!$B$6:$B$255,">="&$C$4,'Controle Diário'!$B$6:$B$255,"<="&$C$5)/SUMIFS('Controle Diário'!$U$6:$U$255,'Controle Diário'!$C$6:$C$255,$B8,'Controle Diário'!$B$6:$B$255,">="&$C$4,'Controle Diário'!$B$6:$B$255,"<="&$C$5),"") -> 0.1137931 | L8: =SUMIFS('Controle Diário'!$AD$6:$AD$255,'Controle Diário'!$C$6:$C$255,$B8,'Controle Diário'!$B$6:$B$255,">="&$C$4,'Controle Diário'!$B$6:$B$255,"<="&$C$5) -> 3150 | M8: =IF($C8=0,"Sem lançamentos no período",IF(IF(ISNUMBER($L8),$L8,0)>0,"CRITICO - custo evitavel no periodo",IF(IF(ISNUMBER($G8),$G8,0)>IF(ISNUMBER($H8),$H8,1),"ATENCAO - terceiros acima da meta",IF(IF(ISNUMBER($I8),$I8,0)>IF(ISNUMBER($J8),$J8,99),"ATENCAO - custo/km acima da meta",IF(IF(ISNUMBER($D8),$D8,1)<IF(ISNUMBER($E8),$E8,0),"ATENCAO - frota abaixo do piso","OK - dentro das metas"))))) -> CRITICO - custo evitavel no periodo
B9: Só Fruta | C9: =(SUMIFS('Controle Diário'!$L$6:$L$255,'Controle Diário'!$C$6:$C$255,$B9,'Controle Diário'!$B$6:$B$255,">="&$C$4,'Controle Diário'!$B$6:$B$255,"<="&$C$5)+SUMIFS('Controle Diário'!$M$6:$M$255,'Controle Diário'!$C$6:$C$255,$B9,'Controle Diário'!$B$6:$B$255,">="&$C$4,'Controle Diário'!$B$6:$B$255,"<="&$C$5)+SUMIFS('Controle Diário'!$N$6:$N$255,'Controle Diário'!$C$6:$C$255,$B9,'Controle Diário'!$B$6:$B$255,">="&$C$4,'Controle Diário'!$B$6:$B$255,"<="&$C$5)) -> 0 | D9: =IFERROR(SUMIFS('Controle Diário'!$L$6:$L$255,'Controle Diário'!$C$6:$C$255,$B9,'Controle Diário'!$B$6:$B$255,">="&$C$4,'Controle Diário'!$B$6:$B$255,"<="&$C$5)/(SUMIFS('Controle Diário'!$L$6:$L$255,'Controle Diário'!$C$6:$C$255,$B9,'Controle Diário'!$B$6:$B$255,">="&$C$4,'Controle Diário'!$B$6:$B$255,"<="&$C$5)+SUMIFS('Controle Diário'!$M$6:$M$255,'Controle Diário'!$C$6:$C$255,$B9,'Controle Diário'!$B$6:$B$255,">="&$C$4,'Controle Diário'!$B$6:$B$255,"<="&$C$5)+SUMIFS('Controle Diário'!$N$6:$N$255,'Controle Diário'!$C$6:$C$255,$B9,'Controle Diário'!$B$6:$B$255,">="&$C$4,'Controle Diário'!$B$6:$B$255,"<="&$C$5)),"") | E9: =IFERROR(INDEX(Parâmetros!$E$5:$E$10,MATCH($B9,Parâmetros!$B$5:$B$10,0)),"") -> 0.5 | F9: =IFERROR(SUMIFS('Controle Diário'!$M$6:$M$255,'Controle Diário'!$C$6:$C$255,$B9,'Controle Diário'!$B$6:$B$255,">="&$C$4,'Controle Diário'!$B$6:$B$255,"<="&$C$5)/(SUMIFS('Controle Diário'!$L$6:$L$255,'Controle Diário'!$C$6:$C$255,$B9,'Controle Diário'!$B$6:$B$255,">="&$C$4,'Controle Diário'!$B$6:$B$255,"<="&$C$5)+SUMIFS('Controle Diário'!$M$6:$M$255,'Controle Diário'!$C$6:$C$255,$B9,'Controle Diário'!$B$6:$B$255,">="&$C$4,'Controle Diário'!$B$6:$B$255,"<="&$C$5)+SUMIFS('Controle Diário'!$N$6:$N$255,'Controle Diário'!$C$6:$C$255,$B9,'Controle Diário'!$B$6:$B$255,">="&$C$4,'Controle Diário'!$B$6:$B$255,"<="&$C$5)),"") | G9: =IFERROR(SUMIFS('Controle Diário'!$N$6:$N$255,'Controle Diário'!$C$6:$C$255,$B9,'Controle Diário'!$B$6:$B$255,">="&$C$4,'Controle Diário'!$B$6:$B$255,"<="&$C$5)/(SUMIFS('Controle Diário'!$L$6:$L$255,'Controle Diário'!$C$6:$C$255,$B9,'Controle Diário'!$B$6:$B$255,">="&$C$4,'Controle Diário'!$B$6:$B$255,"<="&$C$5)+SUMIFS('Controle Diário'!$M$6:$M$255,'Controle Diário'!$C$6:$C$255,$B9,'Controle Diário'!$B$6:$B$255,">="&$C$4,'Controle Diário'!$B$6:$B$255,"<="&$C$5)+SUMIFS('Controle Diário'!$N$6:$N$255,'Controle Diário'!$C$6:$C$255,$B9,'Controle Diário'!$B$6:$B$255,">="&$C$4,'Controle Diário'!$B$6:$B$255,"<="&$C$5)),"") | H9: =IFERROR(INDEX(Parâmetros!$G$5:$G$10,MATCH($B9,Parâmetros!$B$5:$B$10,0)),"") -> 0.37 | I9: =IFERROR(SUMIFS('Controle Diário'!$S$6:$S$255,'Controle Diário'!$C$6:$C$255,$B9,'Controle Diário'!$B$6:$B$255,">="&$C$4,'Controle Diário'!$B$6:$B$255,"<="&$C$5)/SUMIFS('Controle Diário'!$R$6:$R$255,'Controle Diário'!$C$6:$C$255,$B9,'Controle Diário'!$B$6:$B$255,">="&$C$4,'Controle Diário'!$B$6:$B$255,"<="&$C$5),"") | J9: =IFERROR(INDEX(Parâmetros!$D$5:$D$10,MATCH($B9,Parâmetros!$B$5:$B$10,0)),"") -> 5.34 | K9: =IFERROR(SUMIFS('Controle Diário'!$T$6:$T$255,'Controle Diário'!$C$6:$C$255,$B9,'Controle Diário'!$B$6:$B$255,">="&$C$4,'Controle Diário'!$B$6:$B$255,"<="&$C$5)/SUMIFS('Controle Diário'!$U$6:$U$255,'Controle Diário'!$C$6:$C$255,$B9,'Controle Diário'!$B$6:$B$255,">="&$C$4,'Controle Diário'!$B$6:$B$255,"<="&$C$5),"") | L9: =SUMIFS('Controle Diário'!$AD$6:$AD$255,'Controle Diário'!$C$6:$C$255,$B9,'Controle Diário'!$B$6:$B$255,">="&$C$4,'Controle Diário'!$B$6:$B$255,"<="&$C$5) -> 0 | M9: =IF($C9=0,"Sem lançamentos no período",IF(IF(ISNUMBER($L9),$L9,0)>0,"CRITICO - custo evitavel no periodo",IF(IF(ISNUMBER($G9),$G9,0)>IF(ISNUMBER($H9),$H9,1),"ATENCAO - terceiros acima da meta",IF(IF(ISNUMBER($I9),$I9,0)>IF(ISNUMBER($J9),$J9,99),"ATENCAO - custo/km acima da meta",IF(IF(ISNUMBER($D9),$D9,1)<IF(ISNUMBER($E9),$E9,0),"ATENCAO - frota abaixo do piso","OK - dentro das metas"))))) -> Sem lançamentos no período
B10: Stella | C10: =(SUMIFS('Controle Diário'!$L$6:$L$255,'Controle Diário'!$C$6:$C$255,$B10,'Controle Diário'!$B$6:$B$255,">="&$C$4,'Controle Diário'!$B$6:$B$255,"<="&$C$5)+SUMIFS('Controle Diário'!$M$6:$M$255,'Controle Diário'!$C$6:$C$255,$B10,'Controle Diário'!$B$6:$B$255,">="&$C$4,'Controle Diário'!$B$6:$B$255,"<="&$C$5)+SUMIFS('Controle Diário'!$N$6:$N$255,'Controle Diário'!$C$6:$C$255,$B10,'Controle Diário'!$B$6:$B$255,">="&$C$4,'Controle Diário'!$B$6:$B$255,"<="&$C$5)) -> 0 | D10: =IFERROR(SUMIFS('Controle Diário'!$L$6:$L$255,'Controle Diário'!$C$6:$C$255,$B10,'Controle Diário'!$B$6:$B$255,">="&$C$4,'Controle Diário'!$B$6:$B$255,"<="&$C$5)/(SUMIFS('Controle Diário'!$L$6:$L$255,'Controle Diário'!$C$6:$C$255,$B10,'Controle Diário'!$B$6:$B$255,">="&$C$4,'Controle Diário'!$B$6:$B$255,"<="&$C$5)+SUMIFS('Controle Diário'!$M$6:$M$255,'Controle Diário'!$C$6:$C$255,$B10,'Controle Diário'!$B$6:$B$255,">="&$C$4,'Controle Diário'!$B$6:$B$255,"<="&$C$5)+SUMIFS('Controle Diário'!$N$6:$N$255,'Controle Diário'!$C$6:$C$255,$B10,'Controle Diário'!$B$6:$B$255,">="&$C$4,'Controle Diário'!$B$6:$B$255,"<="&$C$5)),"") | E10: =IFERROR(INDEX(Parâmetros!$E$5:$E$10,MATCH($B10,Parâmetros!$B$5:$B$10,0)),"") -> 0.45 | F10: =IFERROR(SUMIFS('Controle Diário'!$M$6:$M$255,'Controle Diário'!$C$6:$C$255,$B10,'Controle Diário'!$B$6:$B$255,">="&$C$4,'Controle Diário'!$B$6:$B$255,"<="&$C$5)/(SUMIFS('Controle Diário'!$L$6:$L$255,'Controle Diário'!$C$6:$C$255,$B10,'Controle Diário'!$B$6:$B$255,">="&$C$4,'Controle Diário'!$B$6:$B$255,"<="&$C$5)+SUMIFS('Controle Diário'!$M$6:$M$255,'Controle Diário'!$C$6:$C$255,$B10,'Controle Diário'!$B$6:$B$255,">="&$C$4,'Controle Diário'!$B$6:$B$255,"<="&$C$5)+SUMIFS('Controle Diário'!$N$6:$N$255,'Controle Diário'!$C$6:$C$255,$B10,'Controle Diário'!$B$6:$B$255,">="&$C$4,'Controle Diário'!$B$6:$B$255,"<="&$C$5)),"") | G10: =IFERROR(SUMIFS('Controle Diário'!$N$6:$N$255,'Controle Diário'!$C$6:$C$255,$B10,'Controle Diário'!$B$6:$B$255,">="&$C$4,'Controle Diário'!$B$6:$B$255,"<="&$C$5)/(SUMIFS('Controle Diário'!$L$6:$L$255,'Controle Diário'!$C$6:$C$255,$B10,'Controle Diário'!$B$6:$B$255,">="&$C$4,'Controle Diário'!$B$6:$B$255,"<="&$C$5)+SUMIFS('Controle Diário'!$M$6:$M$255,'Controle Diário'!$C$6:$C$255,$B10,'Controle Diário'!$B$6:$B$255,">="&$C$4,'Controle Diário'!$B$6:$B$255,"<="&$C$5)+SUMIFS('Controle Diário'!$N$6:$N$255,'Controle Diário'!$C$6:$C$255,$B10,'Controle Diário'!$B$6:$B$255,">="&$C$4,'Controle Diário'!$B$6:$B$255,"<="&$C$5)),"") | H10: =IFERROR(INDEX(Parâmetros!$G$5:$G$10,MATCH($B10,Parâmetros!$B$5:$B$10,0)),"") -> 0.43 | I10: =IFERROR(SUMIFS('Controle Diário'!$S$6:$S$255,'Controle Diário'!$C$6:$C$255,$B10,'Controle Diário'!$B$6:$B$255,">="&$C$4,'Controle Diário'!$B$6:$B$255,"<="&$C$5)/SUMIFS('Controle Diário'!$R$6:$R$255,'Controle Diário'!$C$6:$C$255,$B10,'Controle Diário'!$B$6:$B$255,">="&$C$4,'Controle Diário'!$B$6:$B$255,"<="&$C$5),"") | J10: =IFERROR(INDEX(Parâmetros!$D$5:$D$10,MATCH($B10,Parâmetros!$B$5:$B$10,0)),"") -> 4.2 | K10: =IFERROR(SUMIFS('Controle Diário'!$T$6:$T$255,'Controle Diário'!$C$6:$C$255,$B10,'Controle Diário'!$B$6:$B$255,">="&$C$4,'Controle Diário'!$B$6:$B$255,"<="&$C$5)/SUMIFS('Controle Diário'!$U$6:$U$255,'Controle Diário'!$C$6:$C$255,$B10,'Controle Diário'!$B$6:$B$255,">="&$C$4,'Controle Diário'!$B$6:$B$255,"<="&$C$5),"") | L10: =SUMIFS('Controle Diário'!$AD$6:$AD$255,'Controle Diário'!$C$6:$C$255,$B10,'Controle Diário'!$B$6:$B$255,">="&$C$4,'Controle Diário'!$B$6:$B$255,"<="&$C$5) -> 0 | M10: =IF($C10=0,"Sem lançamentos no período",IF(IF(ISNUMBER($L10),$L10,0)>0,"CRITICO - custo evitavel no periodo",IF(IF(ISNUMBER($G10),$G10,0)>IF(ISNUMBER($H10),$H10,1),"ATENCAO - terceiros acima da meta",IF(IF(ISNUMBER($I10),$I10,0)>IF(ISNUMBER($J10),$J10,99),"ATENCAO - custo/km acima da meta",IF(IF(ISNUMBER($D10),$D10,1)<IF(ISNUMBER($E10),$E10,0),"ATENCAO - frota abaixo do piso","OK - dentro das metas"))))) -> Sem lançamentos no período
B11: Salsaretti | C11: =(SUMIFS('Controle Diário'!$L$6:$L$255,'Controle Diário'!$C$6:$C$255,$B11,'Controle Diário'!$B$6:$B$255,">="&$C$4,'Controle Diário'!$B$6:$B$255,"<="&$C$5)+SUMIFS('Controle Diário'!$M$6:$M$255,'Controle Diário'!$C$6:$C$255,$B11,'Controle Diário'!$B$6:$B$255,">="&$C$4,'Controle Diário'!$B$6:$B$255,"<="&$C$5)+SUMIFS('Controle Diário'!$N$6:$N$255,'Controle Diário'!$C$6:$C$255,$B11,'Controle Diário'!$B$6:$B$255,">="&$C$4,'Controle Diário'!$B$6:$B$255,"<="&$C$5)) -> 0 | D11: =IFERROR(SUMIFS('Controle Diário'!$L$6:$L$255,'Controle Diário'!$C$6:$C$255,$B11,'Controle Diário'!$B$6:$B$255,">="&$C$4,'Controle Diário'!$B$6:$B$255,"<="&$C$5)/(SUMIFS('Controle Diário'!$L$6:$L$255,'Controle Diário'!$C$6:$C$255,$B11,'Controle Diário'!$B$6:$B$255,">="&$C$4,'Controle Diário'!$B$6:$B$255,"<="&$C$5)+SUMIFS('Controle Diário'!$M$6:$M$255,'Controle Diário'!$C$6:$C$255,$B11,'Controle Diário'!$B$6:$B$255,">="&$C$4,'Controle Diário'!$B$6:$B$255,"<="&$C$5)+SUMIFS('Controle Diário'!$N$6:$N$255,'Controle Diário'!$C$6:$C$255,$B11,'Controle Diário'!$B$6:$B$255,">="&$C$4,'Controle Diário'!$B$6:$B$255,"<="&$C$5)),"") | E11: =IFERROR(INDEX(Parâmetros!$E$5:$E$10,MATCH($B11,Parâmetros!$B$5:$B$10,0)),"") -> 0.35 | F11: =IFERROR(SUMIFS('Controle Diário'!$M$6:$M$255,'Controle Diário'!$C$6:$C$255,$B11,'Controle Diário'!$B$6:$B$255,">="&$C$4,'Controle Diário'!$B$6:$B$255,"<="&$C$5)/(SUMIFS('Controle Diário'!$L$6:$L$255,'Controle Diário'!$C$6:$C$255,$B11,'Controle Diário'!$B$6:$B$255,">="&$C$4,'Controle Diário'!$B$6:$B$255,"<="&$C$5)+SUMIFS('Controle Diário'!$M$6:$M$255,'Controle Diário'!$C$6:$C$255,$B11,'Controle Diário'!$B$6:$B$255,">="&$C$4,'Controle Diário'!$B$6:$B$255,"<="&$C$5)+SUMIFS('Controle Diário'!$N$6:$N$255,'Controle Diário'!$C$6:$C$255,$B11,'Controle Diário'!$B$6:$B$255,">="&$C$4,'Controle Diário'!$B$6:$B$255,"<="&$C$5)),"") | G11: =IFERROR(SUMIFS('Controle Diário'!$N$6:$N$255,'Controle Diário'!$C$6:$C$255,$B11,'Controle Diário'!$B$6:$B$255,">="&$C$4,'Controle Diário'!$B$6:$B$255,"<="&$C$5)/(SUMIFS('Controle Diário'!$L$6:$L$255,'Controle Diário'!$C$6:$C$255,$B11,'Controle Diário'!$B$6:$B$255,">="&$C$4,'Controle Diário'!$B$6:$B$255,"<="&$C$5)+SUMIFS('Controle Diário'!$M$6:$M$255,'Controle Diário'!$C$6:$C$255,$B11,'Controle Diário'!$B$6:$B$255,">="&$C$4,'Controle Diário'!$B$6:$B$255,"<="&$C$5)+SUMIFS('Controle Diário'!$N$6:$N$255,'Controle Diário'!$C$6:$C$255,$B11,'Controle Diário'!$B$6:$B$255,">="&$C$4,'Controle Diário'!$B$6:$B$255,"<="&$C$5)),"") | H11: =IFERROR(INDEX(Parâmetros!$G$5:$G$10,MATCH($B11,Parâmetros!$B$5:$B$10,0)),"") -> 0.38 | I11: =IFERROR(SUMIFS('Controle Diário'!$S$6:$S$255,'Controle Diário'!$C$6:$C$255,$B11,'Controle Diário'!$B$6:$B$255,">="&$C$4,'Controle Diário'!$B$6:$B$255,"<="&$C$5)/SUMIFS('Controle Diário'!$R$6:$R$255,'Controle Diário'!$C$6:$C$255,$B11,'Controle Diário'!$B$6:$B$255,">="&$C$4,'Controle Diário'!$B$6:$B$255,"<="&$C$5),"") | J11: =IFERROR(INDEX(Parâmetros!$D$5:$D$10,MATCH($B11,Parâmetros!$B$5:$B$10,0)),"") -> 4.3 | K11: =IFERROR(SUMIFS('Controle Diário'!$T$6:$T$255,'Controle Diário'!$C$6:$C$255,$B11,'Controle Diário'!$B$6:$B$255,">="&$C$4,'Controle Diário'!$B$6:$B$255,"<="&$C$5)/SUMIFS('Controle Diário'!$U$6:$U$255,'Controle Diário'!$C$6:$C$255,$B11,'Controle Diário'!$B$6:$B$255,">="&$C$4,'Controle Diário'!$B$6:$B$255,"<="&$C$5),"") | L11: =SUMIFS('Controle Diário'!$AD$6:$AD$255,'Controle Diário'!$C$6:$C$255,$B11,'Controle Diário'!$B$6:$B$255,">="&$C$4,'Controle Diário'!$B$6:$B$255,"<="&$C$5) -> 0 | M11: =IF($C11=0,"Sem lançamentos no período",IF(IF(ISNUMBER($L11),$L11,0)>0,"CRITICO - custo evitavel no periodo",IF(IF(ISNUMBER($G11),$G11,0)>IF(ISNUMBER($H11),$H11,1),"ATENCAO - terceiros acima da meta",IF(IF(ISNUMBER($I11),$I11,0)>IF(ISNUMBER($J11),$J11,99),"ATENCAO - custo/km acima da meta",IF(IF(ISNUMBER($D11),$D11,1)<IF(ISNUMBER($E11),$E11,0),"ATENCAO - frota abaixo do piso","OK - dentro das metas"))))) -> Sem lançamentos no período
B12: Minas Mais | C12: =(SUMIFS('Controle Diário'!$L$6:$L$255,'Controle Diário'!$C$6:$C$255,$B12,'Controle Diário'!$B$6:$B$255,">="&$C$4,'Controle Diário'!$B$6:$B$255,"<="&$C$5)+SUMIFS('Controle Diário'!$M$6:$M$255,'Controle Diário'!$C$6:$C$255,$B12,'Controle Diário'!$B$6:$B$255,">="&$C$4,'Controle Diário'!$B$6:$B$255,"<="&$C$5)+SUMIFS('Controle Diário'!$N$6:$N$255,'Controle Diário'!$C$6:$C$255,$B12,'Controle Diário'!$B$6:$B$255,">="&$C$4,'Controle Diário'!$B$6:$B$255,"<="&$C$5)) -> 0 | D12: =IFERROR(SUMIFS('Controle Diário'!$L$6:$L$255,'Controle Diário'!$C$6:$C$255,$B12,'Controle Diário'!$B$6:$B$255,">="&$C$4,'Controle Diário'!$B$6:$B$255,"<="&$C$5)/(SUMIFS('Controle Diário'!$L$6:$L$255,'Controle Diário'!$C$6:$C$255,$B12,'Controle Diário'!$B$6:$B$255,">="&$C$4,'Controle Diário'!$B$6:$B$255,"<="&$C$5)+SUMIFS('Controle Diário'!$M$6:$M$255,'Controle Diário'!$C$6:$C$255,$B12,'Controle Diário'!$B$6:$B$255,">="&$C$4,'Controle Diário'!$B$6:$B$255,"<="&$C$5)+SUMIFS('Controle Diário'!$N$6:$N$255,'Controle Diário'!$C$6:$C$255,$B12,'Controle Diário'!$B$6:$B$255,">="&$C$4,'Controle Diário'!$B$6:$B$255,"<="&$C$5)),"") | E12: =IFERROR(INDEX(Parâmetros!$E$5:$E$10,MATCH($B12,Parâmetros!$B$5:$B$10,0)),"") -> 0.41 | F12: =IFERROR(SUMIFS('Controle Diário'!$M$6:$M$255,'Controle Diário'!$C$6:$C$255,$B12,'Controle Diário'!$B$6:$B$255,">="&$C$4,'Controle Diário'!$B$6:$B$255,"<="&$C$5)/(SUMIFS('Controle Diário'!$L$6:$L$255,'Controle Diário'!$C$6:$C$255,$B12,'Controle Diário'!$B$6:$B$255,">="&$C$4,'Controle Diário'!$B$6:$B$255,"<="&$C$5)+SUMIFS('Controle Diário'!$M$6:$M$255,'Controle Diário'!$C$6:$C$255,$B12,'Controle Diário'!$B$6:$B$255,">="&$C$4,'Controle Diário'!$B$6:$B$255,"<="&$C$5)+SUMIFS('Controle Diário'!$N$6:$N$255,'Controle Diário'!$C$6:$C$255,$B12,'Controle Diário'!$B$6:$B$255,">="&$C$4,'Controle Diário'!$B$6:$B$255,"<="&$C$5)),"") | G12: =IFERROR(SUMIFS('Controle Diário'!$N$6:$N$255,'Controle Diário'!$C$6:$C$255,$B12,'Controle Diário'!$B$6:$B$255,">="&$C$4,'Controle Diário'!$B$6:$B$255,"<="&$C$5)/(SUMIFS('Controle Diário'!$L$6:$L$255,'Controle Diário'!$C$6:$C$255,$B12,'Controle Diário'!$B$6:$B$255,">="&$C$4,'Controle Diário'!$B$6:$B$255,"<="&$C$5)+SUMIFS('Controle Diário'!$M$6:$M$255,'Controle Diário'!$C$6:$C$255,$B12,'Controle Diário'!$B$6:$B$255,">="&$C$4,'Controle Diário'!$B$6:$B$255,"<="&$C$5)+SUMIFS('Controle Diário'!$N$6:$N$255,'Controle Diário'!$C$6:$C$255,$B12,'Controle Diário'!$B$6:$B$255,">="&$C$4,'Controle Diário'!$B$6:$B$255,"<="&$C$5)),"") | H12: =IFERROR(INDEX(Parâmetros!$G$5:$G$10,MATCH($B12,Parâmetros!$B$5:$B$10,0)),"") -> 0.32 | I12: =IFERROR(SUMIFS('Controle Diário'!$S$6:$S$255,'Controle Diário'!$C$6:$C$255,$B12,'Controle Diário'!$B$6:$B$255,">="&$C$4,'Controle Diário'!$B$6:$B$255,"<="&$C$5)/SUMIFS('Controle Diário'!$R$6:$R$255,'Controle Diário'!$C$6:$C$255,$B12,'Controle Diário'!$B$6:$B$255,">="&$C$4,'Controle Diário'!$B$6:$B$255,"<="&$C$5),"") | J12: =IFERROR(INDEX(Parâmetros!$D$5:$D$10,MATCH($B12,Parâmetros!$B$5:$B$10,0)),"") -> 5.32 | K12: =IFERROR(SUMIFS('Controle Diário'!$T$6:$T$255,'Controle Diário'!$C$6:$C$255,$B12,'Controle Diário'!$B$6:$B$255,">="&$C$4,'Controle Diário'!$B$6:$B$255,"<="&$C$5)/SUMIFS('Controle Diário'!$U$6:$U$255,'Controle Diário'!$C$6:$C$255,$B12,'Controle Diário'!$B$6:$B$255,">="&$C$4,'Controle Diário'!$B$6:$B$255,"<="&$C$5),"") | L12: =SUMIFS('Controle Diário'!$AD$6:$AD$255,'Controle Diário'!$C$6:$C$255,$B12,'Controle Diário'!$B$6:$B$255,">="&$C$4,'Controle Diário'!$B$6:$B$255,"<="&$C$5) -> 0 | M12: =IF($C12=0,"Sem lançamentos no período",IF(IF(ISNUMBER($L12),$L12,0)>0,"CRITICO - custo evitavel no periodo",IF(IF(ISNUMBER($G12),$G12,0)>IF(ISNUMBER($H12),$H12,1),"ATENCAO - terceiros acima da meta",IF(IF(ISNUMBER($I12),$I12,0)>IF(ISNUMBER($J12),$J12,99),"ATENCAO - custo/km acima da meta",IF(IF(ISNUMBER($D12),$D12,1)<IF(ISNUMBER($E12),$E12,0),"ATENCAO - frota abaixo do piso","OK - dentro das metas"))))) -> Sem lançamentos no período
B13: Nordeste Mais | C13: =(SUMIFS('Controle Diário'!$L$6:$L$255,'Controle Diário'!$C$6:$C$255,$B13,'Controle Diário'!$B$6:$B$255,">="&$C$4,'Controle Diário'!$B$6:$B$255,"<="&$C$5)+SUMIFS('Controle Diário'!$M$6:$M$255,'Controle Diário'!$C$6:$C$255,$B13,'Controle Diário'!$B$6:$B$255,">="&$C$4,'Controle Diário'!$B$6:$B$255,"<="&$C$5)+SUMIFS('Controle Diário'!$N$6:$N$255,'Controle Diário'!$C$6:$C$255,$B13,'Controle Diário'!$B$6:$B$255,">="&$C$4,'Controle Diário'!$B$6:$B$255,"<="&$C$5)) -> 0 | D13: =IFERROR(SUMIFS('Controle Diário'!$L$6:$L$255,'Controle Diário'!$C$6:$C$255,$B13,'Controle Diário'!$B$6:$B$255,">="&$C$4,'Controle Diário'!$B$6:$B$255,"<="&$C$5)/(SUMIFS('Controle Diário'!$L$6:$L$255,'Controle Diário'!$C$6:$C$255,$B13,'Controle Diário'!$B$6:$B$255,">="&$C$4,'Controle Diário'!$B$6:$B$255,"<="&$C$5)+SUMIFS('Controle Diário'!$M$6:$M$255,'Controle Diário'!$C$6:$C$255,$B13,'Controle Diário'!$B$6:$B$255,">="&$C$4,'Controle Diário'!$B$6:$B$255,"<="&$C$5)+SUMIFS('Controle Diário'!$N$6:$N$255,'Controle Diário'!$C$6:$C$255,$B13,'Controle Diário'!$B$6:$B$255,">="&$C$4,'Controle Diário'!$B$6:$B$255,"<="&$C$5)),"") | E13: =IFERROR(INDEX(Parâmetros!$E$5:$E$10,MATCH($B13,Parâmetros!$B$5:$B$10,0)),"") -> 0.28 | F13: =IFERROR(SUMIFS('Controle Diário'!$M$6:$M$255,'Controle Diário'!$C$6:$C$255,$B13,'Controle Diário'!$B$6:$B$255,">="&$C$4,'Controle Diário'!$B$6:$B$255,"<="&$C$5)/(SUMIFS('Controle Diário'!$L$6:$L$255,'Controle Diário'!$C$6:$C$255,$B13,'Controle Diário'!$B$6:$B$255,">="&$C$4,'Controle Diário'!$B$6:$B$255,"<="&$C$5)+SUMIFS('Controle Diário'!$M$6:$M$255,'Controle Diário'!$C$6:$C$255,$B13,'Controle Diário'!$B$6:$B$255,">="&$C$4,'Controle Diário'!$B$6:$B$255,"<="&$C$5)+SUMIFS('Controle Diário'!$N$6:$N$255,'Controle Diário'!$C$6:$C$255,$B13,'Controle Diário'!$B$6:$B$255,">="&$C$4,'Controle Diário'!$B$6:$B$255,"<="&$C$5)),"") | G13: =IFERROR(SUMIFS('Controle Diário'!$N$6:$N$255,'Controle Diário'!$C$6:$C$255,$B13,'Controle Diário'!$B$6:$B$255,">="&$C$4,'Controle Diário'!$B$6:$B$255,"<="&$C$5)/(SUMIFS('Controle Diário'!$L$6:$L$255,'Controle Diário'!$C$6:$C$255,$B13,'Controle Diário'!$B$6:$B$255,">="&$C$4,'Controle Diário'!$B$6:$B$255,"<="&$C$5)+SUMIFS('Controle Diário'!$M$6:$M$255,'Controle Diário'!$C$6:$C$255,$B13,'Controle Diário'!$B$6:$B$255,">="&$C$4,'Controle Diário'!$B$6:$B$255,"<="&$C$5)+SUMIFS('Controle Diário'!$N$6:$N$255,'Controle Diário'!$C$6:$C$255,$B13,'Controle Diário'!$B$6:$B$255,">="&$C$4,'Controle Diário'!$B$6:$B$255,"<="&$C$5)),"") | H13: =IFERROR(INDEX(Parâmetros!$G$5:$G$10,MATCH($B13,Parâmetros!$B$5:$B$10,0)),"") -> 0.45 | I13: =IFERROR(SUMIFS('Controle Diário'!$S$6:$S$255,'Controle Diário'!$C$6:$C$255,$B13,'Controle Diário'!$B$6:$B$255,">="&$C$4,'Controle Diário'!$B$6:$B$255,"<="&$C$5)/SUMIFS('Controle Diário'!$R$6:$R$255,'Controle Diário'!$C$6:$C$255,$B13,'Controle Diário'!$B$6:$B$255,">="&$C$4,'Controle Diário'!$B$6:$B$255,"<="&$C$5),"") | J13: =IFERROR(INDEX(Parâmetros!$D$5:$D$10,MATCH($B13,Parâmetros!$B$5:$B$10,0)),"") -> 4.12 | K13: =IFERROR(SUMIFS('Controle Diário'!$T$6:$T$255,'Controle Diário'!$C$6:$C$255,$B13,'Controle Diário'!$B$6:$B$255,">="&$C$4,'Controle Diário'!$B$6:$B$255,"<="&$C$5)/SUMIFS('Controle Diário'!$U$6:$U$255,'Controle Diário'!$C$6:$C$255,$B13,'Controle Diário'!$B$6:$B$255,">="&$C$4,'Controle Diário'!$B$6:$B$255,"<="&$C$5),"") | L13: =SUMIFS('Controle Diário'!$AD$6:$AD$255,'Controle Diário'!$C$6:$C$255,$B13,'Controle Diário'!$B$6:$B$255,">="&$C$4,'Controle Diário'!$B$6:$B$255,"<="&$C$5) -> 0 | M13: =IF($C13=0,"Sem lançamentos no período",IF(IF(ISNUMBER($L13),$L13,0)>0,"CRITICO - custo evitavel no periodo",IF(IF(ISNUMBER($G13),$G13,0)>IF(ISNUMBER($H13),$H13,1),"ATENCAO - terceiros acima da meta",IF(IF(ISNUMBER($I13),$I13,0)>IF(ISNUMBER($J13),$J13,99),"ATENCAO - custo/km acima da meta",IF(IF(ISNUMBER($D13),$D13,1)<IF(ISNUMBER($E13),$E13,0),"ATENCAO - frota abaixo do piso","OK - dentro das metas"))))) -> Sem lançamentos no período
B15: Total do grupo | C15: =SUM(C8:C13) -> 42 | L15: =SUM(L8:L13) -> 3150 | M15: ← Custo evitável acumulado no período (R$)
B17: Motivos de terceirização no período
B18: Motivo | C18: Cargas | D18: Classificação
B19: =Parâmetros!K5 -> 1. Pico de demanda não previsto | C19: =SUMIFS('Controle Diário'!$N$6:$N$255,'Controle Diário'!$O$6:$O$255,$B19,'Controle Diário'!$B$6:$B$255,">="&$C$4,'Controle Diário'!$B$6:$B$255,"<="&$C$5) -> 18 | D19: =Parâmetros!L5 -> Evitável
